[2023-11-01T11:04:19.623+0000] {processor.py:157} INFO - Started process (PID=49) to work on /opt/airflow/dags/my_dag.py
[2023-11-01T11:04:19.628+0000] {processor.py:829} INFO - Processing file /opt/airflow/dags/my_dag.py for tasks to queue
[2023-11-01T11:04:19.635+0000] {logging_mixin.py:151} INFO - [2023-11-01T11:04:19.634+0000] {dagbag.py:536} INFO - Filling up the DagBag from /opt/airflow/dags/my_dag.py
[2023-11-01T11:04:19.648+0000] {logging_mixin.py:151} INFO - [2023-11-01T11:04:19.645+0000] {dagbag.py:346} ERROR - Failed to import: /opt/airflow/dags/my_dag.py
Traceback (most recent call last):
  File "/home/airflow/.local/lib/python3.8/site-packages/airflow/models/dagbag.py", line 342, in parse
    loader.exec_module(new_module)
  File "<frozen importlib._bootstrap_external>", line 843, in exec_module
  File "<frozen importlib._bootstrap>", line 219, in _call_with_frames_removed
  File "/opt/airflow/dags/my_dag.py", line 6, in <module>
    'start_date': datetime(2023, 1, 1),
TypeError: 'module' object is not callable
[2023-11-01T11:04:19.655+0000] {processor.py:841} WARNING - No viable dags retrieved from /opt/airflow/dags/my_dag.py
[2023-11-01T11:04:19.716+0000] {processor.py:179} INFO - Processing /opt/airflow/dags/my_dag.py took 0.103 seconds
[2023-11-01T11:04:50.457+0000] {processor.py:157} INFO - Started process (PID=111) to work on /opt/airflow/dags/my_dag.py
[2023-11-01T11:04:50.459+0000] {processor.py:829} INFO - Processing file /opt/airflow/dags/my_dag.py for tasks to queue
[2023-11-01T11:04:50.466+0000] {logging_mixin.py:151} INFO - [2023-11-01T11:04:50.465+0000] {dagbag.py:536} INFO - Filling up the DagBag from /opt/airflow/dags/my_dag.py
[2023-11-01T11:04:50.481+0000] {logging_mixin.py:151} INFO - [2023-11-01T11:04:50.476+0000] {dagbag.py:346} ERROR - Failed to import: /opt/airflow/dags/my_dag.py
Traceback (most recent call last):
  File "/home/airflow/.local/lib/python3.8/site-packages/airflow/models/dagbag.py", line 342, in parse
    loader.exec_module(new_module)
  File "<frozen importlib._bootstrap_external>", line 843, in exec_module
  File "<frozen importlib._bootstrap>", line 219, in _call_with_frames_removed
  File "/opt/airflow/dags/my_dag.py", line 6, in <module>
    'start_date': datetime(2023, 1, 1),
TypeError: 'module' object is not callable
[2023-11-01T11:04:50.484+0000] {processor.py:841} WARNING - No viable dags retrieved from /opt/airflow/dags/my_dag.py
[2023-11-01T11:04:50.579+0000] {processor.py:179} INFO - Processing /opt/airflow/dags/my_dag.py took 0.134 seconds
[2023-11-01T11:05:21.214+0000] {processor.py:157} INFO - Started process (PID=173) to work on /opt/airflow/dags/my_dag.py
[2023-11-01T11:05:21.217+0000] {processor.py:829} INFO - Processing file /opt/airflow/dags/my_dag.py for tasks to queue
[2023-11-01T11:05:21.224+0000] {logging_mixin.py:151} INFO - [2023-11-01T11:05:21.223+0000] {dagbag.py:536} INFO - Filling up the DagBag from /opt/airflow/dags/my_dag.py
[2023-11-01T11:05:21.256+0000] {logging_mixin.py:151} INFO - [2023-11-01T11:05:21.236+0000] {dagbag.py:346} ERROR - Failed to import: /opt/airflow/dags/my_dag.py
Traceback (most recent call last):
  File "/home/airflow/.local/lib/python3.8/site-packages/airflow/models/dagbag.py", line 342, in parse
    loader.exec_module(new_module)
  File "<frozen importlib._bootstrap_external>", line 843, in exec_module
  File "<frozen importlib._bootstrap>", line 219, in _call_with_frames_removed
  File "/opt/airflow/dags/my_dag.py", line 6, in <module>
    'start_date': datetime(2023, 1, 1),
TypeError: 'module' object is not callable
[2023-11-01T11:05:21.259+0000] {processor.py:841} WARNING - No viable dags retrieved from /opt/airflow/dags/my_dag.py
[2023-11-01T11:05:21.368+0000] {processor.py:179} INFO - Processing /opt/airflow/dags/my_dag.py took 0.167 seconds
[2023-11-01T11:05:52.307+0000] {processor.py:157} INFO - Started process (PID=235) to work on /opt/airflow/dags/my_dag.py
[2023-11-01T11:05:52.309+0000] {processor.py:829} INFO - Processing file /opt/airflow/dags/my_dag.py for tasks to queue
[2023-11-01T11:05:52.313+0000] {logging_mixin.py:151} INFO - [2023-11-01T11:05:52.313+0000] {dagbag.py:536} INFO - Filling up the DagBag from /opt/airflow/dags/my_dag.py
[2023-11-01T11:05:52.322+0000] {logging_mixin.py:151} INFO - [2023-11-01T11:05:52.320+0000] {dagbag.py:346} ERROR - Failed to import: /opt/airflow/dags/my_dag.py
Traceback (most recent call last):
  File "/home/airflow/.local/lib/python3.8/site-packages/airflow/models/dagbag.py", line 342, in parse
    loader.exec_module(new_module)
  File "<frozen importlib._bootstrap_external>", line 843, in exec_module
  File "<frozen importlib._bootstrap>", line 219, in _call_with_frames_removed
  File "/opt/airflow/dags/my_dag.py", line 6, in <module>
    'start_date': datetime(2023, 1, 1),
TypeError: 'module' object is not callable
[2023-11-01T11:05:52.324+0000] {processor.py:841} WARNING - No viable dags retrieved from /opt/airflow/dags/my_dag.py
[2023-11-01T11:05:52.359+0000] {processor.py:179} INFO - Processing /opt/airflow/dags/my_dag.py took 0.057 seconds
[2023-11-01T11:06:22.592+0000] {processor.py:157} INFO - Started process (PID=296) to work on /opt/airflow/dags/my_dag.py
[2023-11-01T11:06:22.595+0000] {processor.py:829} INFO - Processing file /opt/airflow/dags/my_dag.py for tasks to queue
[2023-11-01T11:06:22.603+0000] {logging_mixin.py:151} INFO - [2023-11-01T11:06:22.602+0000] {dagbag.py:536} INFO - Filling up the DagBag from /opt/airflow/dags/my_dag.py
[2023-11-01T11:06:22.613+0000] {logging_mixin.py:151} INFO - [2023-11-01T11:06:22.611+0000] {dagbag.py:346} ERROR - Failed to import: /opt/airflow/dags/my_dag.py
Traceback (most recent call last):
  File "/home/airflow/.local/lib/python3.8/site-packages/airflow/models/dagbag.py", line 342, in parse
    loader.exec_module(new_module)
  File "<frozen importlib._bootstrap_external>", line 843, in exec_module
  File "<frozen importlib._bootstrap>", line 219, in _call_with_frames_removed
  File "/opt/airflow/dags/my_dag.py", line 6, in <module>
    'start_date': datetime(2023, 1, 1),
TypeError: 'module' object is not callable
[2023-11-01T11:06:22.614+0000] {processor.py:841} WARNING - No viable dags retrieved from /opt/airflow/dags/my_dag.py
[2023-11-01T11:06:22.650+0000] {processor.py:179} INFO - Processing /opt/airflow/dags/my_dag.py took 0.069 seconds
[2023-11-01T11:06:53.526+0000] {processor.py:157} INFO - Started process (PID=358) to work on /opt/airflow/dags/my_dag.py
[2023-11-01T11:06:53.528+0000] {processor.py:829} INFO - Processing file /opt/airflow/dags/my_dag.py for tasks to queue
[2023-11-01T11:06:53.536+0000] {logging_mixin.py:151} INFO - [2023-11-01T11:06:53.535+0000] {dagbag.py:536} INFO - Filling up the DagBag from /opt/airflow/dags/my_dag.py
[2023-11-01T11:06:53.547+0000] {logging_mixin.py:151} INFO - [2023-11-01T11:06:53.544+0000] {dagbag.py:346} ERROR - Failed to import: /opt/airflow/dags/my_dag.py
Traceback (most recent call last):
  File "/home/airflow/.local/lib/python3.8/site-packages/airflow/models/dagbag.py", line 342, in parse
    loader.exec_module(new_module)
  File "<frozen importlib._bootstrap_external>", line 843, in exec_module
  File "<frozen importlib._bootstrap>", line 219, in _call_with_frames_removed
  File "/opt/airflow/dags/my_dag.py", line 6, in <module>
    'start_date': datetime(2023, 1, 1),
TypeError: 'module' object is not callable
[2023-11-01T11:06:53.549+0000] {processor.py:841} WARNING - No viable dags retrieved from /opt/airflow/dags/my_dag.py
[2023-11-01T11:06:53.606+0000] {processor.py:179} INFO - Processing /opt/airflow/dags/my_dag.py took 0.092 seconds
[2023-11-01T11:07:23.929+0000] {processor.py:157} INFO - Started process (PID=420) to work on /opt/airflow/dags/my_dag.py
[2023-11-01T11:07:23.932+0000] {processor.py:829} INFO - Processing file /opt/airflow/dags/my_dag.py for tasks to queue
[2023-11-01T11:07:23.939+0000] {logging_mixin.py:151} INFO - [2023-11-01T11:07:23.938+0000] {dagbag.py:536} INFO - Filling up the DagBag from /opt/airflow/dags/my_dag.py
[2023-11-01T11:07:23.948+0000] {logging_mixin.py:151} INFO - [2023-11-01T11:07:23.946+0000] {dagbag.py:346} ERROR - Failed to import: /opt/airflow/dags/my_dag.py
Traceback (most recent call last):
  File "/home/airflow/.local/lib/python3.8/site-packages/airflow/models/dagbag.py", line 342, in parse
    loader.exec_module(new_module)
  File "<frozen importlib._bootstrap_external>", line 843, in exec_module
  File "<frozen importlib._bootstrap>", line 219, in _call_with_frames_removed
  File "/opt/airflow/dags/my_dag.py", line 6, in <module>
    'start_date': datetime(2023, 1, 1),
TypeError: 'module' object is not callable
[2023-11-01T11:07:23.949+0000] {processor.py:841} WARNING - No viable dags retrieved from /opt/airflow/dags/my_dag.py
[2023-11-01T11:07:23.992+0000] {processor.py:179} INFO - Processing /opt/airflow/dags/my_dag.py took 0.072 seconds
[2023-11-01T11:07:54.165+0000] {processor.py:157} INFO - Started process (PID=480) to work on /opt/airflow/dags/my_dag.py
[2023-11-01T11:07:54.168+0000] {processor.py:829} INFO - Processing file /opt/airflow/dags/my_dag.py for tasks to queue
[2023-11-01T11:07:54.177+0000] {logging_mixin.py:151} INFO - [2023-11-01T11:07:54.176+0000] {dagbag.py:536} INFO - Filling up the DagBag from /opt/airflow/dags/my_dag.py
[2023-11-01T11:07:54.193+0000] {logging_mixin.py:151} INFO - [2023-11-01T11:07:54.188+0000] {dagbag.py:346} ERROR - Failed to import: /opt/airflow/dags/my_dag.py
Traceback (most recent call last):
  File "/home/airflow/.local/lib/python3.8/site-packages/airflow/models/dagbag.py", line 342, in parse
    loader.exec_module(new_module)
  File "<frozen importlib._bootstrap_external>", line 843, in exec_module
  File "<frozen importlib._bootstrap>", line 219, in _call_with_frames_removed
  File "/opt/airflow/dags/my_dag.py", line 6, in <module>
    'start_date': datetime(2023, 1, 1),
TypeError: 'module' object is not callable
[2023-11-01T11:07:54.195+0000] {processor.py:841} WARNING - No viable dags retrieved from /opt/airflow/dags/my_dag.py
[2023-11-01T11:07:54.238+0000] {processor.py:179} INFO - Processing /opt/airflow/dags/my_dag.py took 0.084 seconds
[2023-11-01T11:08:24.627+0000] {processor.py:157} INFO - Started process (PID=542) to work on /opt/airflow/dags/my_dag.py
[2023-11-01T11:08:24.629+0000] {processor.py:829} INFO - Processing file /opt/airflow/dags/my_dag.py for tasks to queue
[2023-11-01T11:08:24.635+0000] {logging_mixin.py:151} INFO - [2023-11-01T11:08:24.634+0000] {dagbag.py:536} INFO - Filling up the DagBag from /opt/airflow/dags/my_dag.py
[2023-11-01T11:08:24.644+0000] {logging_mixin.py:151} INFO - [2023-11-01T11:08:24.642+0000] {dagbag.py:346} ERROR - Failed to import: /opt/airflow/dags/my_dag.py
Traceback (most recent call last):
  File "/home/airflow/.local/lib/python3.8/site-packages/airflow/models/dagbag.py", line 342, in parse
    loader.exec_module(new_module)
  File "<frozen importlib._bootstrap_external>", line 843, in exec_module
  File "<frozen importlib._bootstrap>", line 219, in _call_with_frames_removed
  File "/opt/airflow/dags/my_dag.py", line 6, in <module>
    'start_date': datetime(2023, 1, 1),
TypeError: 'module' object is not callable
[2023-11-01T11:08:24.646+0000] {processor.py:841} WARNING - No viable dags retrieved from /opt/airflow/dags/my_dag.py
[2023-11-01T11:08:24.692+0000] {processor.py:179} INFO - Processing /opt/airflow/dags/my_dag.py took 0.070 seconds
[2023-11-01T11:08:55.368+0000] {processor.py:157} INFO - Started process (PID=604) to work on /opt/airflow/dags/my_dag.py
[2023-11-01T11:08:55.370+0000] {processor.py:829} INFO - Processing file /opt/airflow/dags/my_dag.py for tasks to queue
[2023-11-01T11:08:55.374+0000] {logging_mixin.py:151} INFO - [2023-11-01T11:08:55.374+0000] {dagbag.py:536} INFO - Filling up the DagBag from /opt/airflow/dags/my_dag.py
[2023-11-01T11:08:55.382+0000] {logging_mixin.py:151} INFO - [2023-11-01T11:08:55.380+0000] {dagbag.py:346} ERROR - Failed to import: /opt/airflow/dags/my_dag.py
Traceback (most recent call last):
  File "/home/airflow/.local/lib/python3.8/site-packages/airflow/models/dagbag.py", line 342, in parse
    loader.exec_module(new_module)
  File "<frozen importlib._bootstrap_external>", line 843, in exec_module
  File "<frozen importlib._bootstrap>", line 219, in _call_with_frames_removed
  File "/opt/airflow/dags/my_dag.py", line 6, in <module>
    'start_date': datetime(2023, 1, 1),
TypeError: 'module' object is not callable
[2023-11-01T11:08:55.383+0000] {processor.py:841} WARNING - No viable dags retrieved from /opt/airflow/dags/my_dag.py
[2023-11-01T11:08:55.417+0000] {processor.py:179} INFO - Processing /opt/airflow/dags/my_dag.py took 0.054 seconds
[2023-11-01T11:09:25.748+0000] {processor.py:157} INFO - Started process (PID=666) to work on /opt/airflow/dags/my_dag.py
[2023-11-01T11:09:25.750+0000] {processor.py:829} INFO - Processing file /opt/airflow/dags/my_dag.py for tasks to queue
[2023-11-01T11:09:25.754+0000] {logging_mixin.py:151} INFO - [2023-11-01T11:09:25.754+0000] {dagbag.py:536} INFO - Filling up the DagBag from /opt/airflow/dags/my_dag.py
[2023-11-01T11:09:25.763+0000] {logging_mixin.py:151} INFO - [2023-11-01T11:09:25.761+0000] {dagbag.py:346} ERROR - Failed to import: /opt/airflow/dags/my_dag.py
Traceback (most recent call last):
  File "/home/airflow/.local/lib/python3.8/site-packages/airflow/models/dagbag.py", line 342, in parse
    loader.exec_module(new_module)
  File "<frozen importlib._bootstrap_external>", line 843, in exec_module
  File "<frozen importlib._bootstrap>", line 219, in _call_with_frames_removed
  File "/opt/airflow/dags/my_dag.py", line 6, in <module>
    'start_date': datetime(2023, 1, 1),
TypeError: 'module' object is not callable
[2023-11-01T11:09:25.765+0000] {processor.py:841} WARNING - No viable dags retrieved from /opt/airflow/dags/my_dag.py
[2023-11-01T11:09:25.801+0000] {processor.py:179} INFO - Processing /opt/airflow/dags/my_dag.py took 0.062 seconds
[2023-11-01T11:09:55.891+0000] {processor.py:157} INFO - Started process (PID=727) to work on /opt/airflow/dags/my_dag.py
[2023-11-01T11:09:55.894+0000] {processor.py:829} INFO - Processing file /opt/airflow/dags/my_dag.py for tasks to queue
[2023-11-01T11:09:55.901+0000] {logging_mixin.py:151} INFO - [2023-11-01T11:09:55.899+0000] {dagbag.py:536} INFO - Filling up the DagBag from /opt/airflow/dags/my_dag.py
[2023-11-01T11:09:55.912+0000] {logging_mixin.py:151} INFO - [2023-11-01T11:09:55.909+0000] {dagbag.py:346} ERROR - Failed to import: /opt/airflow/dags/my_dag.py
Traceback (most recent call last):
  File "/home/airflow/.local/lib/python3.8/site-packages/airflow/models/dagbag.py", line 342, in parse
    loader.exec_module(new_module)
  File "<frozen importlib._bootstrap_external>", line 843, in exec_module
  File "<frozen importlib._bootstrap>", line 219, in _call_with_frames_removed
  File "/opt/airflow/dags/my_dag.py", line 6, in <module>
    'start_date': datetime(2023, 1, 1),
TypeError: 'module' object is not callable
[2023-11-01T11:09:55.913+0000] {processor.py:841} WARNING - No viable dags retrieved from /opt/airflow/dags/my_dag.py
[2023-11-01T11:09:55.967+0000] {processor.py:179} INFO - Processing /opt/airflow/dags/my_dag.py took 0.085 seconds
[2023-11-01T11:10:26.882+0000] {processor.py:157} INFO - Started process (PID=791) to work on /opt/airflow/dags/my_dag.py
[2023-11-01T11:10:26.884+0000] {processor.py:829} INFO - Processing file /opt/airflow/dags/my_dag.py for tasks to queue
[2023-11-01T11:10:26.892+0000] {logging_mixin.py:151} INFO - [2023-11-01T11:10:26.891+0000] {dagbag.py:536} INFO - Filling up the DagBag from /opt/airflow/dags/my_dag.py
[2023-11-01T11:10:26.904+0000] {logging_mixin.py:151} INFO - [2023-11-01T11:10:26.901+0000] {dagbag.py:346} ERROR - Failed to import: /opt/airflow/dags/my_dag.py
Traceback (most recent call last):
  File "/home/airflow/.local/lib/python3.8/site-packages/airflow/models/dagbag.py", line 342, in parse
    loader.exec_module(new_module)
  File "<frozen importlib._bootstrap_external>", line 843, in exec_module
  File "<frozen importlib._bootstrap>", line 219, in _call_with_frames_removed
  File "/opt/airflow/dags/my_dag.py", line 6, in <module>
    'start_date': datetime(2023, 1, 1),
TypeError: 'module' object is not callable
[2023-11-01T11:10:26.906+0000] {processor.py:841} WARNING - No viable dags retrieved from /opt/airflow/dags/my_dag.py
[2023-11-01T11:10:26.942+0000] {processor.py:179} INFO - Processing /opt/airflow/dags/my_dag.py took 0.071 seconds
[2023-11-01T11:10:57.943+0000] {processor.py:157} INFO - Started process (PID=853) to work on /opt/airflow/dags/my_dag.py
[2023-11-01T11:10:57.945+0000] {processor.py:829} INFO - Processing file /opt/airflow/dags/my_dag.py for tasks to queue
[2023-11-01T11:10:57.952+0000] {logging_mixin.py:151} INFO - [2023-11-01T11:10:57.951+0000] {dagbag.py:536} INFO - Filling up the DagBag from /opt/airflow/dags/my_dag.py
[2023-11-01T11:10:57.965+0000] {logging_mixin.py:151} INFO - [2023-11-01T11:10:57.960+0000] {dagbag.py:346} ERROR - Failed to import: /opt/airflow/dags/my_dag.py
Traceback (most recent call last):
  File "/home/airflow/.local/lib/python3.8/site-packages/airflow/models/dagbag.py", line 342, in parse
    loader.exec_module(new_module)
  File "<frozen importlib._bootstrap_external>", line 843, in exec_module
  File "<frozen importlib._bootstrap>", line 219, in _call_with_frames_removed
  File "/opt/airflow/dags/my_dag.py", line 6, in <module>
    'start_date': datetime(2023, 1, 1),
TypeError: 'module' object is not callable
[2023-11-01T11:10:57.966+0000] {processor.py:841} WARNING - No viable dags retrieved from /opt/airflow/dags/my_dag.py
[2023-11-01T11:10:58.000+0000] {processor.py:179} INFO - Processing /opt/airflow/dags/my_dag.py took 0.067 seconds
[2023-11-01T11:11:28.068+0000] {processor.py:157} INFO - Started process (PID=914) to work on /opt/airflow/dags/my_dag.py
[2023-11-01T11:11:28.070+0000] {processor.py:829} INFO - Processing file /opt/airflow/dags/my_dag.py for tasks to queue
[2023-11-01T11:11:28.075+0000] {logging_mixin.py:151} INFO - [2023-11-01T11:11:28.074+0000] {dagbag.py:536} INFO - Filling up the DagBag from /opt/airflow/dags/my_dag.py
[2023-11-01T11:11:28.084+0000] {logging_mixin.py:151} INFO - [2023-11-01T11:11:28.081+0000] {dagbag.py:346} ERROR - Failed to import: /opt/airflow/dags/my_dag.py
Traceback (most recent call last):
  File "/home/airflow/.local/lib/python3.8/site-packages/airflow/models/dagbag.py", line 342, in parse
    loader.exec_module(new_module)
  File "<frozen importlib._bootstrap_external>", line 843, in exec_module
  File "<frozen importlib._bootstrap>", line 219, in _call_with_frames_removed
  File "/opt/airflow/dags/my_dag.py", line 6, in <module>
    'start_date': datetime(2023, 1, 1),
TypeError: 'module' object is not callable
[2023-11-01T11:11:28.087+0000] {processor.py:841} WARNING - No viable dags retrieved from /opt/airflow/dags/my_dag.py
[2023-11-01T11:11:28.129+0000] {processor.py:179} INFO - Processing /opt/airflow/dags/my_dag.py took 0.067 seconds
[2023-11-01T11:11:59.003+0000] {processor.py:157} INFO - Started process (PID=975) to work on /opt/airflow/dags/my_dag.py
[2023-11-01T11:11:59.005+0000] {processor.py:829} INFO - Processing file /opt/airflow/dags/my_dag.py for tasks to queue
[2023-11-01T11:11:59.009+0000] {logging_mixin.py:151} INFO - [2023-11-01T11:11:59.008+0000] {dagbag.py:536} INFO - Filling up the DagBag from /opt/airflow/dags/my_dag.py
[2023-11-01T11:11:59.015+0000] {logging_mixin.py:151} INFO - [2023-11-01T11:11:59.013+0000] {dagbag.py:346} ERROR - Failed to import: /opt/airflow/dags/my_dag.py
Traceback (most recent call last):
  File "/home/airflow/.local/lib/python3.8/site-packages/airflow/models/dagbag.py", line 342, in parse
    loader.exec_module(new_module)
  File "<frozen importlib._bootstrap_external>", line 843, in exec_module
  File "<frozen importlib._bootstrap>", line 219, in _call_with_frames_removed
  File "/opt/airflow/dags/my_dag.py", line 6, in <module>
    'start_date': datetime(2023, 1, 1),
TypeError: 'module' object is not callable
[2023-11-01T11:11:59.016+0000] {processor.py:841} WARNING - No viable dags retrieved from /opt/airflow/dags/my_dag.py
[2023-11-01T11:11:59.046+0000] {processor.py:179} INFO - Processing /opt/airflow/dags/my_dag.py took 0.047 seconds
[2023-11-01T11:12:30.187+0000] {processor.py:157} INFO - Started process (PID=1037) to work on /opt/airflow/dags/my_dag.py
[2023-11-01T11:12:30.190+0000] {processor.py:829} INFO - Processing file /opt/airflow/dags/my_dag.py for tasks to queue
[2023-11-01T11:12:30.194+0000] {logging_mixin.py:151} INFO - [2023-11-01T11:12:30.193+0000] {dagbag.py:536} INFO - Filling up the DagBag from /opt/airflow/dags/my_dag.py
[2023-11-01T11:12:30.203+0000] {logging_mixin.py:151} INFO - [2023-11-01T11:12:30.200+0000] {dagbag.py:346} ERROR - Failed to import: /opt/airflow/dags/my_dag.py
Traceback (most recent call last):
  File "/home/airflow/.local/lib/python3.8/site-packages/airflow/models/dagbag.py", line 342, in parse
    loader.exec_module(new_module)
  File "<frozen importlib._bootstrap_external>", line 843, in exec_module
  File "<frozen importlib._bootstrap>", line 219, in _call_with_frames_removed
  File "/opt/airflow/dags/my_dag.py", line 6, in <module>
    'start_date': datetime(2023, 1, 1),
TypeError: 'module' object is not callable
[2023-11-01T11:12:30.204+0000] {processor.py:841} WARNING - No viable dags retrieved from /opt/airflow/dags/my_dag.py
[2023-11-01T11:12:30.274+0000] {processor.py:179} INFO - Processing /opt/airflow/dags/my_dag.py took 0.093 seconds
[2023-11-01T11:13:01.119+0000] {processor.py:157} INFO - Started process (PID=1099) to work on /opt/airflow/dags/my_dag.py
[2023-11-01T11:13:01.122+0000] {processor.py:829} INFO - Processing file /opt/airflow/dags/my_dag.py for tasks to queue
[2023-11-01T11:13:01.126+0000] {logging_mixin.py:151} INFO - [2023-11-01T11:13:01.125+0000] {dagbag.py:536} INFO - Filling up the DagBag from /opt/airflow/dags/my_dag.py
[2023-11-01T11:13:01.135+0000] {logging_mixin.py:151} INFO - [2023-11-01T11:13:01.133+0000] {dagbag.py:346} ERROR - Failed to import: /opt/airflow/dags/my_dag.py
Traceback (most recent call last):
  File "/home/airflow/.local/lib/python3.8/site-packages/airflow/models/dagbag.py", line 342, in parse
    loader.exec_module(new_module)
  File "<frozen importlib._bootstrap_external>", line 843, in exec_module
  File "<frozen importlib._bootstrap>", line 219, in _call_with_frames_removed
  File "/opt/airflow/dags/my_dag.py", line 6, in <module>
    'start_date': datetime(2023, 1, 1),
TypeError: 'module' object is not callable
[2023-11-01T11:13:01.136+0000] {processor.py:841} WARNING - No viable dags retrieved from /opt/airflow/dags/my_dag.py
[2023-11-01T11:13:01.169+0000] {processor.py:179} INFO - Processing /opt/airflow/dags/my_dag.py took 0.056 seconds
