[2023-11-01T15:21:52.260+0000] {taskinstance.py:1159} INFO - Dependencies all met for dep_context=non-requeueable deps ti=<TaskInstance: good_morning_1.get_cur_rate manual__2023-11-01T15:21:46.999654+00:00 [queued]>
[2023-11-01T15:21:52.285+0000] {taskinstance.py:1159} INFO - Dependencies all met for dep_context=requeueable deps ti=<TaskInstance: good_morning_1.get_cur_rate manual__2023-11-01T15:21:46.999654+00:00 [queued]>
[2023-11-01T15:21:52.286+0000] {taskinstance.py:1361} INFO - Starting attempt 1 of 2
[2023-11-01T15:21:52.317+0000] {taskinstance.py:1382} INFO - Executing <Task(BashOperator): get_cur_rate> on 2023-11-01 15:21:46.999654+00:00
[2023-11-01T15:21:52.328+0000] {standard_task_runner.py:57} INFO - Started process 3891 to run task
[2023-11-01T15:21:52.336+0000] {standard_task_runner.py:84} INFO - Running: ['***', 'tasks', 'run', 'good_morning_1', 'get_cur_rate', 'manual__2023-11-01T15:21:46.999654+00:00', '--job-id', '14', '--raw', '--subdir', 'DAGS_FOLDER/good_mornig.py', '--cfg-path', '/tmp/tmptik3ekwj']
[2023-11-01T15:21:52.345+0000] {standard_task_runner.py:85} INFO - Job 14: Subtask get_cur_rate
[2023-11-01T15:21:52.464+0000] {task_command.py:416} INFO - Running <TaskInstance: good_morning_1.get_cur_rate manual__2023-11-01T15:21:46.999654+00:00 [running]> on host cc3c0240a654
[2023-11-01T15:21:52.609+0000] {taskinstance.py:1662} INFO - Exporting env vars: AIRFLOW_CTX_DAG_OWNER='mdv' AIRFLOW_CTX_DAG_ID='good_morning_1' AIRFLOW_CTX_TASK_ID='get_cur_rate' AIRFLOW_CTX_EXECUTION_DATE='2023-11-01T15:21:46.999654+00:00' AIRFLOW_CTX_TRY_NUMBER='1' AIRFLOW_CTX_DAG_RUN_ID='manual__2023-11-01T15:21:46.999654+00:00'
[2023-11-01T15:21:52.612+0000] {subprocess.py:63} INFO - Tmp dir root location: /tmp
[2023-11-01T15:21:52.613+0000] {subprocess.py:75} INFO - Running command: ['/bin/bash', '-c', 'docker run masalskii/ex-rate']
[2023-11-01T15:21:52.645+0000] {subprocess.py:86} INFO - Output:
[2023-11-01T15:21:52.716+0000] {subprocess.py:93} INFO - docker: Cannot connect to the Docker daemon at unix:///var/run/docker.sock. Is the docker daemon running?.
[2023-11-01T15:21:52.717+0000] {subprocess.py:93} INFO - See 'docker run --help'.
[2023-11-01T15:21:52.724+0000] {subprocess.py:97} INFO - Command exited with return code 125
[2023-11-01T15:21:52.745+0000] {taskinstance.py:1937} ERROR - Task failed with exception
Traceback (most recent call last):
  File "/home/airflow/.local/lib/python3.8/site-packages/airflow/operators/bash.py", line 210, in execute
    raise AirflowException(
airflow.exceptions.AirflowException: Bash command failed. The command returned a non-zero exit code 125.
[2023-11-01T15:21:52.756+0000] {taskinstance.py:1400} INFO - Marking task as UP_FOR_RETRY. dag_id=good_morning_1, task_id=get_cur_rate, execution_date=20231101T152146, start_date=20231101T152152, end_date=20231101T152152
[2023-11-01T15:21:52.792+0000] {standard_task_runner.py:104} ERROR - Failed to execute job 14 for task get_cur_rate (Bash command failed. The command returned a non-zero exit code 125.; 3891)
[2023-11-01T15:21:52.829+0000] {local_task_job_runner.py:228} INFO - Task exited with return code 1
[2023-11-01T15:21:52.870+0000] {taskinstance.py:2778} INFO - 0 downstream tasks scheduled from follow-on schedule check
