[2023-11-03T19:42:38.850+0000] {processor.py:157} INFO - Started process (PID=33479) to work on /opt/airflow/dags/04_ELT_example2.py
[2023-11-03T19:42:38.855+0000] {processor.py:829} INFO - Processing file /opt/airflow/dags/04_ELT_example2.py for tasks to queue
[2023-11-03T19:42:38.867+0000] {logging_mixin.py:151} INFO - [2023-11-03T19:42:38.865+0000] {dagbag.py:536} INFO - Filling up the DagBag from /opt/airflow/dags/04_ELT_example2.py
[2023-11-03T19:42:38.973+0000] {logging_mixin.py:151} INFO - [2023-11-03T19:42:38.962+0000] {dagbag.py:346} ERROR - Failed to import: /opt/airflow/dags/04_ELT_example2.py
Traceback (most recent call last):
  File "/home/airflow/.local/lib/python3.8/site-packages/airflow/models/dagbag.py", line 342, in parse
    loader.exec_module(new_module)
  File "<frozen importlib._bootstrap_external>", line 843, in exec_module
  File "<frozen importlib._bootstrap>", line 219, in _call_with_frames_removed
  File "/opt/airflow/dags/04_ELT_example2.py", line 19, in <module>
    conn_id = Variable.get("conn_name")
  File "/home/airflow/.local/lib/python3.8/site-packages/airflow/models/variable.py", line 140, in get
    raise KeyError(f"Variable {key} does not exist")
KeyError: 'Variable conn_name does not exist'
[2023-11-03T19:42:38.982+0000] {processor.py:841} WARNING - No viable dags retrieved from /opt/airflow/dags/04_ELT_example2.py
[2023-11-03T19:42:39.063+0000] {processor.py:179} INFO - Processing /opt/airflow/dags/04_ELT_example2.py took 0.233 seconds
[2023-11-03T19:43:10.128+0000] {processor.py:157} INFO - Started process (PID=33541) to work on /opt/airflow/dags/04_ELT_example2.py
[2023-11-03T19:43:10.131+0000] {processor.py:829} INFO - Processing file /opt/airflow/dags/04_ELT_example2.py for tasks to queue
[2023-11-03T19:43:10.138+0000] {logging_mixin.py:151} INFO - [2023-11-03T19:43:10.137+0000] {dagbag.py:536} INFO - Filling up the DagBag from /opt/airflow/dags/04_ELT_example2.py
[2023-11-03T19:43:10.201+0000] {logging_mixin.py:151} INFO - [2023-11-03T19:43:10.197+0000] {dagbag.py:346} ERROR - Failed to import: /opt/airflow/dags/04_ELT_example2.py
Traceback (most recent call last):
  File "/home/airflow/.local/lib/python3.8/site-packages/airflow/models/dagbag.py", line 342, in parse
    loader.exec_module(new_module)
  File "<frozen importlib._bootstrap_external>", line 843, in exec_module
  File "<frozen importlib._bootstrap>", line 219, in _call_with_frames_removed
  File "/opt/airflow/dags/04_ELT_example2.py", line 19, in <module>
    conn_id = Variable.get("conn_name")
  File "/home/airflow/.local/lib/python3.8/site-packages/airflow/models/variable.py", line 140, in get
    raise KeyError(f"Variable {key} does not exist")
KeyError: 'Variable conn_name does not exist'
[2023-11-03T19:43:10.204+0000] {processor.py:841} WARNING - No viable dags retrieved from /opt/airflow/dags/04_ELT_example2.py
[2023-11-03T19:43:10.240+0000] {processor.py:179} INFO - Processing /opt/airflow/dags/04_ELT_example2.py took 0.120 seconds
[2023-11-03T19:43:41.141+0000] {processor.py:157} INFO - Started process (PID=33603) to work on /opt/airflow/dags/04_ELT_example2.py
[2023-11-03T19:43:41.143+0000] {processor.py:829} INFO - Processing file /opt/airflow/dags/04_ELT_example2.py for tasks to queue
[2023-11-03T19:43:41.150+0000] {logging_mixin.py:151} INFO - [2023-11-03T19:43:41.149+0000] {dagbag.py:536} INFO - Filling up the DagBag from /opt/airflow/dags/04_ELT_example2.py
[2023-11-03T19:43:41.201+0000] {logging_mixin.py:151} INFO - [2023-11-03T19:43:41.197+0000] {dagbag.py:346} ERROR - Failed to import: /opt/airflow/dags/04_ELT_example2.py
Traceback (most recent call last):
  File "/home/airflow/.local/lib/python3.8/site-packages/airflow/models/dagbag.py", line 342, in parse
    loader.exec_module(new_module)
  File "<frozen importlib._bootstrap_external>", line 843, in exec_module
  File "<frozen importlib._bootstrap>", line 219, in _call_with_frames_removed
  File "/opt/airflow/dags/04_ELT_example2.py", line 19, in <module>
    conn_id = Variable.get("conn_name")
  File "/home/airflow/.local/lib/python3.8/site-packages/airflow/models/variable.py", line 140, in get
    raise KeyError(f"Variable {key} does not exist")
KeyError: 'Variable conn_name does not exist'
[2023-11-03T19:43:41.205+0000] {processor.py:841} WARNING - No viable dags retrieved from /opt/airflow/dags/04_ELT_example2.py
[2023-11-03T19:43:41.234+0000] {processor.py:179} INFO - Processing /opt/airflow/dags/04_ELT_example2.py took 0.100 seconds
[2023-11-03T19:44:11.566+0000] {processor.py:157} INFO - Started process (PID=33665) to work on /opt/airflow/dags/04_ELT_example2.py
[2023-11-03T19:44:11.568+0000] {processor.py:829} INFO - Processing file /opt/airflow/dags/04_ELT_example2.py for tasks to queue
[2023-11-03T19:44:11.575+0000] {logging_mixin.py:151} INFO - [2023-11-03T19:44:11.574+0000] {dagbag.py:536} INFO - Filling up the DagBag from /opt/airflow/dags/04_ELT_example2.py
[2023-11-03T19:44:11.637+0000] {logging_mixin.py:151} INFO - [2023-11-03T19:44:11.632+0000] {dagbag.py:346} ERROR - Failed to import: /opt/airflow/dags/04_ELT_example2.py
Traceback (most recent call last):
  File "/home/airflow/.local/lib/python3.8/site-packages/airflow/models/dagbag.py", line 342, in parse
    loader.exec_module(new_module)
  File "<frozen importlib._bootstrap_external>", line 843, in exec_module
  File "<frozen importlib._bootstrap>", line 219, in _call_with_frames_removed
  File "/opt/airflow/dags/04_ELT_example2.py", line 19, in <module>
    conn_id = Variable.get("conn_name")
  File "/home/airflow/.local/lib/python3.8/site-packages/airflow/models/variable.py", line 140, in get
    raise KeyError(f"Variable {key} does not exist")
KeyError: 'Variable conn_name does not exist'
[2023-11-03T19:44:11.640+0000] {processor.py:841} WARNING - No viable dags retrieved from /opt/airflow/dags/04_ELT_example2.py
[2023-11-03T19:44:11.674+0000] {processor.py:179} INFO - Processing /opt/airflow/dags/04_ELT_example2.py took 0.117 seconds
[2023-11-03T19:44:42.063+0000] {processor.py:157} INFO - Started process (PID=33727) to work on /opt/airflow/dags/04_ELT_example2.py
[2023-11-03T19:44:42.066+0000] {processor.py:829} INFO - Processing file /opt/airflow/dags/04_ELT_example2.py for tasks to queue
[2023-11-03T19:44:42.074+0000] {logging_mixin.py:151} INFO - [2023-11-03T19:44:42.072+0000] {dagbag.py:536} INFO - Filling up the DagBag from /opt/airflow/dags/04_ELT_example2.py
[2023-11-03T19:44:42.134+0000] {logging_mixin.py:151} INFO - [2023-11-03T19:44:42.130+0000] {dagbag.py:346} ERROR - Failed to import: /opt/airflow/dags/04_ELT_example2.py
Traceback (most recent call last):
  File "/home/airflow/.local/lib/python3.8/site-packages/airflow/models/dagbag.py", line 342, in parse
    loader.exec_module(new_module)
  File "<frozen importlib._bootstrap_external>", line 843, in exec_module
  File "<frozen importlib._bootstrap>", line 219, in _call_with_frames_removed
  File "/opt/airflow/dags/04_ELT_example2.py", line 19, in <module>
    conn_id = Variable.get("conn_name")
  File "/home/airflow/.local/lib/python3.8/site-packages/airflow/models/variable.py", line 140, in get
    raise KeyError(f"Variable {key} does not exist")
KeyError: 'Variable conn_name does not exist'
[2023-11-03T19:44:42.136+0000] {processor.py:841} WARNING - No viable dags retrieved from /opt/airflow/dags/04_ELT_example2.py
[2023-11-03T19:44:42.170+0000] {processor.py:179} INFO - Processing /opt/airflow/dags/04_ELT_example2.py took 0.116 seconds
[2023-11-03T19:45:12.367+0000] {processor.py:157} INFO - Started process (PID=33789) to work on /opt/airflow/dags/04_ELT_example2.py
[2023-11-03T19:45:12.370+0000] {processor.py:829} INFO - Processing file /opt/airflow/dags/04_ELT_example2.py for tasks to queue
[2023-11-03T19:45:12.378+0000] {logging_mixin.py:151} INFO - [2023-11-03T19:45:12.376+0000] {dagbag.py:536} INFO - Filling up the DagBag from /opt/airflow/dags/04_ELT_example2.py
[2023-11-03T19:45:12.433+0000] {logging_mixin.py:151} INFO - [2023-11-03T19:45:12.429+0000] {dagbag.py:346} ERROR - Failed to import: /opt/airflow/dags/04_ELT_example2.py
Traceback (most recent call last):
  File "/home/airflow/.local/lib/python3.8/site-packages/airflow/models/dagbag.py", line 342, in parse
    loader.exec_module(new_module)
  File "<frozen importlib._bootstrap_external>", line 843, in exec_module
  File "<frozen importlib._bootstrap>", line 219, in _call_with_frames_removed
  File "/opt/airflow/dags/04_ELT_example2.py", line 19, in <module>
    conn_id = Variable.get("conn_name")
  File "/home/airflow/.local/lib/python3.8/site-packages/airflow/models/variable.py", line 140, in get
    raise KeyError(f"Variable {key} does not exist")
KeyError: 'Variable conn_name does not exist'
[2023-11-03T19:45:12.436+0000] {processor.py:841} WARNING - No viable dags retrieved from /opt/airflow/dags/04_ELT_example2.py
[2023-11-03T19:45:12.465+0000] {processor.py:179} INFO - Processing /opt/airflow/dags/04_ELT_example2.py took 0.107 seconds
[2023-11-03T19:45:43.270+0000] {processor.py:157} INFO - Started process (PID=33852) to work on /opt/airflow/dags/04_ELT_example2.py
[2023-11-03T19:45:43.273+0000] {processor.py:829} INFO - Processing file /opt/airflow/dags/04_ELT_example2.py for tasks to queue
[2023-11-03T19:45:43.280+0000] {logging_mixin.py:151} INFO - [2023-11-03T19:45:43.278+0000] {dagbag.py:536} INFO - Filling up the DagBag from /opt/airflow/dags/04_ELT_example2.py
[2023-11-03T19:45:43.327+0000] {logging_mixin.py:151} INFO - [2023-11-03T19:45:43.324+0000] {dagbag.py:346} ERROR - Failed to import: /opt/airflow/dags/04_ELT_example2.py
Traceback (most recent call last):
  File "/home/airflow/.local/lib/python3.8/site-packages/airflow/models/dagbag.py", line 342, in parse
    loader.exec_module(new_module)
  File "<frozen importlib._bootstrap_external>", line 843, in exec_module
  File "<frozen importlib._bootstrap>", line 219, in _call_with_frames_removed
  File "/opt/airflow/dags/04_ELT_example2.py", line 19, in <module>
    conn_id = Variable.get("conn_name")
  File "/home/airflow/.local/lib/python3.8/site-packages/airflow/models/variable.py", line 140, in get
    raise KeyError(f"Variable {key} does not exist")
KeyError: 'Variable conn_name does not exist'
[2023-11-03T19:45:43.329+0000] {processor.py:841} WARNING - No viable dags retrieved from /opt/airflow/dags/04_ELT_example2.py
[2023-11-03T19:45:43.358+0000] {processor.py:179} INFO - Processing /opt/airflow/dags/04_ELT_example2.py took 0.099 seconds
[2023-11-03T19:46:13.530+0000] {processor.py:157} INFO - Started process (PID=33913) to work on /opt/airflow/dags/04_ELT_example2.py
[2023-11-03T19:46:13.534+0000] {processor.py:829} INFO - Processing file /opt/airflow/dags/04_ELT_example2.py for tasks to queue
[2023-11-03T19:46:13.543+0000] {logging_mixin.py:151} INFO - [2023-11-03T19:46:13.541+0000] {dagbag.py:536} INFO - Filling up the DagBag from /opt/airflow/dags/04_ELT_example2.py
[2023-11-03T19:46:13.600+0000] {logging_mixin.py:151} INFO - [2023-11-03T19:46:13.596+0000] {dagbag.py:346} ERROR - Failed to import: /opt/airflow/dags/04_ELT_example2.py
Traceback (most recent call last):
  File "/home/airflow/.local/lib/python3.8/site-packages/airflow/models/dagbag.py", line 342, in parse
    loader.exec_module(new_module)
  File "<frozen importlib._bootstrap_external>", line 843, in exec_module
  File "<frozen importlib._bootstrap>", line 219, in _call_with_frames_removed
  File "/opt/airflow/dags/04_ELT_example2.py", line 19, in <module>
    conn_id = Variable.get("conn_name")
  File "/home/airflow/.local/lib/python3.8/site-packages/airflow/models/variable.py", line 140, in get
    raise KeyError(f"Variable {key} does not exist")
KeyError: 'Variable conn_name does not exist'
[2023-11-03T19:46:13.602+0000] {processor.py:841} WARNING - No viable dags retrieved from /opt/airflow/dags/04_ELT_example2.py
[2023-11-03T19:46:13.630+0000] {processor.py:179} INFO - Processing /opt/airflow/dags/04_ELT_example2.py took 0.112 seconds
[2023-11-03T19:46:44.253+0000] {processor.py:157} INFO - Started process (PID=33976) to work on /opt/airflow/dags/04_ELT_example2.py
[2023-11-03T19:46:44.256+0000] {processor.py:829} INFO - Processing file /opt/airflow/dags/04_ELT_example2.py for tasks to queue
[2023-11-03T19:46:44.267+0000] {logging_mixin.py:151} INFO - [2023-11-03T19:46:44.265+0000] {dagbag.py:536} INFO - Filling up the DagBag from /opt/airflow/dags/04_ELT_example2.py
[2023-11-03T19:46:44.339+0000] {logging_mixin.py:151} INFO - [2023-11-03T19:46:44.333+0000] {dagbag.py:346} ERROR - Failed to import: /opt/airflow/dags/04_ELT_example2.py
Traceback (most recent call last):
  File "/home/airflow/.local/lib/python3.8/site-packages/airflow/models/dagbag.py", line 342, in parse
    loader.exec_module(new_module)
  File "<frozen importlib._bootstrap_external>", line 843, in exec_module
  File "<frozen importlib._bootstrap>", line 219, in _call_with_frames_removed
  File "/opt/airflow/dags/04_ELT_example2.py", line 19, in <module>
    conn_id = Variable.get("conn_name")
  File "/home/airflow/.local/lib/python3.8/site-packages/airflow/models/variable.py", line 140, in get
    raise KeyError(f"Variable {key} does not exist")
KeyError: 'Variable conn_name does not exist'
[2023-11-03T19:46:44.347+0000] {processor.py:841} WARNING - No viable dags retrieved from /opt/airflow/dags/04_ELT_example2.py
[2023-11-03T19:46:44.382+0000] {processor.py:179} INFO - Processing /opt/airflow/dags/04_ELT_example2.py took 0.140 seconds
[2023-11-03T19:47:14.735+0000] {processor.py:157} INFO - Started process (PID=34038) to work on /opt/airflow/dags/04_ELT_example2.py
[2023-11-03T19:47:14.738+0000] {processor.py:829} INFO - Processing file /opt/airflow/dags/04_ELT_example2.py for tasks to queue
[2023-11-03T19:47:14.746+0000] {logging_mixin.py:151} INFO - [2023-11-03T19:47:14.745+0000] {dagbag.py:536} INFO - Filling up the DagBag from /opt/airflow/dags/04_ELT_example2.py
[2023-11-03T19:47:14.818+0000] {logging_mixin.py:151} INFO - [2023-11-03T19:47:14.812+0000] {dagbag.py:346} ERROR - Failed to import: /opt/airflow/dags/04_ELT_example2.py
Traceback (most recent call last):
  File "/home/airflow/.local/lib/python3.8/site-packages/airflow/models/dagbag.py", line 342, in parse
    loader.exec_module(new_module)
  File "<frozen importlib._bootstrap_external>", line 843, in exec_module
  File "<frozen importlib._bootstrap>", line 219, in _call_with_frames_removed
  File "/opt/airflow/dags/04_ELT_example2.py", line 19, in <module>
    conn_id = Variable.get("conn_name")
  File "/home/airflow/.local/lib/python3.8/site-packages/airflow/models/variable.py", line 140, in get
    raise KeyError(f"Variable {key} does not exist")
KeyError: 'Variable conn_name does not exist'
[2023-11-03T19:47:14.820+0000] {processor.py:841} WARNING - No viable dags retrieved from /opt/airflow/dags/04_ELT_example2.py
[2023-11-03T19:47:14.857+0000] {processor.py:179} INFO - Processing /opt/airflow/dags/04_ELT_example2.py took 0.129 seconds
[2023-11-03T19:47:45.305+0000] {processor.py:157} INFO - Started process (PID=34100) to work on /opt/airflow/dags/04_ELT_example2.py
[2023-11-03T19:47:45.307+0000] {processor.py:829} INFO - Processing file /opt/airflow/dags/04_ELT_example2.py for tasks to queue
[2023-11-03T19:47:45.315+0000] {logging_mixin.py:151} INFO - [2023-11-03T19:47:45.313+0000] {dagbag.py:536} INFO - Filling up the DagBag from /opt/airflow/dags/04_ELT_example2.py
[2023-11-03T19:47:45.364+0000] {logging_mixin.py:151} INFO - [2023-11-03T19:47:45.361+0000] {dagbag.py:346} ERROR - Failed to import: /opt/airflow/dags/04_ELT_example2.py
Traceback (most recent call last):
  File "/home/airflow/.local/lib/python3.8/site-packages/airflow/models/dagbag.py", line 342, in parse
    loader.exec_module(new_module)
  File "<frozen importlib._bootstrap_external>", line 843, in exec_module
  File "<frozen importlib._bootstrap>", line 219, in _call_with_frames_removed
  File "/opt/airflow/dags/04_ELT_example2.py", line 19, in <module>
    conn_id = Variable.get("conn_name")
  File "/home/airflow/.local/lib/python3.8/site-packages/airflow/models/variable.py", line 140, in get
    raise KeyError(f"Variable {key} does not exist")
KeyError: 'Variable conn_name does not exist'
[2023-11-03T19:47:45.366+0000] {processor.py:841} WARNING - No viable dags retrieved from /opt/airflow/dags/04_ELT_example2.py
[2023-11-03T19:47:45.394+0000] {processor.py:179} INFO - Processing /opt/airflow/dags/04_ELT_example2.py took 0.100 seconds
[2023-11-03T19:48:15.988+0000] {processor.py:157} INFO - Started process (PID=34162) to work on /opt/airflow/dags/04_ELT_example2.py
[2023-11-03T19:48:15.991+0000] {processor.py:829} INFO - Processing file /opt/airflow/dags/04_ELT_example2.py for tasks to queue
[2023-11-03T19:48:15.997+0000] {logging_mixin.py:151} INFO - [2023-11-03T19:48:15.996+0000] {dagbag.py:536} INFO - Filling up the DagBag from /opt/airflow/dags/04_ELT_example2.py
[2023-11-03T19:48:16.047+0000] {logging_mixin.py:151} INFO - [2023-11-03T19:48:16.043+0000] {dagbag.py:346} ERROR - Failed to import: /opt/airflow/dags/04_ELT_example2.py
Traceback (most recent call last):
  File "/home/airflow/.local/lib/python3.8/site-packages/airflow/models/dagbag.py", line 342, in parse
    loader.exec_module(new_module)
  File "<frozen importlib._bootstrap_external>", line 843, in exec_module
  File "<frozen importlib._bootstrap>", line 219, in _call_with_frames_removed
  File "/opt/airflow/dags/04_ELT_example2.py", line 19, in <module>
    conn_id = Variable.get("conn_name")
  File "/home/airflow/.local/lib/python3.8/site-packages/airflow/models/variable.py", line 140, in get
    raise KeyError(f"Variable {key} does not exist")
KeyError: 'Variable conn_name does not exist'
[2023-11-03T19:48:16.049+0000] {processor.py:841} WARNING - No viable dags retrieved from /opt/airflow/dags/04_ELT_example2.py
[2023-11-03T19:48:16.083+0000] {processor.py:179} INFO - Processing /opt/airflow/dags/04_ELT_example2.py took 0.101 seconds
[2023-11-03T19:48:46.655+0000] {processor.py:157} INFO - Started process (PID=34224) to work on /opt/airflow/dags/04_ELT_example2.py
[2023-11-03T19:48:46.658+0000] {processor.py:829} INFO - Processing file /opt/airflow/dags/04_ELT_example2.py for tasks to queue
[2023-11-03T19:48:46.668+0000] {logging_mixin.py:151} INFO - [2023-11-03T19:48:46.667+0000] {dagbag.py:536} INFO - Filling up the DagBag from /opt/airflow/dags/04_ELT_example2.py
[2023-11-03T19:48:46.723+0000] {logging_mixin.py:151} INFO - [2023-11-03T19:48:46.720+0000] {dagbag.py:346} ERROR - Failed to import: /opt/airflow/dags/04_ELT_example2.py
Traceback (most recent call last):
  File "/home/airflow/.local/lib/python3.8/site-packages/airflow/models/dagbag.py", line 342, in parse
    loader.exec_module(new_module)
  File "<frozen importlib._bootstrap_external>", line 843, in exec_module
  File "<frozen importlib._bootstrap>", line 219, in _call_with_frames_removed
  File "/opt/airflow/dags/04_ELT_example2.py", line 19, in <module>
    conn_id = Variable.get("conn_name")
  File "/home/airflow/.local/lib/python3.8/site-packages/airflow/models/variable.py", line 140, in get
    raise KeyError(f"Variable {key} does not exist")
KeyError: 'Variable conn_name does not exist'
[2023-11-03T19:48:46.725+0000] {processor.py:841} WARNING - No viable dags retrieved from /opt/airflow/dags/04_ELT_example2.py
[2023-11-03T19:48:46.755+0000] {processor.py:179} INFO - Processing /opt/airflow/dags/04_ELT_example2.py took 0.111 seconds
[2023-11-03T19:49:17.230+0000] {processor.py:157} INFO - Started process (PID=34286) to work on /opt/airflow/dags/04_ELT_example2.py
[2023-11-03T19:49:17.232+0000] {processor.py:829} INFO - Processing file /opt/airflow/dags/04_ELT_example2.py for tasks to queue
[2023-11-03T19:49:17.239+0000] {logging_mixin.py:151} INFO - [2023-11-03T19:49:17.238+0000] {dagbag.py:536} INFO - Filling up the DagBag from /opt/airflow/dags/04_ELT_example2.py
[2023-11-03T19:49:17.297+0000] {logging_mixin.py:151} INFO - [2023-11-03T19:49:17.293+0000] {dagbag.py:346} ERROR - Failed to import: /opt/airflow/dags/04_ELT_example2.py
Traceback (most recent call last):
  File "/home/airflow/.local/lib/python3.8/site-packages/airflow/models/dagbag.py", line 342, in parse
    loader.exec_module(new_module)
  File "<frozen importlib._bootstrap_external>", line 843, in exec_module
  File "<frozen importlib._bootstrap>", line 219, in _call_with_frames_removed
  File "/opt/airflow/dags/04_ELT_example2.py", line 19, in <module>
    conn_id = Variable.get("conn_name")
  File "/home/airflow/.local/lib/python3.8/site-packages/airflow/models/variable.py", line 140, in get
    raise KeyError(f"Variable {key} does not exist")
KeyError: 'Variable conn_name does not exist'
[2023-11-03T19:49:17.300+0000] {processor.py:841} WARNING - No viable dags retrieved from /opt/airflow/dags/04_ELT_example2.py
[2023-11-03T19:49:17.340+0000] {processor.py:179} INFO - Processing /opt/airflow/dags/04_ELT_example2.py took 0.120 seconds
[2023-11-03T19:49:47.529+0000] {processor.py:157} INFO - Started process (PID=34347) to work on /opt/airflow/dags/04_ELT_example2.py
[2023-11-03T19:49:47.541+0000] {processor.py:829} INFO - Processing file /opt/airflow/dags/04_ELT_example2.py for tasks to queue
[2023-11-03T19:49:47.549+0000] {logging_mixin.py:151} INFO - [2023-11-03T19:49:47.548+0000] {dagbag.py:536} INFO - Filling up the DagBag from /opt/airflow/dags/04_ELT_example2.py
[2023-11-03T19:49:47.603+0000] {logging_mixin.py:151} INFO - [2023-11-03T19:49:47.600+0000] {dagbag.py:346} ERROR - Failed to import: /opt/airflow/dags/04_ELT_example2.py
Traceback (most recent call last):
  File "/home/airflow/.local/lib/python3.8/site-packages/airflow/models/dagbag.py", line 342, in parse
    loader.exec_module(new_module)
  File "<frozen importlib._bootstrap_external>", line 843, in exec_module
  File "<frozen importlib._bootstrap>", line 219, in _call_with_frames_removed
  File "/opt/airflow/dags/04_ELT_example2.py", line 19, in <module>
    conn_id = Variable.get("conn_name")
  File "/home/airflow/.local/lib/python3.8/site-packages/airflow/models/variable.py", line 140, in get
    raise KeyError(f"Variable {key} does not exist")
KeyError: 'Variable conn_name does not exist'
[2023-11-03T19:49:47.605+0000] {processor.py:841} WARNING - No viable dags retrieved from /opt/airflow/dags/04_ELT_example2.py
[2023-11-03T19:49:47.634+0000] {processor.py:179} INFO - Processing /opt/airflow/dags/04_ELT_example2.py took 0.117 seconds
[2023-11-03T19:50:18.589+0000] {processor.py:157} INFO - Started process (PID=34410) to work on /opt/airflow/dags/04_ELT_example2.py
[2023-11-03T19:50:18.591+0000] {processor.py:829} INFO - Processing file /opt/airflow/dags/04_ELT_example2.py for tasks to queue
[2023-11-03T19:50:18.600+0000] {logging_mixin.py:151} INFO - [2023-11-03T19:50:18.598+0000] {dagbag.py:536} INFO - Filling up the DagBag from /opt/airflow/dags/04_ELT_example2.py
[2023-11-03T19:50:18.665+0000] {logging_mixin.py:151} INFO - [2023-11-03T19:50:18.661+0000] {dagbag.py:346} ERROR - Failed to import: /opt/airflow/dags/04_ELT_example2.py
Traceback (most recent call last):
  File "/home/airflow/.local/lib/python3.8/site-packages/airflow/models/dagbag.py", line 342, in parse
    loader.exec_module(new_module)
  File "<frozen importlib._bootstrap_external>", line 843, in exec_module
  File "<frozen importlib._bootstrap>", line 219, in _call_with_frames_removed
  File "/opt/airflow/dags/04_ELT_example2.py", line 19, in <module>
    conn_id = Variable.get("conn_name")
  File "/home/airflow/.local/lib/python3.8/site-packages/airflow/models/variable.py", line 140, in get
    raise KeyError(f"Variable {key} does not exist")
KeyError: 'Variable conn_name does not exist'
[2023-11-03T19:50:18.667+0000] {processor.py:841} WARNING - No viable dags retrieved from /opt/airflow/dags/04_ELT_example2.py
[2023-11-03T19:50:18.700+0000] {processor.py:179} INFO - Processing /opt/airflow/dags/04_ELT_example2.py took 0.121 seconds
[2023-11-03T19:50:49.293+0000] {processor.py:157} INFO - Started process (PID=34472) to work on /opt/airflow/dags/04_ELT_example2.py
[2023-11-03T19:50:49.296+0000] {processor.py:829} INFO - Processing file /opt/airflow/dags/04_ELT_example2.py for tasks to queue
[2023-11-03T19:50:49.303+0000] {logging_mixin.py:151} INFO - [2023-11-03T19:50:49.302+0000] {dagbag.py:536} INFO - Filling up the DagBag from /opt/airflow/dags/04_ELT_example2.py
[2023-11-03T19:50:49.351+0000] {logging_mixin.py:151} INFO - [2023-11-03T19:50:49.347+0000] {dagbag.py:346} ERROR - Failed to import: /opt/airflow/dags/04_ELT_example2.py
Traceback (most recent call last):
  File "/home/airflow/.local/lib/python3.8/site-packages/airflow/models/dagbag.py", line 342, in parse
    loader.exec_module(new_module)
  File "<frozen importlib._bootstrap_external>", line 843, in exec_module
  File "<frozen importlib._bootstrap>", line 219, in _call_with_frames_removed
  File "/opt/airflow/dags/04_ELT_example2.py", line 19, in <module>
    conn_id = Variable.get("conn_name")
  File "/home/airflow/.local/lib/python3.8/site-packages/airflow/models/variable.py", line 140, in get
    raise KeyError(f"Variable {key} does not exist")
KeyError: 'Variable conn_name does not exist'
[2023-11-03T19:50:49.353+0000] {processor.py:841} WARNING - No viable dags retrieved from /opt/airflow/dags/04_ELT_example2.py
[2023-11-03T19:50:49.383+0000] {processor.py:179} INFO - Processing /opt/airflow/dags/04_ELT_example2.py took 0.102 seconds
[2023-11-03T19:51:19.640+0000] {processor.py:157} INFO - Started process (PID=34534) to work on /opt/airflow/dags/04_ELT_example2.py
[2023-11-03T19:51:19.643+0000] {processor.py:829} INFO - Processing file /opt/airflow/dags/04_ELT_example2.py for tasks to queue
[2023-11-03T19:51:19.653+0000] {logging_mixin.py:151} INFO - [2023-11-03T19:51:19.651+0000] {dagbag.py:536} INFO - Filling up the DagBag from /opt/airflow/dags/04_ELT_example2.py
[2023-11-03T19:51:19.712+0000] {logging_mixin.py:151} INFO - [2023-11-03T19:51:19.708+0000] {dagbag.py:346} ERROR - Failed to import: /opt/airflow/dags/04_ELT_example2.py
Traceback (most recent call last):
  File "/home/airflow/.local/lib/python3.8/site-packages/airflow/models/dagbag.py", line 342, in parse
    loader.exec_module(new_module)
  File "<frozen importlib._bootstrap_external>", line 843, in exec_module
  File "<frozen importlib._bootstrap>", line 219, in _call_with_frames_removed
  File "/opt/airflow/dags/04_ELT_example2.py", line 19, in <module>
    conn_id = Variable.get("conn_name")
  File "/home/airflow/.local/lib/python3.8/site-packages/airflow/models/variable.py", line 140, in get
    raise KeyError(f"Variable {key} does not exist")
KeyError: 'Variable conn_name does not exist'
[2023-11-03T19:51:19.714+0000] {processor.py:841} WARNING - No viable dags retrieved from /opt/airflow/dags/04_ELT_example2.py
[2023-11-03T19:51:19.742+0000] {processor.py:179} INFO - Processing /opt/airflow/dags/04_ELT_example2.py took 0.115 seconds
[2023-11-03T19:51:49.952+0000] {processor.py:157} INFO - Started process (PID=34596) to work on /opt/airflow/dags/04_ELT_example2.py
[2023-11-03T19:51:49.955+0000] {processor.py:829} INFO - Processing file /opt/airflow/dags/04_ELT_example2.py for tasks to queue
[2023-11-03T19:51:49.963+0000] {logging_mixin.py:151} INFO - [2023-11-03T19:51:49.962+0000] {dagbag.py:536} INFO - Filling up the DagBag from /opt/airflow/dags/04_ELT_example2.py
[2023-11-03T19:51:50.023+0000] {logging_mixin.py:151} INFO - [2023-11-03T19:51:50.018+0000] {dagbag.py:346} ERROR - Failed to import: /opt/airflow/dags/04_ELT_example2.py
Traceback (most recent call last):
  File "/home/airflow/.local/lib/python3.8/site-packages/airflow/models/dagbag.py", line 342, in parse
    loader.exec_module(new_module)
  File "<frozen importlib._bootstrap_external>", line 843, in exec_module
  File "<frozen importlib._bootstrap>", line 219, in _call_with_frames_removed
  File "/opt/airflow/dags/04_ELT_example2.py", line 19, in <module>
    conn_id = Variable.get("conn_name")
  File "/home/airflow/.local/lib/python3.8/site-packages/airflow/models/variable.py", line 140, in get
    raise KeyError(f"Variable {key} does not exist")
KeyError: 'Variable conn_name does not exist'
[2023-11-03T19:51:50.026+0000] {processor.py:841} WARNING - No viable dags retrieved from /opt/airflow/dags/04_ELT_example2.py
[2023-11-03T19:51:50.064+0000] {processor.py:179} INFO - Processing /opt/airflow/dags/04_ELT_example2.py took 0.122 seconds
[2023-11-03T19:52:20.167+0000] {processor.py:157} INFO - Started process (PID=34655) to work on /opt/airflow/dags/04_ELT_example2.py
[2023-11-03T19:52:20.170+0000] {processor.py:829} INFO - Processing file /opt/airflow/dags/04_ELT_example2.py for tasks to queue
[2023-11-03T19:52:20.177+0000] {logging_mixin.py:151} INFO - [2023-11-03T19:52:20.176+0000] {dagbag.py:536} INFO - Filling up the DagBag from /opt/airflow/dags/04_ELT_example2.py
[2023-11-03T19:52:20.284+0000] {logging_mixin.py:151} INFO - [2023-11-03T19:52:20.280+0000] {dagbag.py:346} ERROR - Failed to import: /opt/airflow/dags/04_ELT_example2.py
Traceback (most recent call last):
  File "/home/airflow/.local/lib/python3.8/site-packages/airflow/models/dagbag.py", line 342, in parse
    loader.exec_module(new_module)
  File "<frozen importlib._bootstrap_external>", line 843, in exec_module
  File "<frozen importlib._bootstrap>", line 219, in _call_with_frames_removed
  File "/opt/airflow/dags/04_ELT_example2.py", line 19, in <module>
    conn_id = Variable.get("conn_name")
  File "/home/airflow/.local/lib/python3.8/site-packages/airflow/models/variable.py", line 140, in get
    raise KeyError(f"Variable {key} does not exist")
KeyError: 'Variable conn_name does not exist'
[2023-11-03T19:52:20.287+0000] {processor.py:841} WARNING - No viable dags retrieved from /opt/airflow/dags/04_ELT_example2.py
[2023-11-03T19:52:20.326+0000] {processor.py:179} INFO - Processing /opt/airflow/dags/04_ELT_example2.py took 0.167 seconds
[2023-11-03T19:52:50.526+0000] {processor.py:157} INFO - Started process (PID=34717) to work on /opt/airflow/dags/04_ELT_example2.py
[2023-11-03T19:52:50.529+0000] {processor.py:829} INFO - Processing file /opt/airflow/dags/04_ELT_example2.py for tasks to queue
[2023-11-03T19:52:50.538+0000] {logging_mixin.py:151} INFO - [2023-11-03T19:52:50.536+0000] {dagbag.py:536} INFO - Filling up the DagBag from /opt/airflow/dags/04_ELT_example2.py
[2023-11-03T19:52:50.598+0000] {logging_mixin.py:151} INFO - [2023-11-03T19:52:50.593+0000] {dagbag.py:346} ERROR - Failed to import: /opt/airflow/dags/04_ELT_example2.py
Traceback (most recent call last):
  File "/home/airflow/.local/lib/python3.8/site-packages/airflow/models/dagbag.py", line 342, in parse
    loader.exec_module(new_module)
  File "<frozen importlib._bootstrap_external>", line 843, in exec_module
  File "<frozen importlib._bootstrap>", line 219, in _call_with_frames_removed
  File "/opt/airflow/dags/04_ELT_example2.py", line 19, in <module>
    conn_id = Variable.get("conn_name")
  File "/home/airflow/.local/lib/python3.8/site-packages/airflow/models/variable.py", line 140, in get
    raise KeyError(f"Variable {key} does not exist")
KeyError: 'Variable conn_name does not exist'
[2023-11-03T19:52:50.600+0000] {processor.py:841} WARNING - No viable dags retrieved from /opt/airflow/dags/04_ELT_example2.py
[2023-11-03T19:52:50.633+0000] {processor.py:179} INFO - Processing /opt/airflow/dags/04_ELT_example2.py took 0.115 seconds
[2023-11-03T19:53:20.737+0000] {processor.py:157} INFO - Started process (PID=34778) to work on /opt/airflow/dags/04_ELT_example2.py
[2023-11-03T19:53:20.740+0000] {processor.py:829} INFO - Processing file /opt/airflow/dags/04_ELT_example2.py for tasks to queue
[2023-11-03T19:53:20.750+0000] {logging_mixin.py:151} INFO - [2023-11-03T19:53:20.748+0000] {dagbag.py:536} INFO - Filling up the DagBag from /opt/airflow/dags/04_ELT_example2.py
[2023-11-03T19:53:20.799+0000] {logging_mixin.py:151} INFO - [2023-11-03T19:53:20.795+0000] {dagbag.py:346} ERROR - Failed to import: /opt/airflow/dags/04_ELT_example2.py
Traceback (most recent call last):
  File "/home/airflow/.local/lib/python3.8/site-packages/airflow/models/dagbag.py", line 342, in parse
    loader.exec_module(new_module)
  File "<frozen importlib._bootstrap_external>", line 843, in exec_module
  File "<frozen importlib._bootstrap>", line 219, in _call_with_frames_removed
  File "/opt/airflow/dags/04_ELT_example2.py", line 19, in <module>
    conn_id = Variable.get("conn_name")
  File "/home/airflow/.local/lib/python3.8/site-packages/airflow/models/variable.py", line 140, in get
    raise KeyError(f"Variable {key} does not exist")
KeyError: 'Variable conn_name does not exist'
[2023-11-03T19:53:20.801+0000] {processor.py:841} WARNING - No viable dags retrieved from /opt/airflow/dags/04_ELT_example2.py
[2023-11-03T19:53:20.827+0000] {processor.py:179} INFO - Processing /opt/airflow/dags/04_ELT_example2.py took 0.102 seconds
[2023-11-03T19:53:50.969+0000] {processor.py:157} INFO - Started process (PID=34839) to work on /opt/airflow/dags/04_ELT_example2.py
[2023-11-03T19:53:50.972+0000] {processor.py:829} INFO - Processing file /opt/airflow/dags/04_ELT_example2.py for tasks to queue
[2023-11-03T19:53:50.981+0000] {logging_mixin.py:151} INFO - [2023-11-03T19:53:50.980+0000] {dagbag.py:536} INFO - Filling up the DagBag from /opt/airflow/dags/04_ELT_example2.py
[2023-11-03T19:53:51.047+0000] {logging_mixin.py:151} INFO - [2023-11-03T19:53:51.042+0000] {dagbag.py:346} ERROR - Failed to import: /opt/airflow/dags/04_ELT_example2.py
Traceback (most recent call last):
  File "/home/airflow/.local/lib/python3.8/site-packages/airflow/models/dagbag.py", line 342, in parse
    loader.exec_module(new_module)
  File "<frozen importlib._bootstrap_external>", line 843, in exec_module
  File "<frozen importlib._bootstrap>", line 219, in _call_with_frames_removed
  File "/opt/airflow/dags/04_ELT_example2.py", line 19, in <module>
    conn_id = Variable.get("conn_name")
  File "/home/airflow/.local/lib/python3.8/site-packages/airflow/models/variable.py", line 140, in get
    raise KeyError(f"Variable {key} does not exist")
KeyError: 'Variable conn_name does not exist'
[2023-11-03T19:53:51.049+0000] {processor.py:841} WARNING - No viable dags retrieved from /opt/airflow/dags/04_ELT_example2.py
[2023-11-03T19:53:51.083+0000] {processor.py:179} INFO - Processing /opt/airflow/dags/04_ELT_example2.py took 0.124 seconds
[2023-11-03T19:54:21.239+0000] {processor.py:157} INFO - Started process (PID=34900) to work on /opt/airflow/dags/04_ELT_example2.py
[2023-11-03T19:54:21.242+0000] {processor.py:829} INFO - Processing file /opt/airflow/dags/04_ELT_example2.py for tasks to queue
[2023-11-03T19:54:21.249+0000] {logging_mixin.py:151} INFO - [2023-11-03T19:54:21.248+0000] {dagbag.py:536} INFO - Filling up the DagBag from /opt/airflow/dags/04_ELT_example2.py
[2023-11-03T19:54:21.297+0000] {logging_mixin.py:151} INFO - [2023-11-03T19:54:21.294+0000] {dagbag.py:346} ERROR - Failed to import: /opt/airflow/dags/04_ELT_example2.py
Traceback (most recent call last):
  File "/home/airflow/.local/lib/python3.8/site-packages/airflow/models/dagbag.py", line 342, in parse
    loader.exec_module(new_module)
  File "<frozen importlib._bootstrap_external>", line 843, in exec_module
  File "<frozen importlib._bootstrap>", line 219, in _call_with_frames_removed
  File "/opt/airflow/dags/04_ELT_example2.py", line 19, in <module>
    conn_id = Variable.get("conn_name")
  File "/home/airflow/.local/lib/python3.8/site-packages/airflow/models/variable.py", line 140, in get
    raise KeyError(f"Variable {key} does not exist")
KeyError: 'Variable conn_name does not exist'
[2023-11-03T19:54:21.299+0000] {processor.py:841} WARNING - No viable dags retrieved from /opt/airflow/dags/04_ELT_example2.py
[2023-11-03T19:54:21.329+0000] {processor.py:179} INFO - Processing /opt/airflow/dags/04_ELT_example2.py took 0.097 seconds
[2023-11-03T19:54:51.849+0000] {processor.py:157} INFO - Started process (PID=34963) to work on /opt/airflow/dags/04_ELT_example2.py
[2023-11-03T19:54:51.853+0000] {processor.py:829} INFO - Processing file /opt/airflow/dags/04_ELT_example2.py for tasks to queue
[2023-11-03T19:54:51.864+0000] {logging_mixin.py:151} INFO - [2023-11-03T19:54:51.861+0000] {dagbag.py:536} INFO - Filling up the DagBag from /opt/airflow/dags/04_ELT_example2.py
[2023-11-03T19:54:51.974+0000] {logging_mixin.py:151} INFO - [2023-11-03T19:54:51.970+0000] {dagbag.py:346} ERROR - Failed to import: /opt/airflow/dags/04_ELT_example2.py
Traceback (most recent call last):
  File "/home/airflow/.local/lib/python3.8/site-packages/airflow/models/dagbag.py", line 342, in parse
    loader.exec_module(new_module)
  File "<frozen importlib._bootstrap_external>", line 843, in exec_module
  File "<frozen importlib._bootstrap>", line 219, in _call_with_frames_removed
  File "/opt/airflow/dags/04_ELT_example2.py", line 19, in <module>
    conn_id = Variable.get("conn_name")
  File "/home/airflow/.local/lib/python3.8/site-packages/airflow/models/variable.py", line 140, in get
    raise KeyError(f"Variable {key} does not exist")
KeyError: 'Variable conn_name does not exist'
[2023-11-03T19:54:51.977+0000] {processor.py:841} WARNING - No viable dags retrieved from /opt/airflow/dags/04_ELT_example2.py
[2023-11-03T19:54:52.012+0000] {processor.py:179} INFO - Processing /opt/airflow/dags/04_ELT_example2.py took 0.175 seconds
[2023-11-03T19:55:22.228+0000] {processor.py:157} INFO - Started process (PID=35024) to work on /opt/airflow/dags/04_ELT_example2.py
[2023-11-03T19:55:22.231+0000] {processor.py:829} INFO - Processing file /opt/airflow/dags/04_ELT_example2.py for tasks to queue
[2023-11-03T19:55:22.237+0000] {logging_mixin.py:151} INFO - [2023-11-03T19:55:22.236+0000] {dagbag.py:536} INFO - Filling up the DagBag from /opt/airflow/dags/04_ELT_example2.py
[2023-11-03T19:55:22.290+0000] {logging_mixin.py:151} INFO - [2023-11-03T19:55:22.286+0000] {dagbag.py:346} ERROR - Failed to import: /opt/airflow/dags/04_ELT_example2.py
Traceback (most recent call last):
  File "/home/airflow/.local/lib/python3.8/site-packages/airflow/models/dagbag.py", line 342, in parse
    loader.exec_module(new_module)
  File "<frozen importlib._bootstrap_external>", line 843, in exec_module
  File "<frozen importlib._bootstrap>", line 219, in _call_with_frames_removed
  File "/opt/airflow/dags/04_ELT_example2.py", line 19, in <module>
    conn_id = Variable.get("conn_name")
  File "/home/airflow/.local/lib/python3.8/site-packages/airflow/models/variable.py", line 140, in get
    raise KeyError(f"Variable {key} does not exist")
KeyError: 'Variable conn_name does not exist'
[2023-11-03T19:55:22.292+0000] {processor.py:841} WARNING - No viable dags retrieved from /opt/airflow/dags/04_ELT_example2.py
[2023-11-03T19:55:22.320+0000] {processor.py:179} INFO - Processing /opt/airflow/dags/04_ELT_example2.py took 0.099 seconds
[2023-11-03T19:55:52.439+0000] {processor.py:157} INFO - Started process (PID=35083) to work on /opt/airflow/dags/04_ELT_example2.py
[2023-11-03T19:55:52.443+0000] {processor.py:829} INFO - Processing file /opt/airflow/dags/04_ELT_example2.py for tasks to queue
[2023-11-03T19:55:52.454+0000] {logging_mixin.py:151} INFO - [2023-11-03T19:55:52.452+0000] {dagbag.py:536} INFO - Filling up the DagBag from /opt/airflow/dags/04_ELT_example2.py
[2023-11-03T19:55:52.518+0000] {logging_mixin.py:151} INFO - [2023-11-03T19:55:52.513+0000] {dagbag.py:346} ERROR - Failed to import: /opt/airflow/dags/04_ELT_example2.py
Traceback (most recent call last):
  File "/home/airflow/.local/lib/python3.8/site-packages/airflow/models/dagbag.py", line 342, in parse
    loader.exec_module(new_module)
  File "<frozen importlib._bootstrap_external>", line 843, in exec_module
  File "<frozen importlib._bootstrap>", line 219, in _call_with_frames_removed
  File "/opt/airflow/dags/04_ELT_example2.py", line 19, in <module>
    conn_id = Variable.get("conn_name")
  File "/home/airflow/.local/lib/python3.8/site-packages/airflow/models/variable.py", line 140, in get
    raise KeyError(f"Variable {key} does not exist")
KeyError: 'Variable conn_name does not exist'
[2023-11-03T19:55:52.521+0000] {processor.py:841} WARNING - No viable dags retrieved from /opt/airflow/dags/04_ELT_example2.py
[2023-11-03T19:55:52.554+0000] {processor.py:179} INFO - Processing /opt/airflow/dags/04_ELT_example2.py took 0.124 seconds
[2023-11-03T19:56:22.784+0000] {processor.py:157} INFO - Started process (PID=35142) to work on /opt/airflow/dags/04_ELT_example2.py
[2023-11-03T19:56:22.787+0000] {processor.py:829} INFO - Processing file /opt/airflow/dags/04_ELT_example2.py for tasks to queue
[2023-11-03T19:56:22.796+0000] {logging_mixin.py:151} INFO - [2023-11-03T19:56:22.795+0000] {dagbag.py:536} INFO - Filling up the DagBag from /opt/airflow/dags/04_ELT_example2.py
[2023-11-03T19:56:22.866+0000] {logging_mixin.py:151} INFO - [2023-11-03T19:56:22.860+0000] {dagbag.py:346} ERROR - Failed to import: /opt/airflow/dags/04_ELT_example2.py
Traceback (most recent call last):
  File "/home/airflow/.local/lib/python3.8/site-packages/airflow/models/dagbag.py", line 342, in parse
    loader.exec_module(new_module)
  File "<frozen importlib._bootstrap_external>", line 843, in exec_module
  File "<frozen importlib._bootstrap>", line 219, in _call_with_frames_removed
  File "/opt/airflow/dags/04_ELT_example2.py", line 19, in <module>
    conn_id = Variable.get("conn_name")
  File "/home/airflow/.local/lib/python3.8/site-packages/airflow/models/variable.py", line 140, in get
    raise KeyError(f"Variable {key} does not exist")
KeyError: 'Variable conn_name does not exist'
[2023-11-03T19:56:22.868+0000] {processor.py:841} WARNING - No viable dags retrieved from /opt/airflow/dags/04_ELT_example2.py
[2023-11-03T19:56:22.896+0000] {processor.py:179} INFO - Processing /opt/airflow/dags/04_ELT_example2.py took 0.123 seconds
[2023-11-03T19:56:53.436+0000] {processor.py:157} INFO - Started process (PID=35204) to work on /opt/airflow/dags/04_ELT_example2.py
[2023-11-03T19:56:53.439+0000] {processor.py:829} INFO - Processing file /opt/airflow/dags/04_ELT_example2.py for tasks to queue
[2023-11-03T19:56:53.445+0000] {logging_mixin.py:151} INFO - [2023-11-03T19:56:53.444+0000] {dagbag.py:536} INFO - Filling up the DagBag from /opt/airflow/dags/04_ELT_example2.py
[2023-11-03T19:56:53.500+0000] {logging_mixin.py:151} INFO - [2023-11-03T19:56:53.496+0000] {dagbag.py:346} ERROR - Failed to import: /opt/airflow/dags/04_ELT_example2.py
Traceback (most recent call last):
  File "/home/airflow/.local/lib/python3.8/site-packages/airflow/models/dagbag.py", line 342, in parse
    loader.exec_module(new_module)
  File "<frozen importlib._bootstrap_external>", line 843, in exec_module
  File "<frozen importlib._bootstrap>", line 219, in _call_with_frames_removed
  File "/opt/airflow/dags/04_ELT_example2.py", line 19, in <module>
    conn_id = Variable.get("conn_name")
  File "/home/airflow/.local/lib/python3.8/site-packages/airflow/models/variable.py", line 140, in get
    raise KeyError(f"Variable {key} does not exist")
KeyError: 'Variable conn_name does not exist'
[2023-11-03T19:56:53.503+0000] {processor.py:841} WARNING - No viable dags retrieved from /opt/airflow/dags/04_ELT_example2.py
[2023-11-03T19:56:53.529+0000] {processor.py:179} INFO - Processing /opt/airflow/dags/04_ELT_example2.py took 0.104 seconds
[2023-11-03T19:57:23.863+0000] {processor.py:157} INFO - Started process (PID=35266) to work on /opt/airflow/dags/04_ELT_example2.py
[2023-11-03T19:57:23.866+0000] {processor.py:829} INFO - Processing file /opt/airflow/dags/04_ELT_example2.py for tasks to queue
[2023-11-03T19:57:23.876+0000] {logging_mixin.py:151} INFO - [2023-11-03T19:57:23.874+0000] {dagbag.py:536} INFO - Filling up the DagBag from /opt/airflow/dags/04_ELT_example2.py
[2023-11-03T19:57:23.946+0000] {logging_mixin.py:151} INFO - [2023-11-03T19:57:23.940+0000] {dagbag.py:346} ERROR - Failed to import: /opt/airflow/dags/04_ELT_example2.py
Traceback (most recent call last):
  File "/home/airflow/.local/lib/python3.8/site-packages/airflow/models/dagbag.py", line 342, in parse
    loader.exec_module(new_module)
  File "<frozen importlib._bootstrap_external>", line 843, in exec_module
  File "<frozen importlib._bootstrap>", line 219, in _call_with_frames_removed
  File "/opt/airflow/dags/04_ELT_example2.py", line 19, in <module>
    conn_id = Variable.get("conn_name")
  File "/home/airflow/.local/lib/python3.8/site-packages/airflow/models/variable.py", line 140, in get
    raise KeyError(f"Variable {key} does not exist")
KeyError: 'Variable conn_name does not exist'
[2023-11-03T19:57:23.948+0000] {processor.py:841} WARNING - No viable dags retrieved from /opt/airflow/dags/04_ELT_example2.py
[2023-11-03T19:57:23.982+0000] {processor.py:179} INFO - Processing /opt/airflow/dags/04_ELT_example2.py took 0.129 seconds
[2023-11-03T19:57:54.266+0000] {processor.py:157} INFO - Started process (PID=35326) to work on /opt/airflow/dags/04_ELT_example2.py
[2023-11-03T19:57:54.271+0000] {processor.py:829} INFO - Processing file /opt/airflow/dags/04_ELT_example2.py for tasks to queue
[2023-11-03T19:57:54.281+0000] {logging_mixin.py:151} INFO - [2023-11-03T19:57:54.280+0000] {dagbag.py:536} INFO - Filling up the DagBag from /opt/airflow/dags/04_ELT_example2.py
[2023-11-03T19:57:54.343+0000] {logging_mixin.py:151} INFO - [2023-11-03T19:57:54.338+0000] {dagbag.py:346} ERROR - Failed to import: /opt/airflow/dags/04_ELT_example2.py
Traceback (most recent call last):
  File "/home/airflow/.local/lib/python3.8/site-packages/airflow/models/dagbag.py", line 342, in parse
    loader.exec_module(new_module)
  File "<frozen importlib._bootstrap_external>", line 843, in exec_module
  File "<frozen importlib._bootstrap>", line 219, in _call_with_frames_removed
  File "/opt/airflow/dags/04_ELT_example2.py", line 19, in <module>
    conn_id = Variable.get("conn_name")
  File "/home/airflow/.local/lib/python3.8/site-packages/airflow/models/variable.py", line 140, in get
    raise KeyError(f"Variable {key} does not exist")
KeyError: 'Variable conn_name does not exist'
[2023-11-03T19:57:54.346+0000] {processor.py:841} WARNING - No viable dags retrieved from /opt/airflow/dags/04_ELT_example2.py
[2023-11-03T19:57:54.379+0000] {processor.py:179} INFO - Processing /opt/airflow/dags/04_ELT_example2.py took 0.124 seconds
[2023-11-03T19:58:25.177+0000] {processor.py:157} INFO - Started process (PID=35388) to work on /opt/airflow/dags/04_ELT_example2.py
[2023-11-03T19:58:25.182+0000] {processor.py:829} INFO - Processing file /opt/airflow/dags/04_ELT_example2.py for tasks to queue
[2023-11-03T19:58:25.197+0000] {logging_mixin.py:151} INFO - [2023-11-03T19:58:25.195+0000] {dagbag.py:536} INFO - Filling up the DagBag from /opt/airflow/dags/04_ELT_example2.py
[2023-11-03T19:58:25.277+0000] {logging_mixin.py:151} INFO - [2023-11-03T19:58:25.273+0000] {dagbag.py:346} ERROR - Failed to import: /opt/airflow/dags/04_ELT_example2.py
Traceback (most recent call last):
  File "/home/airflow/.local/lib/python3.8/site-packages/airflow/models/dagbag.py", line 342, in parse
    loader.exec_module(new_module)
  File "<frozen importlib._bootstrap_external>", line 843, in exec_module
  File "<frozen importlib._bootstrap>", line 219, in _call_with_frames_removed
  File "/opt/airflow/dags/04_ELT_example2.py", line 19, in <module>
    conn_id = Variable.get("conn_name")
  File "/home/airflow/.local/lib/python3.8/site-packages/airflow/models/variable.py", line 140, in get
    raise KeyError(f"Variable {key} does not exist")
KeyError: 'Variable conn_name does not exist'
[2023-11-03T19:58:25.279+0000] {processor.py:841} WARNING - No viable dags retrieved from /opt/airflow/dags/04_ELT_example2.py
[2023-11-03T19:58:25.323+0000] {processor.py:179} INFO - Processing /opt/airflow/dags/04_ELT_example2.py took 0.159 seconds
[2023-11-03T19:58:55.793+0000] {processor.py:157} INFO - Started process (PID=35451) to work on /opt/airflow/dags/04_ELT_example2.py
[2023-11-03T19:58:55.797+0000] {processor.py:829} INFO - Processing file /opt/airflow/dags/04_ELT_example2.py for tasks to queue
[2023-11-03T19:58:55.808+0000] {logging_mixin.py:151} INFO - [2023-11-03T19:58:55.806+0000] {dagbag.py:536} INFO - Filling up the DagBag from /opt/airflow/dags/04_ELT_example2.py
[2023-11-03T19:58:55.876+0000] {logging_mixin.py:151} INFO - [2023-11-03T19:58:55.872+0000] {dagbag.py:346} ERROR - Failed to import: /opt/airflow/dags/04_ELT_example2.py
Traceback (most recent call last):
  File "/home/airflow/.local/lib/python3.8/site-packages/airflow/models/dagbag.py", line 342, in parse
    loader.exec_module(new_module)
  File "<frozen importlib._bootstrap_external>", line 843, in exec_module
  File "<frozen importlib._bootstrap>", line 219, in _call_with_frames_removed
  File "/opt/airflow/dags/04_ELT_example2.py", line 19, in <module>
    conn_id = Variable.get("conn_name")
  File "/home/airflow/.local/lib/python3.8/site-packages/airflow/models/variable.py", line 140, in get
    raise KeyError(f"Variable {key} does not exist")
KeyError: 'Variable conn_name does not exist'
[2023-11-03T19:58:55.878+0000] {processor.py:841} WARNING - No viable dags retrieved from /opt/airflow/dags/04_ELT_example2.py
[2023-11-03T19:58:55.908+0000] {processor.py:179} INFO - Processing /opt/airflow/dags/04_ELT_example2.py took 0.127 seconds
[2023-11-03T19:59:26.431+0000] {processor.py:157} INFO - Started process (PID=35513) to work on /opt/airflow/dags/04_ELT_example2.py
[2023-11-03T19:59:26.436+0000] {processor.py:829} INFO - Processing file /opt/airflow/dags/04_ELT_example2.py for tasks to queue
[2023-11-03T19:59:26.443+0000] {logging_mixin.py:151} INFO - [2023-11-03T19:59:26.441+0000] {dagbag.py:536} INFO - Filling up the DagBag from /opt/airflow/dags/04_ELT_example2.py
[2023-11-03T19:59:26.497+0000] {logging_mixin.py:151} INFO - [2023-11-03T19:59:26.494+0000] {dagbag.py:346} ERROR - Failed to import: /opt/airflow/dags/04_ELT_example2.py
Traceback (most recent call last):
  File "/home/airflow/.local/lib/python3.8/site-packages/airflow/models/dagbag.py", line 342, in parse
    loader.exec_module(new_module)
  File "<frozen importlib._bootstrap_external>", line 843, in exec_module
  File "<frozen importlib._bootstrap>", line 219, in _call_with_frames_removed
  File "/opt/airflow/dags/04_ELT_example2.py", line 19, in <module>
    conn_id = Variable.get("conn_name")
  File "/home/airflow/.local/lib/python3.8/site-packages/airflow/models/variable.py", line 140, in get
    raise KeyError(f"Variable {key} does not exist")
KeyError: 'Variable conn_name does not exist'
[2023-11-03T19:59:26.499+0000] {processor.py:841} WARNING - No viable dags retrieved from /opt/airflow/dags/04_ELT_example2.py
[2023-11-03T19:59:26.531+0000] {processor.py:179} INFO - Processing /opt/airflow/dags/04_ELT_example2.py took 0.113 seconds
[2023-11-03T19:59:57.060+0000] {processor.py:157} INFO - Started process (PID=35575) to work on /opt/airflow/dags/04_ELT_example2.py
[2023-11-03T19:59:57.063+0000] {processor.py:829} INFO - Processing file /opt/airflow/dags/04_ELT_example2.py for tasks to queue
[2023-11-03T19:59:57.070+0000] {logging_mixin.py:151} INFO - [2023-11-03T19:59:57.069+0000] {dagbag.py:536} INFO - Filling up the DagBag from /opt/airflow/dags/04_ELT_example2.py
[2023-11-03T19:59:57.136+0000] {logging_mixin.py:151} INFO - [2023-11-03T19:59:57.132+0000] {dagbag.py:346} ERROR - Failed to import: /opt/airflow/dags/04_ELT_example2.py
Traceback (most recent call last):
  File "/home/airflow/.local/lib/python3.8/site-packages/airflow/models/dagbag.py", line 342, in parse
    loader.exec_module(new_module)
  File "<frozen importlib._bootstrap_external>", line 843, in exec_module
  File "<frozen importlib._bootstrap>", line 219, in _call_with_frames_removed
  File "/opt/airflow/dags/04_ELT_example2.py", line 19, in <module>
    conn_id = Variable.get("conn_name")
  File "/home/airflow/.local/lib/python3.8/site-packages/airflow/models/variable.py", line 140, in get
    raise KeyError(f"Variable {key} does not exist")
KeyError: 'Variable conn_name does not exist'
[2023-11-03T19:59:57.138+0000] {processor.py:841} WARNING - No viable dags retrieved from /opt/airflow/dags/04_ELT_example2.py
[2023-11-03T19:59:57.171+0000] {processor.py:179} INFO - Processing /opt/airflow/dags/04_ELT_example2.py took 0.121 seconds
[2023-11-03T20:00:27.455+0000] {processor.py:157} INFO - Started process (PID=35637) to work on /opt/airflow/dags/04_ELT_example2.py
[2023-11-03T20:00:27.458+0000] {processor.py:829} INFO - Processing file /opt/airflow/dags/04_ELT_example2.py for tasks to queue
[2023-11-03T20:00:27.466+0000] {logging_mixin.py:151} INFO - [2023-11-03T20:00:27.464+0000] {dagbag.py:536} INFO - Filling up the DagBag from /opt/airflow/dags/04_ELT_example2.py
[2023-11-03T20:00:27.524+0000] {logging_mixin.py:151} INFO - [2023-11-03T20:00:27.520+0000] {dagbag.py:346} ERROR - Failed to import: /opt/airflow/dags/04_ELT_example2.py
Traceback (most recent call last):
  File "/home/airflow/.local/lib/python3.8/site-packages/airflow/models/dagbag.py", line 342, in parse
    loader.exec_module(new_module)
  File "<frozen importlib._bootstrap_external>", line 843, in exec_module
  File "<frozen importlib._bootstrap>", line 219, in _call_with_frames_removed
  File "/opt/airflow/dags/04_ELT_example2.py", line 19, in <module>
    conn_id = Variable.get("conn_name")
  File "/home/airflow/.local/lib/python3.8/site-packages/airflow/models/variable.py", line 140, in get
    raise KeyError(f"Variable {key} does not exist")
KeyError: 'Variable conn_name does not exist'
[2023-11-03T20:00:27.526+0000] {processor.py:841} WARNING - No viable dags retrieved from /opt/airflow/dags/04_ELT_example2.py
[2023-11-03T20:00:27.557+0000] {processor.py:179} INFO - Processing /opt/airflow/dags/04_ELT_example2.py took 0.110 seconds
[2023-11-03T20:00:57.819+0000] {processor.py:157} INFO - Started process (PID=35699) to work on /opt/airflow/dags/04_ELT_example2.py
[2023-11-03T20:00:57.830+0000] {processor.py:829} INFO - Processing file /opt/airflow/dags/04_ELT_example2.py for tasks to queue
[2023-11-03T20:00:57.854+0000] {logging_mixin.py:151} INFO - [2023-11-03T20:00:57.853+0000] {dagbag.py:536} INFO - Filling up the DagBag from /opt/airflow/dags/04_ELT_example2.py
[2023-11-03T20:00:57.989+0000] {logging_mixin.py:151} INFO - [2023-11-03T20:00:57.979+0000] {dagbag.py:346} ERROR - Failed to import: /opt/airflow/dags/04_ELT_example2.py
Traceback (most recent call last):
  File "/home/airflow/.local/lib/python3.8/site-packages/airflow/models/dagbag.py", line 342, in parse
    loader.exec_module(new_module)
  File "<frozen importlib._bootstrap_external>", line 843, in exec_module
  File "<frozen importlib._bootstrap>", line 219, in _call_with_frames_removed
  File "/opt/airflow/dags/04_ELT_example2.py", line 19, in <module>
    conn_id = Variable.get("conn_name")
  File "/home/airflow/.local/lib/python3.8/site-packages/airflow/models/variable.py", line 140, in get
    raise KeyError(f"Variable {key} does not exist")
KeyError: 'Variable conn_name does not exist'
[2023-11-03T20:00:57.997+0000] {processor.py:841} WARNING - No viable dags retrieved from /opt/airflow/dags/04_ELT_example2.py
[2023-11-03T20:00:58.029+0000] {processor.py:179} INFO - Processing /opt/airflow/dags/04_ELT_example2.py took 0.249 seconds
[2023-11-03T20:01:28.834+0000] {processor.py:157} INFO - Started process (PID=35761) to work on /opt/airflow/dags/04_ELT_example2.py
[2023-11-03T20:01:28.837+0000] {processor.py:829} INFO - Processing file /opt/airflow/dags/04_ELT_example2.py for tasks to queue
[2023-11-03T20:01:28.847+0000] {logging_mixin.py:151} INFO - [2023-11-03T20:01:28.846+0000] {dagbag.py:536} INFO - Filling up the DagBag from /opt/airflow/dags/04_ELT_example2.py
[2023-11-03T20:01:28.901+0000] {logging_mixin.py:151} INFO - [2023-11-03T20:01:28.898+0000] {dagbag.py:346} ERROR - Failed to import: /opt/airflow/dags/04_ELT_example2.py
Traceback (most recent call last):
  File "/home/airflow/.local/lib/python3.8/site-packages/airflow/models/dagbag.py", line 342, in parse
    loader.exec_module(new_module)
  File "<frozen importlib._bootstrap_external>", line 843, in exec_module
  File "<frozen importlib._bootstrap>", line 219, in _call_with_frames_removed
  File "/opt/airflow/dags/04_ELT_example2.py", line 19, in <module>
    conn_id = Variable.get("conn_name")
  File "/home/airflow/.local/lib/python3.8/site-packages/airflow/models/variable.py", line 140, in get
    raise KeyError(f"Variable {key} does not exist")
KeyError: 'Variable conn_name does not exist'
[2023-11-03T20:01:28.903+0000] {processor.py:841} WARNING - No viable dags retrieved from /opt/airflow/dags/04_ELT_example2.py
[2023-11-03T20:01:28.931+0000] {processor.py:179} INFO - Processing /opt/airflow/dags/04_ELT_example2.py took 0.111 seconds
[2023-11-03T20:01:59.582+0000] {processor.py:157} INFO - Started process (PID=35823) to work on /opt/airflow/dags/04_ELT_example2.py
[2023-11-03T20:01:59.586+0000] {processor.py:829} INFO - Processing file /opt/airflow/dags/04_ELT_example2.py for tasks to queue
[2023-11-03T20:01:59.596+0000] {logging_mixin.py:151} INFO - [2023-11-03T20:01:59.595+0000] {dagbag.py:536} INFO - Filling up the DagBag from /opt/airflow/dags/04_ELT_example2.py
[2023-11-03T20:01:59.658+0000] {logging_mixin.py:151} INFO - [2023-11-03T20:01:59.653+0000] {dagbag.py:346} ERROR - Failed to import: /opt/airflow/dags/04_ELT_example2.py
Traceback (most recent call last):
  File "/home/airflow/.local/lib/python3.8/site-packages/airflow/models/dagbag.py", line 342, in parse
    loader.exec_module(new_module)
  File "<frozen importlib._bootstrap_external>", line 843, in exec_module
  File "<frozen importlib._bootstrap>", line 219, in _call_with_frames_removed
  File "/opt/airflow/dags/04_ELT_example2.py", line 19, in <module>
    conn_id = Variable.get("conn_name")
  File "/home/airflow/.local/lib/python3.8/site-packages/airflow/models/variable.py", line 140, in get
    raise KeyError(f"Variable {key} does not exist")
KeyError: 'Variable conn_name does not exist'
[2023-11-03T20:01:59.660+0000] {processor.py:841} WARNING - No viable dags retrieved from /opt/airflow/dags/04_ELT_example2.py
[2023-11-03T20:01:59.699+0000] {processor.py:179} INFO - Processing /opt/airflow/dags/04_ELT_example2.py took 0.129 seconds
[2023-11-03T20:02:30.545+0000] {processor.py:157} INFO - Started process (PID=35885) to work on /opt/airflow/dags/04_ELT_example2.py
[2023-11-03T20:02:30.548+0000] {processor.py:829} INFO - Processing file /opt/airflow/dags/04_ELT_example2.py for tasks to queue
[2023-11-03T20:02:30.555+0000] {logging_mixin.py:151} INFO - [2023-11-03T20:02:30.554+0000] {dagbag.py:536} INFO - Filling up the DagBag from /opt/airflow/dags/04_ELT_example2.py
[2023-11-03T20:02:30.618+0000] {logging_mixin.py:151} INFO - [2023-11-03T20:02:30.613+0000] {dagbag.py:346} ERROR - Failed to import: /opt/airflow/dags/04_ELT_example2.py
Traceback (most recent call last):
  File "/home/airflow/.local/lib/python3.8/site-packages/airflow/models/dagbag.py", line 342, in parse
    loader.exec_module(new_module)
  File "<frozen importlib._bootstrap_external>", line 843, in exec_module
  File "<frozen importlib._bootstrap>", line 219, in _call_with_frames_removed
  File "/opt/airflow/dags/04_ELT_example2.py", line 19, in <module>
    conn_id = Variable.get("conn_name")
  File "/home/airflow/.local/lib/python3.8/site-packages/airflow/models/variable.py", line 140, in get
    raise KeyError(f"Variable {key} does not exist")
KeyError: 'Variable conn_name does not exist'
[2023-11-03T20:02:30.620+0000] {processor.py:841} WARNING - No viable dags retrieved from /opt/airflow/dags/04_ELT_example2.py
[2023-11-03T20:02:30.656+0000] {processor.py:179} INFO - Processing /opt/airflow/dags/04_ELT_example2.py took 0.122 seconds
[2023-11-03T20:03:01.182+0000] {processor.py:157} INFO - Started process (PID=35947) to work on /opt/airflow/dags/04_ELT_example2.py
[2023-11-03T20:03:01.184+0000] {processor.py:829} INFO - Processing file /opt/airflow/dags/04_ELT_example2.py for tasks to queue
[2023-11-03T20:03:01.194+0000] {logging_mixin.py:151} INFO - [2023-11-03T20:03:01.191+0000] {dagbag.py:536} INFO - Filling up the DagBag from /opt/airflow/dags/04_ELT_example2.py
[2023-11-03T20:03:01.262+0000] {logging_mixin.py:151} INFO - [2023-11-03T20:03:01.258+0000] {dagbag.py:346} ERROR - Failed to import: /opt/airflow/dags/04_ELT_example2.py
Traceback (most recent call last):
  File "/home/airflow/.local/lib/python3.8/site-packages/airflow/models/dagbag.py", line 342, in parse
    loader.exec_module(new_module)
  File "<frozen importlib._bootstrap_external>", line 843, in exec_module
  File "<frozen importlib._bootstrap>", line 219, in _call_with_frames_removed
  File "/opt/airflow/dags/04_ELT_example2.py", line 19, in <module>
    conn_id = Variable.get("conn_name")
  File "/home/airflow/.local/lib/python3.8/site-packages/airflow/models/variable.py", line 140, in get
    raise KeyError(f"Variable {key} does not exist")
KeyError: 'Variable conn_name does not exist'
[2023-11-03T20:03:01.264+0000] {processor.py:841} WARNING - No viable dags retrieved from /opt/airflow/dags/04_ELT_example2.py
[2023-11-03T20:03:01.293+0000] {processor.py:179} INFO - Processing /opt/airflow/dags/04_ELT_example2.py took 0.119 seconds
[2023-11-03T20:03:32.111+0000] {processor.py:157} INFO - Started process (PID=36010) to work on /opt/airflow/dags/04_ELT_example2.py
[2023-11-03T20:03:32.114+0000] {processor.py:829} INFO - Processing file /opt/airflow/dags/04_ELT_example2.py for tasks to queue
[2023-11-03T20:03:32.123+0000] {logging_mixin.py:151} INFO - [2023-11-03T20:03:32.121+0000] {dagbag.py:536} INFO - Filling up the DagBag from /opt/airflow/dags/04_ELT_example2.py
[2023-11-03T20:03:32.180+0000] {logging_mixin.py:151} INFO - [2023-11-03T20:03:32.176+0000] {dagbag.py:346} ERROR - Failed to import: /opt/airflow/dags/04_ELT_example2.py
Traceback (most recent call last):
  File "/home/airflow/.local/lib/python3.8/site-packages/airflow/models/dagbag.py", line 342, in parse
    loader.exec_module(new_module)
  File "<frozen importlib._bootstrap_external>", line 843, in exec_module
  File "<frozen importlib._bootstrap>", line 219, in _call_with_frames_removed
  File "/opt/airflow/dags/04_ELT_example2.py", line 19, in <module>
    conn_id = Variable.get("conn_name")
  File "/home/airflow/.local/lib/python3.8/site-packages/airflow/models/variable.py", line 140, in get
    raise KeyError(f"Variable {key} does not exist")
KeyError: 'Variable conn_name does not exist'
[2023-11-03T20:03:32.183+0000] {processor.py:841} WARNING - No viable dags retrieved from /opt/airflow/dags/04_ELT_example2.py
[2023-11-03T20:03:32.215+0000] {processor.py:179} INFO - Processing /opt/airflow/dags/04_ELT_example2.py took 0.112 seconds
[2023-11-03T20:04:02.896+0000] {processor.py:157} INFO - Started process (PID=36073) to work on /opt/airflow/dags/04_ELT_example2.py
[2023-11-03T20:04:02.900+0000] {processor.py:829} INFO - Processing file /opt/airflow/dags/04_ELT_example2.py for tasks to queue
[2023-11-03T20:04:02.907+0000] {logging_mixin.py:151} INFO - [2023-11-03T20:04:02.906+0000] {dagbag.py:536} INFO - Filling up the DagBag from /opt/airflow/dags/04_ELT_example2.py
[2023-11-03T20:04:02.965+0000] {logging_mixin.py:151} INFO - [2023-11-03T20:04:02.961+0000] {dagbag.py:346} ERROR - Failed to import: /opt/airflow/dags/04_ELT_example2.py
Traceback (most recent call last):
  File "/home/airflow/.local/lib/python3.8/site-packages/airflow/models/dagbag.py", line 342, in parse
    loader.exec_module(new_module)
  File "<frozen importlib._bootstrap_external>", line 843, in exec_module
  File "<frozen importlib._bootstrap>", line 219, in _call_with_frames_removed
  File "/opt/airflow/dags/04_ELT_example2.py", line 19, in <module>
    conn_id = Variable.get("conn_name")
  File "/home/airflow/.local/lib/python3.8/site-packages/airflow/models/variable.py", line 140, in get
    raise KeyError(f"Variable {key} does not exist")
KeyError: 'Variable conn_name does not exist'
[2023-11-03T20:04:02.967+0000] {processor.py:841} WARNING - No viable dags retrieved from /opt/airflow/dags/04_ELT_example2.py
[2023-11-03T20:04:02.993+0000] {processor.py:179} INFO - Processing /opt/airflow/dags/04_ELT_example2.py took 0.108 seconds
[2023-11-03T20:04:33.075+0000] {processor.py:157} INFO - Started process (PID=36133) to work on /opt/airflow/dags/04_ELT_example2.py
[2023-11-03T20:04:33.078+0000] {processor.py:829} INFO - Processing file /opt/airflow/dags/04_ELT_example2.py for tasks to queue
[2023-11-03T20:04:33.086+0000] {logging_mixin.py:151} INFO - [2023-11-03T20:04:33.085+0000] {dagbag.py:536} INFO - Filling up the DagBag from /opt/airflow/dags/04_ELT_example2.py
[2023-11-03T20:04:33.143+0000] {logging_mixin.py:151} INFO - [2023-11-03T20:04:33.139+0000] {dagbag.py:346} ERROR - Failed to import: /opt/airflow/dags/04_ELT_example2.py
Traceback (most recent call last):
  File "/home/airflow/.local/lib/python3.8/site-packages/airflow/models/dagbag.py", line 342, in parse
    loader.exec_module(new_module)
  File "<frozen importlib._bootstrap_external>", line 843, in exec_module
  File "<frozen importlib._bootstrap>", line 219, in _call_with_frames_removed
  File "/opt/airflow/dags/04_ELT_example2.py", line 19, in <module>
    conn_id = Variable.get("conn_name")
  File "/home/airflow/.local/lib/python3.8/site-packages/airflow/models/variable.py", line 140, in get
    raise KeyError(f"Variable {key} does not exist")
KeyError: 'Variable conn_name does not exist'
[2023-11-03T20:04:33.146+0000] {processor.py:841} WARNING - No viable dags retrieved from /opt/airflow/dags/04_ELT_example2.py
[2023-11-03T20:04:33.176+0000] {processor.py:179} INFO - Processing /opt/airflow/dags/04_ELT_example2.py took 0.109 seconds
[2023-11-03T20:05:03.496+0000] {processor.py:157} INFO - Started process (PID=36195) to work on /opt/airflow/dags/04_ELT_example2.py
[2023-11-03T20:05:03.500+0000] {processor.py:829} INFO - Processing file /opt/airflow/dags/04_ELT_example2.py for tasks to queue
[2023-11-03T20:05:03.509+0000] {logging_mixin.py:151} INFO - [2023-11-03T20:05:03.507+0000] {dagbag.py:536} INFO - Filling up the DagBag from /opt/airflow/dags/04_ELT_example2.py
[2023-11-03T20:05:03.578+0000] {logging_mixin.py:151} INFO - [2023-11-03T20:05:03.573+0000] {dagbag.py:346} ERROR - Failed to import: /opt/airflow/dags/04_ELT_example2.py
Traceback (most recent call last):
  File "/home/airflow/.local/lib/python3.8/site-packages/airflow/models/dagbag.py", line 342, in parse
    loader.exec_module(new_module)
  File "<frozen importlib._bootstrap_external>", line 843, in exec_module
  File "<frozen importlib._bootstrap>", line 219, in _call_with_frames_removed
  File "/opt/airflow/dags/04_ELT_example2.py", line 19, in <module>
    conn_id = Variable.get("conn_name")
  File "/home/airflow/.local/lib/python3.8/site-packages/airflow/models/variable.py", line 140, in get
    raise KeyError(f"Variable {key} does not exist")
KeyError: 'Variable conn_name does not exist'
[2023-11-03T20:05:03.580+0000] {processor.py:841} WARNING - No viable dags retrieved from /opt/airflow/dags/04_ELT_example2.py
[2023-11-03T20:05:03.607+0000] {processor.py:179} INFO - Processing /opt/airflow/dags/04_ELT_example2.py took 0.120 seconds
[2023-11-03T20:05:33.694+0000] {processor.py:157} INFO - Started process (PID=36257) to work on /opt/airflow/dags/04_ELT_example2.py
[2023-11-03T20:05:33.698+0000] {processor.py:829} INFO - Processing file /opt/airflow/dags/04_ELT_example2.py for tasks to queue
[2023-11-03T20:05:33.708+0000] {logging_mixin.py:151} INFO - [2023-11-03T20:05:33.707+0000] {dagbag.py:536} INFO - Filling up the DagBag from /opt/airflow/dags/04_ELT_example2.py
[2023-11-03T20:05:33.827+0000] {logging_mixin.py:151} INFO - [2023-11-03T20:05:33.822+0000] {dagbag.py:346} ERROR - Failed to import: /opt/airflow/dags/04_ELT_example2.py
Traceback (most recent call last):
  File "/home/airflow/.local/lib/python3.8/site-packages/airflow/models/dagbag.py", line 342, in parse
    loader.exec_module(new_module)
  File "<frozen importlib._bootstrap_external>", line 843, in exec_module
  File "<frozen importlib._bootstrap>", line 219, in _call_with_frames_removed
  File "/opt/airflow/dags/04_ELT_example2.py", line 19, in <module>
    conn_id = Variable.get("conn_name")
  File "/home/airflow/.local/lib/python3.8/site-packages/airflow/models/variable.py", line 140, in get
    raise KeyError(f"Variable {key} does not exist")
KeyError: 'Variable conn_name does not exist'
[2023-11-03T20:05:33.831+0000] {processor.py:841} WARNING - No viable dags retrieved from /opt/airflow/dags/04_ELT_example2.py
[2023-11-03T20:05:33.914+0000] {processor.py:179} INFO - Processing /opt/airflow/dags/04_ELT_example2.py took 0.231 seconds
