[2023-10-28 17:29:52,229] {processor.py:153} INFO - Started process (PID=47) to work on /opt/airflow/dags/my_dag.py
[2023-10-28 17:29:52,230] {processor.py:641} INFO - Processing file /opt/airflow/dags/my_dag.py for tasks to queue
[2023-10-28 17:29:52,232] {logging_mixin.py:115} INFO - [2023-10-28 17:29:52,231] {dagbag.py:508} INFO - Filling up the DagBag from /opt/airflow/dags/my_dag.py
[2023-10-28 17:29:52,267] {logging_mixin.py:115} INFO - [2023-10-28 17:29:52,258] {dagbag.py:321} ERROR - Failed to import: /opt/airflow/dags/my_dag.py
Traceback (most recent call last):
  File "/home/airflow/.local/lib/python3.7/site-packages/airflow/models/dagbag.py", line 318, in parse
    loader.exec_module(new_module)
  File "<frozen importlib._bootstrap_external>", line 728, in exec_module
  File "<frozen importlib._bootstrap>", line 219, in _call_with_frames_removed
  File "/opt/airflow/dags/my_dag.py", line 6, in <module>
    'start_date': datetime(2023, 1, 1),
TypeError: 'module' object is not callable
[2023-10-28 17:29:52,268] {processor.py:653} WARNING - No viable dags retrieved from /opt/airflow/dags/my_dag.py
[2023-10-28 17:29:52,682] {processor.py:161} INFO - Processing /opt/airflow/dags/my_dag.py took 0.463 seconds
[2023-10-28 17:30:22,822] {processor.py:153} INFO - Started process (PID=110) to work on /opt/airflow/dags/my_dag.py
[2023-10-28 17:30:22,824] {processor.py:641} INFO - Processing file /opt/airflow/dags/my_dag.py for tasks to queue
[2023-10-28 17:30:22,825] {logging_mixin.py:115} INFO - [2023-10-28 17:30:22,825] {dagbag.py:508} INFO - Filling up the DagBag from /opt/airflow/dags/my_dag.py
[2023-10-28 17:30:22,833] {logging_mixin.py:115} INFO - [2023-10-28 17:30:22,832] {dagbag.py:321} ERROR - Failed to import: /opt/airflow/dags/my_dag.py
Traceback (most recent call last):
  File "/home/airflow/.local/lib/python3.7/site-packages/airflow/models/dagbag.py", line 318, in parse
    loader.exec_module(new_module)
  File "<frozen importlib._bootstrap_external>", line 728, in exec_module
  File "<frozen importlib._bootstrap>", line 219, in _call_with_frames_removed
  File "/opt/airflow/dags/my_dag.py", line 6, in <module>
    'start_date': datetime(2023, 1, 1),
TypeError: 'module' object is not callable
[2023-10-28 17:30:22,834] {processor.py:653} WARNING - No viable dags retrieved from /opt/airflow/dags/my_dag.py
[2023-10-28 17:30:22,866] {processor.py:161} INFO - Processing /opt/airflow/dags/my_dag.py took 0.049 seconds
[2023-10-28 17:30:53,297] {processor.py:153} INFO - Started process (PID=163) to work on /opt/airflow/dags/my_dag.py
[2023-10-28 17:30:53,306] {processor.py:641} INFO - Processing file /opt/airflow/dags/my_dag.py for tasks to queue
[2023-10-28 17:30:53,309] {logging_mixin.py:115} INFO - [2023-10-28 17:30:53,309] {dagbag.py:508} INFO - Filling up the DagBag from /opt/airflow/dags/my_dag.py
[2023-10-28 17:30:53,344] {logging_mixin.py:115} INFO - [2023-10-28 17:30:53,336] {dagbag.py:321} ERROR - Failed to import: /opt/airflow/dags/my_dag.py
Traceback (most recent call last):
  File "/home/airflow/.local/lib/python3.7/site-packages/airflow/models/dagbag.py", line 318, in parse
    loader.exec_module(new_module)
  File "<frozen importlib._bootstrap_external>", line 728, in exec_module
  File "<frozen importlib._bootstrap>", line 219, in _call_with_frames_removed
  File "/opt/airflow/dags/my_dag.py", line 6, in <module>
    'start_date': datetime(2023, 1, 1),
TypeError: 'module' object is not callable
[2023-10-28 17:30:53,348] {processor.py:653} WARNING - No viable dags retrieved from /opt/airflow/dags/my_dag.py
[2023-10-28 17:30:53,422] {processor.py:161} INFO - Processing /opt/airflow/dags/my_dag.py took 0.133 seconds
[2023-10-28 17:31:24,086] {processor.py:153} INFO - Started process (PID=225) to work on /opt/airflow/dags/my_dag.py
[2023-10-28 17:31:24,088] {processor.py:641} INFO - Processing file /opt/airflow/dags/my_dag.py for tasks to queue
[2023-10-28 17:31:24,091] {logging_mixin.py:115} INFO - [2023-10-28 17:31:24,091] {dagbag.py:508} INFO - Filling up the DagBag from /opt/airflow/dags/my_dag.py
[2023-10-28 17:31:24,106] {logging_mixin.py:115} INFO - [2023-10-28 17:31:24,103] {dagbag.py:321} ERROR - Failed to import: /opt/airflow/dags/my_dag.py
Traceback (most recent call last):
  File "/home/airflow/.local/lib/python3.7/site-packages/airflow/models/dagbag.py", line 318, in parse
    loader.exec_module(new_module)
  File "<frozen importlib._bootstrap_external>", line 728, in exec_module
  File "<frozen importlib._bootstrap>", line 219, in _call_with_frames_removed
  File "/opt/airflow/dags/my_dag.py", line 6, in <module>
    'start_date': datetime(2023, 1, 1),
TypeError: 'module' object is not callable
[2023-10-28 17:31:24,108] {processor.py:653} WARNING - No viable dags retrieved from /opt/airflow/dags/my_dag.py
[2023-10-28 17:31:24,146] {processor.py:161} INFO - Processing /opt/airflow/dags/my_dag.py took 0.069 seconds
[2023-10-28 17:31:54,354] {processor.py:153} INFO - Started process (PID=278) to work on /opt/airflow/dags/my_dag.py
[2023-10-28 17:31:54,355] {processor.py:641} INFO - Processing file /opt/airflow/dags/my_dag.py for tasks to queue
[2023-10-28 17:31:54,357] {logging_mixin.py:115} INFO - [2023-10-28 17:31:54,356] {dagbag.py:508} INFO - Filling up the DagBag from /opt/airflow/dags/my_dag.py
[2023-10-28 17:31:54,369] {logging_mixin.py:115} INFO - [2023-10-28 17:31:54,368] {dagbag.py:321} ERROR - Failed to import: /opt/airflow/dags/my_dag.py
Traceback (most recent call last):
  File "/home/airflow/.local/lib/python3.7/site-packages/airflow/models/dagbag.py", line 318, in parse
    loader.exec_module(new_module)
  File "<frozen importlib._bootstrap_external>", line 728, in exec_module
  File "<frozen importlib._bootstrap>", line 219, in _call_with_frames_removed
  File "/opt/airflow/dags/my_dag.py", line 6, in <module>
    'start_date': datetime(2023, 1, 1),
TypeError: 'module' object is not callable
[2023-10-28 17:31:54,370] {processor.py:653} WARNING - No viable dags retrieved from /opt/airflow/dags/my_dag.py
[2023-10-28 17:31:54,426] {processor.py:161} INFO - Processing /opt/airflow/dags/my_dag.py took 0.076 seconds
[2023-10-28 17:32:24,776] {processor.py:153} INFO - Started process (PID=340) to work on /opt/airflow/dags/my_dag.py
[2023-10-28 17:32:24,777] {processor.py:641} INFO - Processing file /opt/airflow/dags/my_dag.py for tasks to queue
[2023-10-28 17:32:24,779] {logging_mixin.py:115} INFO - [2023-10-28 17:32:24,778] {dagbag.py:508} INFO - Filling up the DagBag from /opt/airflow/dags/my_dag.py
[2023-10-28 17:32:24,787] {logging_mixin.py:115} INFO - [2023-10-28 17:32:24,786] {dagbag.py:321} ERROR - Failed to import: /opt/airflow/dags/my_dag.py
Traceback (most recent call last):
  File "/home/airflow/.local/lib/python3.7/site-packages/airflow/models/dagbag.py", line 318, in parse
    loader.exec_module(new_module)
  File "<frozen importlib._bootstrap_external>", line 728, in exec_module
  File "<frozen importlib._bootstrap>", line 219, in _call_with_frames_removed
  File "/opt/airflow/dags/my_dag.py", line 6, in <module>
    'start_date': datetime(2023, 1, 1),
TypeError: 'module' object is not callable
[2023-10-28 17:32:24,788] {processor.py:653} WARNING - No viable dags retrieved from /opt/airflow/dags/my_dag.py
[2023-10-28 17:32:24,821] {processor.py:161} INFO - Processing /opt/airflow/dags/my_dag.py took 0.050 seconds
[2023-10-28 17:32:54,988] {processor.py:153} INFO - Started process (PID=393) to work on /opt/airflow/dags/my_dag.py
[2023-10-28 17:32:54,989] {processor.py:641} INFO - Processing file /opt/airflow/dags/my_dag.py for tasks to queue
[2023-10-28 17:32:54,991] {logging_mixin.py:115} INFO - [2023-10-28 17:32:54,990] {dagbag.py:508} INFO - Filling up the DagBag from /opt/airflow/dags/my_dag.py
[2023-10-28 17:32:55,004] {logging_mixin.py:115} INFO - [2023-10-28 17:32:55,000] {dagbag.py:321} ERROR - Failed to import: /opt/airflow/dags/my_dag.py
Traceback (most recent call last):
  File "/home/airflow/.local/lib/python3.7/site-packages/airflow/models/dagbag.py", line 318, in parse
    loader.exec_module(new_module)
  File "<frozen importlib._bootstrap_external>", line 728, in exec_module
  File "<frozen importlib._bootstrap>", line 219, in _call_with_frames_removed
  File "/opt/airflow/dags/my_dag.py", line 6, in <module>
    'start_date': datetime(2023, 1, 1),
TypeError: 'module' object is not callable
[2023-10-28 17:32:55,006] {processor.py:653} WARNING - No viable dags retrieved from /opt/airflow/dags/my_dag.py
[2023-10-28 17:32:55,062] {processor.py:161} INFO - Processing /opt/airflow/dags/my_dag.py took 0.079 seconds
[2023-10-28 17:33:25,397] {processor.py:153} INFO - Started process (PID=455) to work on /opt/airflow/dags/my_dag.py
[2023-10-28 17:33:25,400] {processor.py:641} INFO - Processing file /opt/airflow/dags/my_dag.py for tasks to queue
[2023-10-28 17:33:25,402] {logging_mixin.py:115} INFO - [2023-10-28 17:33:25,402] {dagbag.py:508} INFO - Filling up the DagBag from /opt/airflow/dags/my_dag.py
[2023-10-28 17:33:25,412] {logging_mixin.py:115} INFO - [2023-10-28 17:33:25,410] {dagbag.py:321} ERROR - Failed to import: /opt/airflow/dags/my_dag.py
Traceback (most recent call last):
  File "/home/airflow/.local/lib/python3.7/site-packages/airflow/models/dagbag.py", line 318, in parse
    loader.exec_module(new_module)
  File "<frozen importlib._bootstrap_external>", line 728, in exec_module
  File "<frozen importlib._bootstrap>", line 219, in _call_with_frames_removed
  File "/opt/airflow/dags/my_dag.py", line 6, in <module>
    'start_date': datetime(2023, 1, 1),
TypeError: 'module' object is not callable
[2023-10-28 17:33:25,413] {processor.py:653} WARNING - No viable dags retrieved from /opt/airflow/dags/my_dag.py
[2023-10-28 17:33:25,444] {processor.py:161} INFO - Processing /opt/airflow/dags/my_dag.py took 0.054 seconds
[2023-10-28 17:33:56,177] {processor.py:153} INFO - Started process (PID=508) to work on /opt/airflow/dags/my_dag.py
[2023-10-28 17:33:56,178] {processor.py:641} INFO - Processing file /opt/airflow/dags/my_dag.py for tasks to queue
[2023-10-28 17:33:56,180] {logging_mixin.py:115} INFO - [2023-10-28 17:33:56,179] {dagbag.py:508} INFO - Filling up the DagBag from /opt/airflow/dags/my_dag.py
[2023-10-28 17:33:56,192] {logging_mixin.py:115} INFO - [2023-10-28 17:33:56,191] {dagbag.py:321} ERROR - Failed to import: /opt/airflow/dags/my_dag.py
Traceback (most recent call last):
  File "/home/airflow/.local/lib/python3.7/site-packages/airflow/models/dagbag.py", line 318, in parse
    loader.exec_module(new_module)
  File "<frozen importlib._bootstrap_external>", line 728, in exec_module
  File "<frozen importlib._bootstrap>", line 219, in _call_with_frames_removed
  File "/opt/airflow/dags/my_dag.py", line 6, in <module>
    'start_date': datetime(2023, 1, 1),
TypeError: 'module' object is not callable
[2023-10-28 17:33:56,193] {processor.py:653} WARNING - No viable dags retrieved from /opt/airflow/dags/my_dag.py
[2023-10-28 17:33:56,234] {processor.py:161} INFO - Processing /opt/airflow/dags/my_dag.py took 0.061 seconds
[2023-10-28 17:34:26,439] {processor.py:153} INFO - Started process (PID=570) to work on /opt/airflow/dags/my_dag.py
[2023-10-28 17:34:26,440] {processor.py:641} INFO - Processing file /opt/airflow/dags/my_dag.py for tasks to queue
[2023-10-28 17:34:26,442] {logging_mixin.py:115} INFO - [2023-10-28 17:34:26,442] {dagbag.py:508} INFO - Filling up the DagBag from /opt/airflow/dags/my_dag.py
[2023-10-28 17:34:26,453] {logging_mixin.py:115} INFO - [2023-10-28 17:34:26,452] {dagbag.py:321} ERROR - Failed to import: /opt/airflow/dags/my_dag.py
Traceback (most recent call last):
  File "/home/airflow/.local/lib/python3.7/site-packages/airflow/models/dagbag.py", line 318, in parse
    loader.exec_module(new_module)
  File "<frozen importlib._bootstrap_external>", line 728, in exec_module
  File "<frozen importlib._bootstrap>", line 219, in _call_with_frames_removed
  File "/opt/airflow/dags/my_dag.py", line 6, in <module>
    'start_date': datetime(2023, 1, 1),
TypeError: 'module' object is not callable
[2023-10-28 17:34:26,454] {processor.py:653} WARNING - No viable dags retrieved from /opt/airflow/dags/my_dag.py
[2023-10-28 17:34:26,495] {processor.py:161} INFO - Processing /opt/airflow/dags/my_dag.py took 0.061 seconds
[2023-10-28 17:34:56,956] {processor.py:153} INFO - Started process (PID=623) to work on /opt/airflow/dags/my_dag.py
[2023-10-28 17:34:56,958] {processor.py:641} INFO - Processing file /opt/airflow/dags/my_dag.py for tasks to queue
[2023-10-28 17:34:56,960] {logging_mixin.py:115} INFO - [2023-10-28 17:34:56,959] {dagbag.py:508} INFO - Filling up the DagBag from /opt/airflow/dags/my_dag.py
[2023-10-28 17:34:56,968] {logging_mixin.py:115} INFO - [2023-10-28 17:34:56,967] {dagbag.py:321} ERROR - Failed to import: /opt/airflow/dags/my_dag.py
Traceback (most recent call last):
  File "/home/airflow/.local/lib/python3.7/site-packages/airflow/models/dagbag.py", line 318, in parse
    loader.exec_module(new_module)
  File "<frozen importlib._bootstrap_external>", line 728, in exec_module
  File "<frozen importlib._bootstrap>", line 219, in _call_with_frames_removed
  File "/opt/airflow/dags/my_dag.py", line 6, in <module>
    'start_date': datetime(2023, 1, 1),
TypeError: 'module' object is not callable
[2023-10-28 17:34:56,969] {processor.py:653} WARNING - No viable dags retrieved from /opt/airflow/dags/my_dag.py
[2023-10-28 17:34:57,019] {processor.py:161} INFO - Processing /opt/airflow/dags/my_dag.py took 0.068 seconds
[2023-10-28 17:35:27,951] {processor.py:153} INFO - Started process (PID=685) to work on /opt/airflow/dags/my_dag.py
[2023-10-28 17:35:27,952] {processor.py:641} INFO - Processing file /opt/airflow/dags/my_dag.py for tasks to queue
[2023-10-28 17:35:27,954] {logging_mixin.py:115} INFO - [2023-10-28 17:35:27,954] {dagbag.py:508} INFO - Filling up the DagBag from /opt/airflow/dags/my_dag.py
[2023-10-28 17:35:27,972] {logging_mixin.py:115} INFO - [2023-10-28 17:35:27,969] {dagbag.py:321} ERROR - Failed to import: /opt/airflow/dags/my_dag.py
Traceback (most recent call last):
  File "/home/airflow/.local/lib/python3.7/site-packages/airflow/models/dagbag.py", line 318, in parse
    loader.exec_module(new_module)
  File "<frozen importlib._bootstrap_external>", line 728, in exec_module
  File "<frozen importlib._bootstrap>", line 219, in _call_with_frames_removed
  File "/opt/airflow/dags/my_dag.py", line 6, in <module>
    'start_date': datetime(2023, 1, 1),
TypeError: 'module' object is not callable
[2023-10-28 17:35:27,973] {processor.py:653} WARNING - No viable dags retrieved from /opt/airflow/dags/my_dag.py
[2023-10-28 17:35:28,011] {processor.py:161} INFO - Processing /opt/airflow/dags/my_dag.py took 0.072 seconds
[2023-10-28 17:35:58,321] {processor.py:153} INFO - Started process (PID=747) to work on /opt/airflow/dags/my_dag.py
[2023-10-28 17:35:58,323] {processor.py:641} INFO - Processing file /opt/airflow/dags/my_dag.py for tasks to queue
[2023-10-28 17:35:58,324] {logging_mixin.py:115} INFO - [2023-10-28 17:35:58,324] {dagbag.py:508} INFO - Filling up the DagBag from /opt/airflow/dags/my_dag.py
[2023-10-28 17:35:58,334] {logging_mixin.py:115} INFO - [2023-10-28 17:35:58,333] {dagbag.py:321} ERROR - Failed to import: /opt/airflow/dags/my_dag.py
Traceback (most recent call last):
  File "/home/airflow/.local/lib/python3.7/site-packages/airflow/models/dagbag.py", line 318, in parse
    loader.exec_module(new_module)
  File "<frozen importlib._bootstrap_external>", line 728, in exec_module
  File "<frozen importlib._bootstrap>", line 219, in _call_with_frames_removed
  File "/opt/airflow/dags/my_dag.py", line 6, in <module>
    'start_date': datetime(2023, 1, 1),
TypeError: 'module' object is not callable
[2023-10-28 17:35:58,335] {processor.py:653} WARNING - No viable dags retrieved from /opt/airflow/dags/my_dag.py
[2023-10-28 17:35:58,377] {processor.py:161} INFO - Processing /opt/airflow/dags/my_dag.py took 0.064 seconds
[2023-10-28 17:36:28,773] {processor.py:153} INFO - Started process (PID=800) to work on /opt/airflow/dags/my_dag.py
[2023-10-28 17:36:28,776] {processor.py:641} INFO - Processing file /opt/airflow/dags/my_dag.py for tasks to queue
[2023-10-28 17:36:28,778] {logging_mixin.py:115} INFO - [2023-10-28 17:36:28,778] {dagbag.py:508} INFO - Filling up the DagBag from /opt/airflow/dags/my_dag.py
[2023-10-28 17:36:28,795] {logging_mixin.py:115} INFO - [2023-10-28 17:36:28,791] {dagbag.py:321} ERROR - Failed to import: /opt/airflow/dags/my_dag.py
Traceback (most recent call last):
  File "/home/airflow/.local/lib/python3.7/site-packages/airflow/models/dagbag.py", line 318, in parse
    loader.exec_module(new_module)
  File "<frozen importlib._bootstrap_external>", line 728, in exec_module
  File "<frozen importlib._bootstrap>", line 219, in _call_with_frames_removed
  File "/opt/airflow/dags/my_dag.py", line 6, in <module>
    'start_date': datetime(2023, 1, 1),
TypeError: 'module' object is not callable
[2023-10-28 17:36:28,796] {processor.py:653} WARNING - No viable dags retrieved from /opt/airflow/dags/my_dag.py
[2023-10-28 17:36:28,840] {processor.py:161} INFO - Processing /opt/airflow/dags/my_dag.py took 0.071 seconds
