[2023-11-03T19:42:39.227+0000] {processor.py:157} INFO - Started process (PID=33480) to work on /opt/airflow/dags/04_ELT_example.py
[2023-11-03T19:42:39.232+0000] {processor.py:829} INFO - Processing file /opt/airflow/dags/04_ELT_example.py for tasks to queue
[2023-11-03T19:42:39.245+0000] {logging_mixin.py:151} INFO - [2023-11-03T19:42:39.244+0000] {dagbag.py:536} INFO - Filling up the DagBag from /opt/airflow/dags/04_ELT_example.py
[2023-11-03T19:42:39.367+0000] {logging_mixin.py:151} INFO - [2023-11-03T19:42:39.352+0000] {dagbag.py:346} ERROR - Failed to import: /opt/airflow/dags/04_ELT_example.py
Traceback (most recent call last):
  File "/home/airflow/.local/lib/python3.8/site-packages/airflow/models/dagbag.py", line 342, in parse
    loader.exec_module(new_module)
  File "<frozen importlib._bootstrap_external>", line 843, in exec_module
  File "<frozen importlib._bootstrap>", line 219, in _call_with_frames_removed
  File "/opt/airflow/dags/04_ELT_example.py", line 17, in <module>
    conn_id = Variable.get("conn_name")
  File "/home/airflow/.local/lib/python3.8/site-packages/airflow/models/variable.py", line 140, in get
    raise KeyError(f"Variable {key} does not exist")
KeyError: 'Variable conn_name does not exist'
[2023-11-03T19:42:39.372+0000] {processor.py:841} WARNING - No viable dags retrieved from /opt/airflow/dags/04_ELT_example.py
[2023-11-03T19:42:39.440+0000] {processor.py:179} INFO - Processing /opt/airflow/dags/04_ELT_example.py took 0.226 seconds
[2023-11-03T19:43:10.313+0000] {processor.py:157} INFO - Started process (PID=33542) to work on /opt/airflow/dags/04_ELT_example.py
[2023-11-03T19:43:10.316+0000] {processor.py:829} INFO - Processing file /opt/airflow/dags/04_ELT_example.py for tasks to queue
[2023-11-03T19:43:10.323+0000] {logging_mixin.py:151} INFO - [2023-11-03T19:43:10.322+0000] {dagbag.py:536} INFO - Filling up the DagBag from /opt/airflow/dags/04_ELT_example.py
[2023-11-03T19:43:10.379+0000] {logging_mixin.py:151} INFO - [2023-11-03T19:43:10.375+0000] {dagbag.py:346} ERROR - Failed to import: /opt/airflow/dags/04_ELT_example.py
Traceback (most recent call last):
  File "/home/airflow/.local/lib/python3.8/site-packages/airflow/models/dagbag.py", line 342, in parse
    loader.exec_module(new_module)
  File "<frozen importlib._bootstrap_external>", line 843, in exec_module
  File "<frozen importlib._bootstrap>", line 219, in _call_with_frames_removed
  File "/opt/airflow/dags/04_ELT_example.py", line 17, in <module>
    conn_id = Variable.get("conn_name")
  File "/home/airflow/.local/lib/python3.8/site-packages/airflow/models/variable.py", line 140, in get
    raise KeyError(f"Variable {key} does not exist")
KeyError: 'Variable conn_name does not exist'
[2023-11-03T19:43:10.381+0000] {processor.py:841} WARNING - No viable dags retrieved from /opt/airflow/dags/04_ELT_example.py
[2023-11-03T19:43:10.416+0000] {processor.py:179} INFO - Processing /opt/airflow/dags/04_ELT_example.py took 0.112 seconds
[2023-11-03T19:43:41.296+0000] {processor.py:157} INFO - Started process (PID=33604) to work on /opt/airflow/dags/04_ELT_example.py
[2023-11-03T19:43:41.298+0000] {processor.py:829} INFO - Processing file /opt/airflow/dags/04_ELT_example.py for tasks to queue
[2023-11-03T19:43:41.305+0000] {logging_mixin.py:151} INFO - [2023-11-03T19:43:41.304+0000] {dagbag.py:536} INFO - Filling up the DagBag from /opt/airflow/dags/04_ELT_example.py
[2023-11-03T19:43:41.356+0000] {logging_mixin.py:151} INFO - [2023-11-03T19:43:41.352+0000] {dagbag.py:346} ERROR - Failed to import: /opt/airflow/dags/04_ELT_example.py
Traceback (most recent call last):
  File "/home/airflow/.local/lib/python3.8/site-packages/airflow/models/dagbag.py", line 342, in parse
    loader.exec_module(new_module)
  File "<frozen importlib._bootstrap_external>", line 843, in exec_module
  File "<frozen importlib._bootstrap>", line 219, in _call_with_frames_removed
  File "/opt/airflow/dags/04_ELT_example.py", line 17, in <module>
    conn_id = Variable.get("conn_name")
  File "/home/airflow/.local/lib/python3.8/site-packages/airflow/models/variable.py", line 140, in get
    raise KeyError(f"Variable {key} does not exist")
KeyError: 'Variable conn_name does not exist'
[2023-11-03T19:43:41.358+0000] {processor.py:841} WARNING - No viable dags retrieved from /opt/airflow/dags/04_ELT_example.py
[2023-11-03T19:43:41.385+0000] {processor.py:179} INFO - Processing /opt/airflow/dags/04_ELT_example.py took 0.097 seconds
[2023-11-03T19:44:11.793+0000] {processor.py:157} INFO - Started process (PID=33666) to work on /opt/airflow/dags/04_ELT_example.py
[2023-11-03T19:44:11.801+0000] {processor.py:829} INFO - Processing file /opt/airflow/dags/04_ELT_example.py for tasks to queue
[2023-11-03T19:44:11.819+0000] {logging_mixin.py:151} INFO - [2023-11-03T19:44:11.818+0000] {dagbag.py:536} INFO - Filling up the DagBag from /opt/airflow/dags/04_ELT_example.py
[2023-11-03T19:44:11.946+0000] {logging_mixin.py:151} INFO - [2023-11-03T19:44:11.941+0000] {dagbag.py:346} ERROR - Failed to import: /opt/airflow/dags/04_ELT_example.py
Traceback (most recent call last):
  File "/home/airflow/.local/lib/python3.8/site-packages/airflow/models/dagbag.py", line 342, in parse
    loader.exec_module(new_module)
  File "<frozen importlib._bootstrap_external>", line 843, in exec_module
  File "<frozen importlib._bootstrap>", line 219, in _call_with_frames_removed
  File "/opt/airflow/dags/04_ELT_example.py", line 17, in <module>
    conn_id = Variable.get("conn_name")
  File "/home/airflow/.local/lib/python3.8/site-packages/airflow/models/variable.py", line 140, in get
    raise KeyError(f"Variable {key} does not exist")
KeyError: 'Variable conn_name does not exist'
[2023-11-03T19:44:11.953+0000] {processor.py:841} WARNING - No viable dags retrieved from /opt/airflow/dags/04_ELT_example.py
[2023-11-03T19:44:11.987+0000] {processor.py:179} INFO - Processing /opt/airflow/dags/04_ELT_example.py took 0.204 seconds
[2023-11-03T19:44:42.240+0000] {processor.py:157} INFO - Started process (PID=33728) to work on /opt/airflow/dags/04_ELT_example.py
[2023-11-03T19:44:42.243+0000] {processor.py:829} INFO - Processing file /opt/airflow/dags/04_ELT_example.py for tasks to queue
[2023-11-03T19:44:42.251+0000] {logging_mixin.py:151} INFO - [2023-11-03T19:44:42.249+0000] {dagbag.py:536} INFO - Filling up the DagBag from /opt/airflow/dags/04_ELT_example.py
[2023-11-03T19:44:42.305+0000] {logging_mixin.py:151} INFO - [2023-11-03T19:44:42.295+0000] {dagbag.py:346} ERROR - Failed to import: /opt/airflow/dags/04_ELT_example.py
Traceback (most recent call last):
  File "/home/airflow/.local/lib/python3.8/site-packages/airflow/models/dagbag.py", line 342, in parse
    loader.exec_module(new_module)
  File "<frozen importlib._bootstrap_external>", line 843, in exec_module
  File "<frozen importlib._bootstrap>", line 219, in _call_with_frames_removed
  File "/opt/airflow/dags/04_ELT_example.py", line 17, in <module>
    conn_id = Variable.get("conn_name")
  File "/home/airflow/.local/lib/python3.8/site-packages/airflow/models/variable.py", line 140, in get
    raise KeyError(f"Variable {key} does not exist")
KeyError: 'Variable conn_name does not exist'
[2023-11-03T19:44:42.310+0000] {processor.py:841} WARNING - No viable dags retrieved from /opt/airflow/dags/04_ELT_example.py
[2023-11-03T19:44:42.344+0000] {processor.py:179} INFO - Processing /opt/airflow/dags/04_ELT_example.py took 0.111 seconds
[2023-11-03T19:45:12.563+0000] {processor.py:157} INFO - Started process (PID=33791) to work on /opt/airflow/dags/04_ELT_example.py
[2023-11-03T19:45:12.566+0000] {processor.py:829} INFO - Processing file /opt/airflow/dags/04_ELT_example.py for tasks to queue
[2023-11-03T19:45:12.574+0000] {logging_mixin.py:151} INFO - [2023-11-03T19:45:12.573+0000] {dagbag.py:536} INFO - Filling up the DagBag from /opt/airflow/dags/04_ELT_example.py
[2023-11-03T19:45:12.632+0000] {logging_mixin.py:151} INFO - [2023-11-03T19:45:12.628+0000] {dagbag.py:346} ERROR - Failed to import: /opt/airflow/dags/04_ELT_example.py
Traceback (most recent call last):
  File "/home/airflow/.local/lib/python3.8/site-packages/airflow/models/dagbag.py", line 342, in parse
    loader.exec_module(new_module)
  File "<frozen importlib._bootstrap_external>", line 843, in exec_module
  File "<frozen importlib._bootstrap>", line 219, in _call_with_frames_removed
  File "/opt/airflow/dags/04_ELT_example.py", line 17, in <module>
    conn_id = Variable.get("conn_name")
  File "/home/airflow/.local/lib/python3.8/site-packages/airflow/models/variable.py", line 140, in get
    raise KeyError(f"Variable {key} does not exist")
KeyError: 'Variable conn_name does not exist'
[2023-11-03T19:45:12.634+0000] {processor.py:841} WARNING - No viable dags retrieved from /opt/airflow/dags/04_ELT_example.py
[2023-11-03T19:45:12.666+0000] {processor.py:179} INFO - Processing /opt/airflow/dags/04_ELT_example.py took 0.112 seconds
[2023-11-03T19:45:43.427+0000] {processor.py:157} INFO - Started process (PID=33853) to work on /opt/airflow/dags/04_ELT_example.py
[2023-11-03T19:45:43.430+0000] {processor.py:829} INFO - Processing file /opt/airflow/dags/04_ELT_example.py for tasks to queue
[2023-11-03T19:45:43.436+0000] {logging_mixin.py:151} INFO - [2023-11-03T19:45:43.435+0000] {dagbag.py:536} INFO - Filling up the DagBag from /opt/airflow/dags/04_ELT_example.py
[2023-11-03T19:45:43.499+0000] {logging_mixin.py:151} INFO - [2023-11-03T19:45:43.494+0000] {dagbag.py:346} ERROR - Failed to import: /opt/airflow/dags/04_ELT_example.py
Traceback (most recent call last):
  File "/home/airflow/.local/lib/python3.8/site-packages/airflow/models/dagbag.py", line 342, in parse
    loader.exec_module(new_module)
  File "<frozen importlib._bootstrap_external>", line 843, in exec_module
  File "<frozen importlib._bootstrap>", line 219, in _call_with_frames_removed
  File "/opt/airflow/dags/04_ELT_example.py", line 17, in <module>
    conn_id = Variable.get("conn_name")
  File "/home/airflow/.local/lib/python3.8/site-packages/airflow/models/variable.py", line 140, in get
    raise KeyError(f"Variable {key} does not exist")
KeyError: 'Variable conn_name does not exist'
[2023-11-03T19:45:43.501+0000] {processor.py:841} WARNING - No viable dags retrieved from /opt/airflow/dags/04_ELT_example.py
[2023-11-03T19:45:43.530+0000] {processor.py:179} INFO - Processing /opt/airflow/dags/04_ELT_example.py took 0.112 seconds
[2023-11-03T19:46:13.733+0000] {processor.py:157} INFO - Started process (PID=33915) to work on /opt/airflow/dags/04_ELT_example.py
[2023-11-03T19:46:13.742+0000] {processor.py:829} INFO - Processing file /opt/airflow/dags/04_ELT_example.py for tasks to queue
[2023-11-03T19:46:13.751+0000] {logging_mixin.py:151} INFO - [2023-11-03T19:46:13.750+0000] {dagbag.py:536} INFO - Filling up the DagBag from /opt/airflow/dags/04_ELT_example.py
[2023-11-03T19:46:13.878+0000] {logging_mixin.py:151} INFO - [2023-11-03T19:46:13.873+0000] {dagbag.py:346} ERROR - Failed to import: /opt/airflow/dags/04_ELT_example.py
Traceback (most recent call last):
  File "/home/airflow/.local/lib/python3.8/site-packages/airflow/models/dagbag.py", line 342, in parse
    loader.exec_module(new_module)
  File "<frozen importlib._bootstrap_external>", line 843, in exec_module
  File "<frozen importlib._bootstrap>", line 219, in _call_with_frames_removed
  File "/opt/airflow/dags/04_ELT_example.py", line 17, in <module>
    conn_id = Variable.get("conn_name")
  File "/home/airflow/.local/lib/python3.8/site-packages/airflow/models/variable.py", line 140, in get
    raise KeyError(f"Variable {key} does not exist")
KeyError: 'Variable conn_name does not exist'
[2023-11-03T19:46:13.881+0000] {processor.py:841} WARNING - No viable dags retrieved from /opt/airflow/dags/04_ELT_example.py
[2023-11-03T19:46:13.988+0000] {processor.py:179} INFO - Processing /opt/airflow/dags/04_ELT_example.py took 0.266 seconds
[2023-11-03T19:46:44.460+0000] {processor.py:157} INFO - Started process (PID=33977) to work on /opt/airflow/dags/04_ELT_example.py
[2023-11-03T19:46:44.463+0000] {processor.py:829} INFO - Processing file /opt/airflow/dags/04_ELT_example.py for tasks to queue
[2023-11-03T19:46:44.471+0000] {logging_mixin.py:151} INFO - [2023-11-03T19:46:44.469+0000] {dagbag.py:536} INFO - Filling up the DagBag from /opt/airflow/dags/04_ELT_example.py
[2023-11-03T19:46:44.538+0000] {logging_mixin.py:151} INFO - [2023-11-03T19:46:44.534+0000] {dagbag.py:346} ERROR - Failed to import: /opt/airflow/dags/04_ELT_example.py
Traceback (most recent call last):
  File "/home/airflow/.local/lib/python3.8/site-packages/airflow/models/dagbag.py", line 342, in parse
    loader.exec_module(new_module)
  File "<frozen importlib._bootstrap_external>", line 843, in exec_module
  File "<frozen importlib._bootstrap>", line 219, in _call_with_frames_removed
  File "/opt/airflow/dags/04_ELT_example.py", line 17, in <module>
    conn_id = Variable.get("conn_name")
  File "/home/airflow/.local/lib/python3.8/site-packages/airflow/models/variable.py", line 140, in get
    raise KeyError(f"Variable {key} does not exist")
KeyError: 'Variable conn_name does not exist'
[2023-11-03T19:46:44.539+0000] {processor.py:841} WARNING - No viable dags retrieved from /opt/airflow/dags/04_ELT_example.py
[2023-11-03T19:46:44.566+0000] {processor.py:179} INFO - Processing /opt/airflow/dags/04_ELT_example.py took 0.115 seconds
[2023-11-03T19:47:14.948+0000] {processor.py:157} INFO - Started process (PID=34039) to work on /opt/airflow/dags/04_ELT_example.py
[2023-11-03T19:47:14.952+0000] {processor.py:829} INFO - Processing file /opt/airflow/dags/04_ELT_example.py for tasks to queue
[2023-11-03T19:47:14.962+0000] {logging_mixin.py:151} INFO - [2023-11-03T19:47:14.960+0000] {dagbag.py:536} INFO - Filling up the DagBag from /opt/airflow/dags/04_ELT_example.py
[2023-11-03T19:47:15.025+0000] {logging_mixin.py:151} INFO - [2023-11-03T19:47:15.021+0000] {dagbag.py:346} ERROR - Failed to import: /opt/airflow/dags/04_ELT_example.py
Traceback (most recent call last):
  File "/home/airflow/.local/lib/python3.8/site-packages/airflow/models/dagbag.py", line 342, in parse
    loader.exec_module(new_module)
  File "<frozen importlib._bootstrap_external>", line 843, in exec_module
  File "<frozen importlib._bootstrap>", line 219, in _call_with_frames_removed
  File "/opt/airflow/dags/04_ELT_example.py", line 17, in <module>
    conn_id = Variable.get("conn_name")
  File "/home/airflow/.local/lib/python3.8/site-packages/airflow/models/variable.py", line 140, in get
    raise KeyError(f"Variable {key} does not exist")
KeyError: 'Variable conn_name does not exist'
[2023-11-03T19:47:15.027+0000] {processor.py:841} WARNING - No viable dags retrieved from /opt/airflow/dags/04_ELT_example.py
[2023-11-03T19:47:15.059+0000] {processor.py:179} INFO - Processing /opt/airflow/dags/04_ELT_example.py took 0.124 seconds
[2023-11-03T19:47:45.494+0000] {processor.py:157} INFO - Started process (PID=34101) to work on /opt/airflow/dags/04_ELT_example.py
[2023-11-03T19:47:45.499+0000] {processor.py:829} INFO - Processing file /opt/airflow/dags/04_ELT_example.py for tasks to queue
[2023-11-03T19:47:45.509+0000] {logging_mixin.py:151} INFO - [2023-11-03T19:47:45.507+0000] {dagbag.py:536} INFO - Filling up the DagBag from /opt/airflow/dags/04_ELT_example.py
[2023-11-03T19:47:45.564+0000] {logging_mixin.py:151} INFO - [2023-11-03T19:47:45.560+0000] {dagbag.py:346} ERROR - Failed to import: /opt/airflow/dags/04_ELT_example.py
Traceback (most recent call last):
  File "/home/airflow/.local/lib/python3.8/site-packages/airflow/models/dagbag.py", line 342, in parse
    loader.exec_module(new_module)
  File "<frozen importlib._bootstrap_external>", line 843, in exec_module
  File "<frozen importlib._bootstrap>", line 219, in _call_with_frames_removed
  File "/opt/airflow/dags/04_ELT_example.py", line 17, in <module>
    conn_id = Variable.get("conn_name")
  File "/home/airflow/.local/lib/python3.8/site-packages/airflow/models/variable.py", line 140, in get
    raise KeyError(f"Variable {key} does not exist")
KeyError: 'Variable conn_name does not exist'
[2023-11-03T19:47:45.567+0000] {processor.py:841} WARNING - No viable dags retrieved from /opt/airflow/dags/04_ELT_example.py
[2023-11-03T19:47:45.594+0000] {processor.py:179} INFO - Processing /opt/airflow/dags/04_ELT_example.py took 0.112 seconds
[2023-11-03T19:48:16.159+0000] {processor.py:157} INFO - Started process (PID=34163) to work on /opt/airflow/dags/04_ELT_example.py
[2023-11-03T19:48:16.162+0000] {processor.py:829} INFO - Processing file /opt/airflow/dags/04_ELT_example.py for tasks to queue
[2023-11-03T19:48:16.173+0000] {logging_mixin.py:151} INFO - [2023-11-03T19:48:16.171+0000] {dagbag.py:536} INFO - Filling up the DagBag from /opt/airflow/dags/04_ELT_example.py
[2023-11-03T19:48:16.234+0000] {logging_mixin.py:151} INFO - [2023-11-03T19:48:16.230+0000] {dagbag.py:346} ERROR - Failed to import: /opt/airflow/dags/04_ELT_example.py
Traceback (most recent call last):
  File "/home/airflow/.local/lib/python3.8/site-packages/airflow/models/dagbag.py", line 342, in parse
    loader.exec_module(new_module)
  File "<frozen importlib._bootstrap_external>", line 843, in exec_module
  File "<frozen importlib._bootstrap>", line 219, in _call_with_frames_removed
  File "/opt/airflow/dags/04_ELT_example.py", line 17, in <module>
    conn_id = Variable.get("conn_name")
  File "/home/airflow/.local/lib/python3.8/site-packages/airflow/models/variable.py", line 140, in get
    raise KeyError(f"Variable {key} does not exist")
KeyError: 'Variable conn_name does not exist'
[2023-11-03T19:48:16.236+0000] {processor.py:841} WARNING - No viable dags retrieved from /opt/airflow/dags/04_ELT_example.py
[2023-11-03T19:48:16.265+0000] {processor.py:179} INFO - Processing /opt/airflow/dags/04_ELT_example.py took 0.117 seconds
[2023-11-03T19:48:46.834+0000] {processor.py:157} INFO - Started process (PID=34225) to work on /opt/airflow/dags/04_ELT_example.py
[2023-11-03T19:48:46.837+0000] {processor.py:829} INFO - Processing file /opt/airflow/dags/04_ELT_example.py for tasks to queue
[2023-11-03T19:48:46.843+0000] {logging_mixin.py:151} INFO - [2023-11-03T19:48:46.842+0000] {dagbag.py:536} INFO - Filling up the DagBag from /opt/airflow/dags/04_ELT_example.py
[2023-11-03T19:48:46.898+0000] {logging_mixin.py:151} INFO - [2023-11-03T19:48:46.894+0000] {dagbag.py:346} ERROR - Failed to import: /opt/airflow/dags/04_ELT_example.py
Traceback (most recent call last):
  File "/home/airflow/.local/lib/python3.8/site-packages/airflow/models/dagbag.py", line 342, in parse
    loader.exec_module(new_module)
  File "<frozen importlib._bootstrap_external>", line 843, in exec_module
  File "<frozen importlib._bootstrap>", line 219, in _call_with_frames_removed
  File "/opt/airflow/dags/04_ELT_example.py", line 17, in <module>
    conn_id = Variable.get("conn_name")
  File "/home/airflow/.local/lib/python3.8/site-packages/airflow/models/variable.py", line 140, in get
    raise KeyError(f"Variable {key} does not exist")
KeyError: 'Variable conn_name does not exist'
[2023-11-03T19:48:46.899+0000] {processor.py:841} WARNING - No viable dags retrieved from /opt/airflow/dags/04_ELT_example.py
[2023-11-03T19:48:46.931+0000] {processor.py:179} INFO - Processing /opt/airflow/dags/04_ELT_example.py took 0.108 seconds
[2023-11-03T19:49:17.425+0000] {processor.py:157} INFO - Started process (PID=34287) to work on /opt/airflow/dags/04_ELT_example.py
[2023-11-03T19:49:17.428+0000] {processor.py:829} INFO - Processing file /opt/airflow/dags/04_ELT_example.py for tasks to queue
[2023-11-03T19:49:17.435+0000] {logging_mixin.py:151} INFO - [2023-11-03T19:49:17.434+0000] {dagbag.py:536} INFO - Filling up the DagBag from /opt/airflow/dags/04_ELT_example.py
[2023-11-03T19:49:17.523+0000] {logging_mixin.py:151} INFO - [2023-11-03T19:49:17.518+0000] {dagbag.py:346} ERROR - Failed to import: /opt/airflow/dags/04_ELT_example.py
Traceback (most recent call last):
  File "/home/airflow/.local/lib/python3.8/site-packages/airflow/models/dagbag.py", line 342, in parse
    loader.exec_module(new_module)
  File "<frozen importlib._bootstrap_external>", line 843, in exec_module
  File "<frozen importlib._bootstrap>", line 219, in _call_with_frames_removed
  File "/opt/airflow/dags/04_ELT_example.py", line 17, in <module>
    conn_id = Variable.get("conn_name")
  File "/home/airflow/.local/lib/python3.8/site-packages/airflow/models/variable.py", line 140, in get
    raise KeyError(f"Variable {key} does not exist")
KeyError: 'Variable conn_name does not exist'
[2023-11-03T19:49:17.526+0000] {processor.py:841} WARNING - No viable dags retrieved from /opt/airflow/dags/04_ELT_example.py
[2023-11-03T19:49:17.556+0000] {processor.py:179} INFO - Processing /opt/airflow/dags/04_ELT_example.py took 0.140 seconds
[2023-11-03T19:49:47.762+0000] {processor.py:157} INFO - Started process (PID=34349) to work on /opt/airflow/dags/04_ELT_example.py
[2023-11-03T19:49:47.770+0000] {processor.py:829} INFO - Processing file /opt/airflow/dags/04_ELT_example.py for tasks to queue
[2023-11-03T19:49:47.783+0000] {logging_mixin.py:151} INFO - [2023-11-03T19:49:47.781+0000] {dagbag.py:536} INFO - Filling up the DagBag from /opt/airflow/dags/04_ELT_example.py
[2023-11-03T19:49:47.895+0000] {logging_mixin.py:151} INFO - [2023-11-03T19:49:47.890+0000] {dagbag.py:346} ERROR - Failed to import: /opt/airflow/dags/04_ELT_example.py
Traceback (most recent call last):
  File "/home/airflow/.local/lib/python3.8/site-packages/airflow/models/dagbag.py", line 342, in parse
    loader.exec_module(new_module)
  File "<frozen importlib._bootstrap_external>", line 843, in exec_module
  File "<frozen importlib._bootstrap>", line 219, in _call_with_frames_removed
  File "/opt/airflow/dags/04_ELT_example.py", line 17, in <module>
    conn_id = Variable.get("conn_name")
  File "/home/airflow/.local/lib/python3.8/site-packages/airflow/models/variable.py", line 140, in get
    raise KeyError(f"Variable {key} does not exist")
KeyError: 'Variable conn_name does not exist'
[2023-11-03T19:49:47.899+0000] {processor.py:841} WARNING - No viable dags retrieved from /opt/airflow/dags/04_ELT_example.py
[2023-11-03T19:49:47.969+0000] {processor.py:179} INFO - Processing /opt/airflow/dags/04_ELT_example.py took 0.224 seconds
[2023-11-03T19:50:18.776+0000] {processor.py:157} INFO - Started process (PID=34411) to work on /opt/airflow/dags/04_ELT_example.py
[2023-11-03T19:50:18.779+0000] {processor.py:829} INFO - Processing file /opt/airflow/dags/04_ELT_example.py for tasks to queue
[2023-11-03T19:50:18.787+0000] {logging_mixin.py:151} INFO - [2023-11-03T19:50:18.785+0000] {dagbag.py:536} INFO - Filling up the DagBag from /opt/airflow/dags/04_ELT_example.py
[2023-11-03T19:50:18.840+0000] {logging_mixin.py:151} INFO - [2023-11-03T19:50:18.836+0000] {dagbag.py:346} ERROR - Failed to import: /opt/airflow/dags/04_ELT_example.py
Traceback (most recent call last):
  File "/home/airflow/.local/lib/python3.8/site-packages/airflow/models/dagbag.py", line 342, in parse
    loader.exec_module(new_module)
  File "<frozen importlib._bootstrap_external>", line 843, in exec_module
  File "<frozen importlib._bootstrap>", line 219, in _call_with_frames_removed
  File "/opt/airflow/dags/04_ELT_example.py", line 17, in <module>
    conn_id = Variable.get("conn_name")
  File "/home/airflow/.local/lib/python3.8/site-packages/airflow/models/variable.py", line 140, in get
    raise KeyError(f"Variable {key} does not exist")
KeyError: 'Variable conn_name does not exist'
[2023-11-03T19:50:18.843+0000] {processor.py:841} WARNING - No viable dags retrieved from /opt/airflow/dags/04_ELT_example.py
[2023-11-03T19:50:18.872+0000] {processor.py:179} INFO - Processing /opt/airflow/dags/04_ELT_example.py took 0.109 seconds
[2023-11-03T19:50:49.459+0000] {processor.py:157} INFO - Started process (PID=34473) to work on /opt/airflow/dags/04_ELT_example.py
[2023-11-03T19:50:49.462+0000] {processor.py:829} INFO - Processing file /opt/airflow/dags/04_ELT_example.py for tasks to queue
[2023-11-03T19:50:49.469+0000] {logging_mixin.py:151} INFO - [2023-11-03T19:50:49.468+0000] {dagbag.py:536} INFO - Filling up the DagBag from /opt/airflow/dags/04_ELT_example.py
[2023-11-03T19:50:49.529+0000] {logging_mixin.py:151} INFO - [2023-11-03T19:50:49.524+0000] {dagbag.py:346} ERROR - Failed to import: /opt/airflow/dags/04_ELT_example.py
Traceback (most recent call last):
  File "/home/airflow/.local/lib/python3.8/site-packages/airflow/models/dagbag.py", line 342, in parse
    loader.exec_module(new_module)
  File "<frozen importlib._bootstrap_external>", line 843, in exec_module
  File "<frozen importlib._bootstrap>", line 219, in _call_with_frames_removed
  File "/opt/airflow/dags/04_ELT_example.py", line 17, in <module>
    conn_id = Variable.get("conn_name")
  File "/home/airflow/.local/lib/python3.8/site-packages/airflow/models/variable.py", line 140, in get
    raise KeyError(f"Variable {key} does not exist")
KeyError: 'Variable conn_name does not exist'
[2023-11-03T19:50:49.532+0000] {processor.py:841} WARNING - No viable dags retrieved from /opt/airflow/dags/04_ELT_example.py
[2023-11-03T19:50:49.561+0000] {processor.py:179} INFO - Processing /opt/airflow/dags/04_ELT_example.py took 0.110 seconds
[2023-11-03T19:51:19.807+0000] {processor.py:157} INFO - Started process (PID=34535) to work on /opt/airflow/dags/04_ELT_example.py
[2023-11-03T19:51:19.810+0000] {processor.py:829} INFO - Processing file /opt/airflow/dags/04_ELT_example.py for tasks to queue
[2023-11-03T19:51:19.819+0000] {logging_mixin.py:151} INFO - [2023-11-03T19:51:19.818+0000] {dagbag.py:536} INFO - Filling up the DagBag from /opt/airflow/dags/04_ELT_example.py
[2023-11-03T19:51:19.869+0000] {logging_mixin.py:151} INFO - [2023-11-03T19:51:19.866+0000] {dagbag.py:346} ERROR - Failed to import: /opt/airflow/dags/04_ELT_example.py
Traceback (most recent call last):
  File "/home/airflow/.local/lib/python3.8/site-packages/airflow/models/dagbag.py", line 342, in parse
    loader.exec_module(new_module)
  File "<frozen importlib._bootstrap_external>", line 843, in exec_module
  File "<frozen importlib._bootstrap>", line 219, in _call_with_frames_removed
  File "/opt/airflow/dags/04_ELT_example.py", line 17, in <module>
    conn_id = Variable.get("conn_name")
  File "/home/airflow/.local/lib/python3.8/site-packages/airflow/models/variable.py", line 140, in get
    raise KeyError(f"Variable {key} does not exist")
KeyError: 'Variable conn_name does not exist'
[2023-11-03T19:51:19.871+0000] {processor.py:841} WARNING - No viable dags retrieved from /opt/airflow/dags/04_ELT_example.py
[2023-11-03T19:51:19.900+0000] {processor.py:179} INFO - Processing /opt/airflow/dags/04_ELT_example.py took 0.104 seconds
[2023-11-03T19:51:50.141+0000] {processor.py:157} INFO - Started process (PID=34597) to work on /opt/airflow/dags/04_ELT_example.py
[2023-11-03T19:51:50.143+0000] {processor.py:829} INFO - Processing file /opt/airflow/dags/04_ELT_example.py for tasks to queue
[2023-11-03T19:51:50.150+0000] {logging_mixin.py:151} INFO - [2023-11-03T19:51:50.149+0000] {dagbag.py:536} INFO - Filling up the DagBag from /opt/airflow/dags/04_ELT_example.py
[2023-11-03T19:51:50.206+0000] {logging_mixin.py:151} INFO - [2023-11-03T19:51:50.201+0000] {dagbag.py:346} ERROR - Failed to import: /opt/airflow/dags/04_ELT_example.py
Traceback (most recent call last):
  File "/home/airflow/.local/lib/python3.8/site-packages/airflow/models/dagbag.py", line 342, in parse
    loader.exec_module(new_module)
  File "<frozen importlib._bootstrap_external>", line 843, in exec_module
  File "<frozen importlib._bootstrap>", line 219, in _call_with_frames_removed
  File "/opt/airflow/dags/04_ELT_example.py", line 17, in <module>
    conn_id = Variable.get("conn_name")
  File "/home/airflow/.local/lib/python3.8/site-packages/airflow/models/variable.py", line 140, in get
    raise KeyError(f"Variable {key} does not exist")
KeyError: 'Variable conn_name does not exist'
[2023-11-03T19:51:50.208+0000] {processor.py:841} WARNING - No viable dags retrieved from /opt/airflow/dags/04_ELT_example.py
[2023-11-03T19:51:50.236+0000] {processor.py:179} INFO - Processing /opt/airflow/dags/04_ELT_example.py took 0.102 seconds
[2023-11-03T19:52:20.719+0000] {processor.py:157} INFO - Started process (PID=34659) to work on /opt/airflow/dags/04_ELT_example.py
[2023-11-03T19:52:20.722+0000] {processor.py:829} INFO - Processing file /opt/airflow/dags/04_ELT_example.py for tasks to queue
[2023-11-03T19:52:20.730+0000] {logging_mixin.py:151} INFO - [2023-11-03T19:52:20.728+0000] {dagbag.py:536} INFO - Filling up the DagBag from /opt/airflow/dags/04_ELT_example.py
[2023-11-03T19:52:20.785+0000] {logging_mixin.py:151} INFO - [2023-11-03T19:52:20.781+0000] {dagbag.py:346} ERROR - Failed to import: /opt/airflow/dags/04_ELT_example.py
Traceback (most recent call last):
  File "/home/airflow/.local/lib/python3.8/site-packages/airflow/models/dagbag.py", line 342, in parse
    loader.exec_module(new_module)
  File "<frozen importlib._bootstrap_external>", line 843, in exec_module
  File "<frozen importlib._bootstrap>", line 219, in _call_with_frames_removed
  File "/opt/airflow/dags/04_ELT_example.py", line 17, in <module>
    conn_id = Variable.get("conn_name")
  File "/home/airflow/.local/lib/python3.8/site-packages/airflow/models/variable.py", line 140, in get
    raise KeyError(f"Variable {key} does not exist")
KeyError: 'Variable conn_name does not exist'
[2023-11-03T19:52:20.787+0000] {processor.py:841} WARNING - No viable dags retrieved from /opt/airflow/dags/04_ELT_example.py
[2023-11-03T19:52:20.818+0000] {processor.py:179} INFO - Processing /opt/airflow/dags/04_ELT_example.py took 0.108 seconds
[2023-11-03T19:52:51.351+0000] {processor.py:157} INFO - Started process (PID=34721) to work on /opt/airflow/dags/04_ELT_example.py
[2023-11-03T19:52:51.354+0000] {processor.py:829} INFO - Processing file /opt/airflow/dags/04_ELT_example.py for tasks to queue
[2023-11-03T19:52:51.363+0000] {logging_mixin.py:151} INFO - [2023-11-03T19:52:51.361+0000] {dagbag.py:536} INFO - Filling up the DagBag from /opt/airflow/dags/04_ELT_example.py
[2023-11-03T19:52:51.420+0000] {logging_mixin.py:151} INFO - [2023-11-03T19:52:51.416+0000] {dagbag.py:346} ERROR - Failed to import: /opt/airflow/dags/04_ELT_example.py
Traceback (most recent call last):
  File "/home/airflow/.local/lib/python3.8/site-packages/airflow/models/dagbag.py", line 342, in parse
    loader.exec_module(new_module)
  File "<frozen importlib._bootstrap_external>", line 843, in exec_module
  File "<frozen importlib._bootstrap>", line 219, in _call_with_frames_removed
  File "/opt/airflow/dags/04_ELT_example.py", line 17, in <module>
    conn_id = Variable.get("conn_name")
  File "/home/airflow/.local/lib/python3.8/site-packages/airflow/models/variable.py", line 140, in get
    raise KeyError(f"Variable {key} does not exist")
KeyError: 'Variable conn_name does not exist'
[2023-11-03T19:52:51.423+0000] {processor.py:841} WARNING - No viable dags retrieved from /opt/airflow/dags/04_ELT_example.py
[2023-11-03T19:52:51.449+0000] {processor.py:179} INFO - Processing /opt/airflow/dags/04_ELT_example.py took 0.106 seconds
[2023-11-03T19:53:21.822+0000] {processor.py:157} INFO - Started process (PID=34783) to work on /opt/airflow/dags/04_ELT_example.py
[2023-11-03T19:53:21.838+0000] {processor.py:829} INFO - Processing file /opt/airflow/dags/04_ELT_example.py for tasks to queue
[2023-11-03T19:53:21.846+0000] {logging_mixin.py:151} INFO - [2023-11-03T19:53:21.845+0000] {dagbag.py:536} INFO - Filling up the DagBag from /opt/airflow/dags/04_ELT_example.py
[2023-11-03T19:53:21.930+0000] {logging_mixin.py:151} INFO - [2023-11-03T19:53:21.926+0000] {dagbag.py:346} ERROR - Failed to import: /opt/airflow/dags/04_ELT_example.py
Traceback (most recent call last):
  File "/home/airflow/.local/lib/python3.8/site-packages/airflow/models/dagbag.py", line 342, in parse
    loader.exec_module(new_module)
  File "<frozen importlib._bootstrap_external>", line 843, in exec_module
  File "<frozen importlib._bootstrap>", line 219, in _call_with_frames_removed
  File "/opt/airflow/dags/04_ELT_example.py", line 17, in <module>
    conn_id = Variable.get("conn_name")
  File "/home/airflow/.local/lib/python3.8/site-packages/airflow/models/variable.py", line 140, in get
    raise KeyError(f"Variable {key} does not exist")
KeyError: 'Variable conn_name does not exist'
[2023-11-03T19:53:21.932+0000] {processor.py:841} WARNING - No viable dags retrieved from /opt/airflow/dags/04_ELT_example.py
[2023-11-03T19:53:21.960+0000] {processor.py:179} INFO - Processing /opt/airflow/dags/04_ELT_example.py took 0.158 seconds
[2023-11-03T19:53:52.234+0000] {processor.py:157} INFO - Started process (PID=34845) to work on /opt/airflow/dags/04_ELT_example.py
[2023-11-03T19:53:52.237+0000] {processor.py:829} INFO - Processing file /opt/airflow/dags/04_ELT_example.py for tasks to queue
[2023-11-03T19:53:52.244+0000] {logging_mixin.py:151} INFO - [2023-11-03T19:53:52.243+0000] {dagbag.py:536} INFO - Filling up the DagBag from /opt/airflow/dags/04_ELT_example.py
[2023-11-03T19:53:52.301+0000] {logging_mixin.py:151} INFO - [2023-11-03T19:53:52.297+0000] {dagbag.py:346} ERROR - Failed to import: /opt/airflow/dags/04_ELT_example.py
Traceback (most recent call last):
  File "/home/airflow/.local/lib/python3.8/site-packages/airflow/models/dagbag.py", line 342, in parse
    loader.exec_module(new_module)
  File "<frozen importlib._bootstrap_external>", line 843, in exec_module
  File "<frozen importlib._bootstrap>", line 219, in _call_with_frames_removed
  File "/opt/airflow/dags/04_ELT_example.py", line 17, in <module>
    conn_id = Variable.get("conn_name")
  File "/home/airflow/.local/lib/python3.8/site-packages/airflow/models/variable.py", line 140, in get
    raise KeyError(f"Variable {key} does not exist")
KeyError: 'Variable conn_name does not exist'
[2023-11-03T19:53:52.303+0000] {processor.py:841} WARNING - No viable dags retrieved from /opt/airflow/dags/04_ELT_example.py
[2023-11-03T19:53:52.336+0000] {processor.py:179} INFO - Processing /opt/airflow/dags/04_ELT_example.py took 0.109 seconds
[2023-11-03T19:54:22.647+0000] {processor.py:157} INFO - Started process (PID=34907) to work on /opt/airflow/dags/04_ELT_example.py
[2023-11-03T19:54:22.650+0000] {processor.py:829} INFO - Processing file /opt/airflow/dags/04_ELT_example.py for tasks to queue
[2023-11-03T19:54:22.659+0000] {logging_mixin.py:151} INFO - [2023-11-03T19:54:22.657+0000] {dagbag.py:536} INFO - Filling up the DagBag from /opt/airflow/dags/04_ELT_example.py
[2023-11-03T19:54:22.728+0000] {logging_mixin.py:151} INFO - [2023-11-03T19:54:22.723+0000] {dagbag.py:346} ERROR - Failed to import: /opt/airflow/dags/04_ELT_example.py
Traceback (most recent call last):
  File "/home/airflow/.local/lib/python3.8/site-packages/airflow/models/dagbag.py", line 342, in parse
    loader.exec_module(new_module)
  File "<frozen importlib._bootstrap_external>", line 843, in exec_module
  File "<frozen importlib._bootstrap>", line 219, in _call_with_frames_removed
  File "/opt/airflow/dags/04_ELT_example.py", line 17, in <module>
    conn_id = Variable.get("conn_name")
  File "/home/airflow/.local/lib/python3.8/site-packages/airflow/models/variable.py", line 140, in get
    raise KeyError(f"Variable {key} does not exist")
KeyError: 'Variable conn_name does not exist'
[2023-11-03T19:54:22.730+0000] {processor.py:841} WARNING - No viable dags retrieved from /opt/airflow/dags/04_ELT_example.py
[2023-11-03T19:54:22.760+0000] {processor.py:179} INFO - Processing /opt/airflow/dags/04_ELT_example.py took 0.123 seconds
[2023-11-03T19:54:53.040+0000] {processor.py:157} INFO - Started process (PID=34969) to work on /opt/airflow/dags/04_ELT_example.py
[2023-11-03T19:54:53.044+0000] {processor.py:829} INFO - Processing file /opt/airflow/dags/04_ELT_example.py for tasks to queue
[2023-11-03T19:54:53.053+0000] {logging_mixin.py:151} INFO - [2023-11-03T19:54:53.052+0000] {dagbag.py:536} INFO - Filling up the DagBag from /opt/airflow/dags/04_ELT_example.py
[2023-11-03T19:54:53.110+0000] {logging_mixin.py:151} INFO - [2023-11-03T19:54:53.106+0000] {dagbag.py:346} ERROR - Failed to import: /opt/airflow/dags/04_ELT_example.py
Traceback (most recent call last):
  File "/home/airflow/.local/lib/python3.8/site-packages/airflow/models/dagbag.py", line 342, in parse
    loader.exec_module(new_module)
  File "<frozen importlib._bootstrap_external>", line 843, in exec_module
  File "<frozen importlib._bootstrap>", line 219, in _call_with_frames_removed
  File "/opt/airflow/dags/04_ELT_example.py", line 17, in <module>
    conn_id = Variable.get("conn_name")
  File "/home/airflow/.local/lib/python3.8/site-packages/airflow/models/variable.py", line 140, in get
    raise KeyError(f"Variable {key} does not exist")
KeyError: 'Variable conn_name does not exist'
[2023-11-03T19:54:53.112+0000] {processor.py:841} WARNING - No viable dags retrieved from /opt/airflow/dags/04_ELT_example.py
[2023-11-03T19:54:53.139+0000] {processor.py:179} INFO - Processing /opt/airflow/dags/04_ELT_example.py took 0.110 seconds
[2023-11-03T19:55:23.375+0000] {processor.py:157} INFO - Started process (PID=35031) to work on /opt/airflow/dags/04_ELT_example.py
[2023-11-03T19:55:23.377+0000] {processor.py:829} INFO - Processing file /opt/airflow/dags/04_ELT_example.py for tasks to queue
[2023-11-03T19:55:23.384+0000] {logging_mixin.py:151} INFO - [2023-11-03T19:55:23.383+0000] {dagbag.py:536} INFO - Filling up the DagBag from /opt/airflow/dags/04_ELT_example.py
[2023-11-03T19:55:23.443+0000] {logging_mixin.py:151} INFO - [2023-11-03T19:55:23.438+0000] {dagbag.py:346} ERROR - Failed to import: /opt/airflow/dags/04_ELT_example.py
Traceback (most recent call last):
  File "/home/airflow/.local/lib/python3.8/site-packages/airflow/models/dagbag.py", line 342, in parse
    loader.exec_module(new_module)
  File "<frozen importlib._bootstrap_external>", line 843, in exec_module
  File "<frozen importlib._bootstrap>", line 219, in _call_with_frames_removed
  File "/opt/airflow/dags/04_ELT_example.py", line 17, in <module>
    conn_id = Variable.get("conn_name")
  File "/home/airflow/.local/lib/python3.8/site-packages/airflow/models/variable.py", line 140, in get
    raise KeyError(f"Variable {key} does not exist")
KeyError: 'Variable conn_name does not exist'
[2023-11-03T19:55:23.446+0000] {processor.py:841} WARNING - No viable dags retrieved from /opt/airflow/dags/04_ELT_example.py
[2023-11-03T19:55:23.479+0000] {processor.py:179} INFO - Processing /opt/airflow/dags/04_ELT_example.py took 0.111 seconds
[2023-11-03T19:55:53.974+0000] {processor.py:157} INFO - Started process (PID=35093) to work on /opt/airflow/dags/04_ELT_example.py
[2023-11-03T19:55:53.978+0000] {processor.py:829} INFO - Processing file /opt/airflow/dags/04_ELT_example.py for tasks to queue
[2023-11-03T19:55:53.986+0000] {logging_mixin.py:151} INFO - [2023-11-03T19:55:53.985+0000] {dagbag.py:536} INFO - Filling up the DagBag from /opt/airflow/dags/04_ELT_example.py
[2023-11-03T19:55:54.054+0000] {logging_mixin.py:151} INFO - [2023-11-03T19:55:54.050+0000] {dagbag.py:346} ERROR - Failed to import: /opt/airflow/dags/04_ELT_example.py
Traceback (most recent call last):
  File "/home/airflow/.local/lib/python3.8/site-packages/airflow/models/dagbag.py", line 342, in parse
    loader.exec_module(new_module)
  File "<frozen importlib._bootstrap_external>", line 843, in exec_module
  File "<frozen importlib._bootstrap>", line 219, in _call_with_frames_removed
  File "/opt/airflow/dags/04_ELT_example.py", line 17, in <module>
    conn_id = Variable.get("conn_name")
  File "/home/airflow/.local/lib/python3.8/site-packages/airflow/models/variable.py", line 140, in get
    raise KeyError(f"Variable {key} does not exist")
KeyError: 'Variable conn_name does not exist'
[2023-11-03T19:55:54.056+0000] {processor.py:841} WARNING - No viable dags retrieved from /opt/airflow/dags/04_ELT_example.py
[2023-11-03T19:55:54.088+0000] {processor.py:179} INFO - Processing /opt/airflow/dags/04_ELT_example.py took 0.127 seconds
[2023-11-03T19:56:24.505+0000] {processor.py:157} INFO - Started process (PID=35154) to work on /opt/airflow/dags/04_ELT_example.py
[2023-11-03T19:56:24.508+0000] {processor.py:829} INFO - Processing file /opt/airflow/dags/04_ELT_example.py for tasks to queue
[2023-11-03T19:56:24.516+0000] {logging_mixin.py:151} INFO - [2023-11-03T19:56:24.515+0000] {dagbag.py:536} INFO - Filling up the DagBag from /opt/airflow/dags/04_ELT_example.py
[2023-11-03T19:56:24.591+0000] {logging_mixin.py:151} INFO - [2023-11-03T19:56:24.586+0000] {dagbag.py:346} ERROR - Failed to import: /opt/airflow/dags/04_ELT_example.py
Traceback (most recent call last):
  File "/home/airflow/.local/lib/python3.8/site-packages/airflow/models/dagbag.py", line 342, in parse
    loader.exec_module(new_module)
  File "<frozen importlib._bootstrap_external>", line 843, in exec_module
  File "<frozen importlib._bootstrap>", line 219, in _call_with_frames_removed
  File "/opt/airflow/dags/04_ELT_example.py", line 17, in <module>
    conn_id = Variable.get("conn_name")
  File "/home/airflow/.local/lib/python3.8/site-packages/airflow/models/variable.py", line 140, in get
    raise KeyError(f"Variable {key} does not exist")
KeyError: 'Variable conn_name does not exist'
[2023-11-03T19:56:24.594+0000] {processor.py:841} WARNING - No viable dags retrieved from /opt/airflow/dags/04_ELT_example.py
[2023-11-03T19:56:24.621+0000] {processor.py:179} INFO - Processing /opt/airflow/dags/04_ELT_example.py took 0.128 seconds
[2023-11-03T19:56:55.607+0000] {processor.py:157} INFO - Started process (PID=35216) to work on /opt/airflow/dags/04_ELT_example.py
[2023-11-03T19:56:55.611+0000] {processor.py:829} INFO - Processing file /opt/airflow/dags/04_ELT_example.py for tasks to queue
[2023-11-03T19:56:55.619+0000] {logging_mixin.py:151} INFO - [2023-11-03T19:56:55.618+0000] {dagbag.py:536} INFO - Filling up the DagBag from /opt/airflow/dags/04_ELT_example.py
[2023-11-03T19:56:55.680+0000] {logging_mixin.py:151} INFO - [2023-11-03T19:56:55.675+0000] {dagbag.py:346} ERROR - Failed to import: /opt/airflow/dags/04_ELT_example.py
Traceback (most recent call last):
  File "/home/airflow/.local/lib/python3.8/site-packages/airflow/models/dagbag.py", line 342, in parse
    loader.exec_module(new_module)
  File "<frozen importlib._bootstrap_external>", line 843, in exec_module
  File "<frozen importlib._bootstrap>", line 219, in _call_with_frames_removed
  File "/opt/airflow/dags/04_ELT_example.py", line 17, in <module>
    conn_id = Variable.get("conn_name")
  File "/home/airflow/.local/lib/python3.8/site-packages/airflow/models/variable.py", line 140, in get
    raise KeyError(f"Variable {key} does not exist")
KeyError: 'Variable conn_name does not exist'
[2023-11-03T19:56:55.682+0000] {processor.py:841} WARNING - No viable dags retrieved from /opt/airflow/dags/04_ELT_example.py
[2023-11-03T19:56:55.716+0000] {processor.py:179} INFO - Processing /opt/airflow/dags/04_ELT_example.py took 0.121 seconds
[2023-11-03T19:57:25.996+0000] {processor.py:157} INFO - Started process (PID=35278) to work on /opt/airflow/dags/04_ELT_example.py
[2023-11-03T19:57:25.999+0000] {processor.py:829} INFO - Processing file /opt/airflow/dags/04_ELT_example.py for tasks to queue
[2023-11-03T19:57:26.006+0000] {logging_mixin.py:151} INFO - [2023-11-03T19:57:26.005+0000] {dagbag.py:536} INFO - Filling up the DagBag from /opt/airflow/dags/04_ELT_example.py
[2023-11-03T19:57:26.057+0000] {logging_mixin.py:151} INFO - [2023-11-03T19:57:26.054+0000] {dagbag.py:346} ERROR - Failed to import: /opt/airflow/dags/04_ELT_example.py
Traceback (most recent call last):
  File "/home/airflow/.local/lib/python3.8/site-packages/airflow/models/dagbag.py", line 342, in parse
    loader.exec_module(new_module)
  File "<frozen importlib._bootstrap_external>", line 843, in exec_module
  File "<frozen importlib._bootstrap>", line 219, in _call_with_frames_removed
  File "/opt/airflow/dags/04_ELT_example.py", line 17, in <module>
    conn_id = Variable.get("conn_name")
  File "/home/airflow/.local/lib/python3.8/site-packages/airflow/models/variable.py", line 140, in get
    raise KeyError(f"Variable {key} does not exist")
KeyError: 'Variable conn_name does not exist'
[2023-11-03T19:57:26.059+0000] {processor.py:841} WARNING - No viable dags retrieved from /opt/airflow/dags/04_ELT_example.py
[2023-11-03T19:57:26.089+0000] {processor.py:179} INFO - Processing /opt/airflow/dags/04_ELT_example.py took 0.102 seconds
[2023-11-03T19:57:56.721+0000] {processor.py:157} INFO - Started process (PID=35340) to work on /opt/airflow/dags/04_ELT_example.py
[2023-11-03T19:57:56.723+0000] {processor.py:829} INFO - Processing file /opt/airflow/dags/04_ELT_example.py for tasks to queue
[2023-11-03T19:57:56.733+0000] {logging_mixin.py:151} INFO - [2023-11-03T19:57:56.731+0000] {dagbag.py:536} INFO - Filling up the DagBag from /opt/airflow/dags/04_ELT_example.py
[2023-11-03T19:57:56.787+0000] {logging_mixin.py:151} INFO - [2023-11-03T19:57:56.784+0000] {dagbag.py:346} ERROR - Failed to import: /opt/airflow/dags/04_ELT_example.py
Traceback (most recent call last):
  File "/home/airflow/.local/lib/python3.8/site-packages/airflow/models/dagbag.py", line 342, in parse
    loader.exec_module(new_module)
  File "<frozen importlib._bootstrap_external>", line 843, in exec_module
  File "<frozen importlib._bootstrap>", line 219, in _call_with_frames_removed
  File "/opt/airflow/dags/04_ELT_example.py", line 17, in <module>
    conn_id = Variable.get("conn_name")
  File "/home/airflow/.local/lib/python3.8/site-packages/airflow/models/variable.py", line 140, in get
    raise KeyError(f"Variable {key} does not exist")
KeyError: 'Variable conn_name does not exist'
[2023-11-03T19:57:56.790+0000] {processor.py:841} WARNING - No viable dags retrieved from /opt/airflow/dags/04_ELT_example.py
[2023-11-03T19:57:56.817+0000] {processor.py:179} INFO - Processing /opt/airflow/dags/04_ELT_example.py took 0.105 seconds
[2023-11-03T19:58:27.522+0000] {processor.py:157} INFO - Started process (PID=35400) to work on /opt/airflow/dags/04_ELT_example.py
[2023-11-03T19:58:27.527+0000] {processor.py:829} INFO - Processing file /opt/airflow/dags/04_ELT_example.py for tasks to queue
[2023-11-03T19:58:27.534+0000] {logging_mixin.py:151} INFO - [2023-11-03T19:58:27.533+0000] {dagbag.py:536} INFO - Filling up the DagBag from /opt/airflow/dags/04_ELT_example.py
[2023-11-03T19:58:27.599+0000] {logging_mixin.py:151} INFO - [2023-11-03T19:58:27.595+0000] {dagbag.py:346} ERROR - Failed to import: /opt/airflow/dags/04_ELT_example.py
Traceback (most recent call last):
  File "/home/airflow/.local/lib/python3.8/site-packages/airflow/models/dagbag.py", line 342, in parse
    loader.exec_module(new_module)
  File "<frozen importlib._bootstrap_external>", line 843, in exec_module
  File "<frozen importlib._bootstrap>", line 219, in _call_with_frames_removed
  File "/opt/airflow/dags/04_ELT_example.py", line 17, in <module>
    conn_id = Variable.get("conn_name")
  File "/home/airflow/.local/lib/python3.8/site-packages/airflow/models/variable.py", line 140, in get
    raise KeyError(f"Variable {key} does not exist")
KeyError: 'Variable conn_name does not exist'
[2023-11-03T19:58:27.601+0000] {processor.py:841} WARNING - No viable dags retrieved from /opt/airflow/dags/04_ELT_example.py
[2023-11-03T19:58:27.638+0000] {processor.py:179} INFO - Processing /opt/airflow/dags/04_ELT_example.py took 0.124 seconds
[2023-11-03T19:58:57.999+0000] {processor.py:157} INFO - Started process (PID=35459) to work on /opt/airflow/dags/04_ELT_example.py
[2023-11-03T19:58:58.002+0000] {processor.py:829} INFO - Processing file /opt/airflow/dags/04_ELT_example.py for tasks to queue
[2023-11-03T19:58:58.010+0000] {logging_mixin.py:151} INFO - [2023-11-03T19:58:58.009+0000] {dagbag.py:536} INFO - Filling up the DagBag from /opt/airflow/dags/04_ELT_example.py
[2023-11-03T19:58:58.063+0000] {logging_mixin.py:151} INFO - [2023-11-03T19:58:58.060+0000] {dagbag.py:346} ERROR - Failed to import: /opt/airflow/dags/04_ELT_example.py
Traceback (most recent call last):
  File "/home/airflow/.local/lib/python3.8/site-packages/airflow/models/dagbag.py", line 342, in parse
    loader.exec_module(new_module)
  File "<frozen importlib._bootstrap_external>", line 843, in exec_module
  File "<frozen importlib._bootstrap>", line 219, in _call_with_frames_removed
  File "/opt/airflow/dags/04_ELT_example.py", line 17, in <module>
    conn_id = Variable.get("conn_name")
  File "/home/airflow/.local/lib/python3.8/site-packages/airflow/models/variable.py", line 140, in get
    raise KeyError(f"Variable {key} does not exist")
KeyError: 'Variable conn_name does not exist'
[2023-11-03T19:58:58.065+0000] {processor.py:841} WARNING - No viable dags retrieved from /opt/airflow/dags/04_ELT_example.py
[2023-11-03T19:58:58.098+0000] {processor.py:179} INFO - Processing /opt/airflow/dags/04_ELT_example.py took 0.107 seconds
[2023-11-03T19:59:28.542+0000] {processor.py:157} INFO - Started process (PID=35519) to work on /opt/airflow/dags/04_ELT_example.py
[2023-11-03T19:59:28.544+0000] {processor.py:829} INFO - Processing file /opt/airflow/dags/04_ELT_example.py for tasks to queue
[2023-11-03T19:59:28.552+0000] {logging_mixin.py:151} INFO - [2023-11-03T19:59:28.551+0000] {dagbag.py:536} INFO - Filling up the DagBag from /opt/airflow/dags/04_ELT_example.py
[2023-11-03T19:59:28.602+0000] {logging_mixin.py:151} INFO - [2023-11-03T19:59:28.599+0000] {dagbag.py:346} ERROR - Failed to import: /opt/airflow/dags/04_ELT_example.py
Traceback (most recent call last):
  File "/home/airflow/.local/lib/python3.8/site-packages/airflow/models/dagbag.py", line 342, in parse
    loader.exec_module(new_module)
  File "<frozen importlib._bootstrap_external>", line 843, in exec_module
  File "<frozen importlib._bootstrap>", line 219, in _call_with_frames_removed
  File "/opt/airflow/dags/04_ELT_example.py", line 17, in <module>
    conn_id = Variable.get("conn_name")
  File "/home/airflow/.local/lib/python3.8/site-packages/airflow/models/variable.py", line 140, in get
    raise KeyError(f"Variable {key} does not exist")
KeyError: 'Variable conn_name does not exist'
[2023-11-03T19:59:28.604+0000] {processor.py:841} WARNING - No viable dags retrieved from /opt/airflow/dags/04_ELT_example.py
[2023-11-03T19:59:28.639+0000] {processor.py:179} INFO - Processing /opt/airflow/dags/04_ELT_example.py took 0.108 seconds
[2023-11-03T19:59:59.179+0000] {processor.py:157} INFO - Started process (PID=35581) to work on /opt/airflow/dags/04_ELT_example.py
[2023-11-03T19:59:59.181+0000] {processor.py:829} INFO - Processing file /opt/airflow/dags/04_ELT_example.py for tasks to queue
[2023-11-03T19:59:59.188+0000] {logging_mixin.py:151} INFO - [2023-11-03T19:59:59.187+0000] {dagbag.py:536} INFO - Filling up the DagBag from /opt/airflow/dags/04_ELT_example.py
[2023-11-03T19:59:59.248+0000] {logging_mixin.py:151} INFO - [2023-11-03T19:59:59.244+0000] {dagbag.py:346} ERROR - Failed to import: /opt/airflow/dags/04_ELT_example.py
Traceback (most recent call last):
  File "/home/airflow/.local/lib/python3.8/site-packages/airflow/models/dagbag.py", line 342, in parse
    loader.exec_module(new_module)
  File "<frozen importlib._bootstrap_external>", line 843, in exec_module
  File "<frozen importlib._bootstrap>", line 219, in _call_with_frames_removed
  File "/opt/airflow/dags/04_ELT_example.py", line 17, in <module>
    conn_id = Variable.get("conn_name")
  File "/home/airflow/.local/lib/python3.8/site-packages/airflow/models/variable.py", line 140, in get
    raise KeyError(f"Variable {key} does not exist")
KeyError: 'Variable conn_name does not exist'
[2023-11-03T19:59:59.250+0000] {processor.py:841} WARNING - No viable dags retrieved from /opt/airflow/dags/04_ELT_example.py
[2023-11-03T19:59:59.279+0000] {processor.py:179} INFO - Processing /opt/airflow/dags/04_ELT_example.py took 0.108 seconds
[2023-11-03T20:00:29.437+0000] {processor.py:157} INFO - Started process (PID=35642) to work on /opt/airflow/dags/04_ELT_example.py
[2023-11-03T20:00:29.440+0000] {processor.py:829} INFO - Processing file /opt/airflow/dags/04_ELT_example.py for tasks to queue
[2023-11-03T20:00:29.448+0000] {logging_mixin.py:151} INFO - [2023-11-03T20:00:29.447+0000] {dagbag.py:536} INFO - Filling up the DagBag from /opt/airflow/dags/04_ELT_example.py
[2023-11-03T20:00:29.509+0000] {logging_mixin.py:151} INFO - [2023-11-03T20:00:29.504+0000] {dagbag.py:346} ERROR - Failed to import: /opt/airflow/dags/04_ELT_example.py
Traceback (most recent call last):
  File "/home/airflow/.local/lib/python3.8/site-packages/airflow/models/dagbag.py", line 342, in parse
    loader.exec_module(new_module)
  File "<frozen importlib._bootstrap_external>", line 843, in exec_module
  File "<frozen importlib._bootstrap>", line 219, in _call_with_frames_removed
  File "/opt/airflow/dags/04_ELT_example.py", line 17, in <module>
    conn_id = Variable.get("conn_name")
  File "/home/airflow/.local/lib/python3.8/site-packages/airflow/models/variable.py", line 140, in get
    raise KeyError(f"Variable {key} does not exist")
KeyError: 'Variable conn_name does not exist'
[2023-11-03T20:00:29.512+0000] {processor.py:841} WARNING - No viable dags retrieved from /opt/airflow/dags/04_ELT_example.py
[2023-11-03T20:00:29.544+0000] {processor.py:179} INFO - Processing /opt/airflow/dags/04_ELT_example.py took 0.116 seconds
[2023-11-03T20:01:00.178+0000] {processor.py:157} INFO - Started process (PID=35705) to work on /opt/airflow/dags/04_ELT_example.py
[2023-11-03T20:01:00.182+0000] {processor.py:829} INFO - Processing file /opt/airflow/dags/04_ELT_example.py for tasks to queue
[2023-11-03T20:01:00.194+0000] {logging_mixin.py:151} INFO - [2023-11-03T20:01:00.192+0000] {dagbag.py:536} INFO - Filling up the DagBag from /opt/airflow/dags/04_ELT_example.py
[2023-11-03T20:01:00.248+0000] {logging_mixin.py:151} INFO - [2023-11-03T20:01:00.244+0000] {dagbag.py:346} ERROR - Failed to import: /opt/airflow/dags/04_ELT_example.py
Traceback (most recent call last):
  File "/home/airflow/.local/lib/python3.8/site-packages/airflow/models/dagbag.py", line 342, in parse
    loader.exec_module(new_module)
  File "<frozen importlib._bootstrap_external>", line 843, in exec_module
  File "<frozen importlib._bootstrap>", line 219, in _call_with_frames_removed
  File "/opt/airflow/dags/04_ELT_example.py", line 17, in <module>
    conn_id = Variable.get("conn_name")
  File "/home/airflow/.local/lib/python3.8/site-packages/airflow/models/variable.py", line 140, in get
    raise KeyError(f"Variable {key} does not exist")
KeyError: 'Variable conn_name does not exist'
[2023-11-03T20:01:00.251+0000] {processor.py:841} WARNING - No viable dags retrieved from /opt/airflow/dags/04_ELT_example.py
[2023-11-03T20:01:00.280+0000] {processor.py:179} INFO - Processing /opt/airflow/dags/04_ELT_example.py took 0.114 seconds
[2023-11-03T20:01:30.712+0000] {processor.py:157} INFO - Started process (PID=35767) to work on /opt/airflow/dags/04_ELT_example.py
[2023-11-03T20:01:30.715+0000] {processor.py:829} INFO - Processing file /opt/airflow/dags/04_ELT_example.py for tasks to queue
[2023-11-03T20:01:30.725+0000] {logging_mixin.py:151} INFO - [2023-11-03T20:01:30.723+0000] {dagbag.py:536} INFO - Filling up the DagBag from /opt/airflow/dags/04_ELT_example.py
[2023-11-03T20:01:30.774+0000] {logging_mixin.py:151} INFO - [2023-11-03T20:01:30.770+0000] {dagbag.py:346} ERROR - Failed to import: /opt/airflow/dags/04_ELT_example.py
Traceback (most recent call last):
  File "/home/airflow/.local/lib/python3.8/site-packages/airflow/models/dagbag.py", line 342, in parse
    loader.exec_module(new_module)
  File "<frozen importlib._bootstrap_external>", line 843, in exec_module
  File "<frozen importlib._bootstrap>", line 219, in _call_with_frames_removed
  File "/opt/airflow/dags/04_ELT_example.py", line 17, in <module>
    conn_id = Variable.get("conn_name")
  File "/home/airflow/.local/lib/python3.8/site-packages/airflow/models/variable.py", line 140, in get
    raise KeyError(f"Variable {key} does not exist")
KeyError: 'Variable conn_name does not exist'
[2023-11-03T20:01:30.776+0000] {processor.py:841} WARNING - No viable dags retrieved from /opt/airflow/dags/04_ELT_example.py
[2023-11-03T20:01:30.812+0000] {processor.py:179} INFO - Processing /opt/airflow/dags/04_ELT_example.py took 0.112 seconds
[2023-11-03T20:02:01.748+0000] {processor.py:157} INFO - Started process (PID=35829) to work on /opt/airflow/dags/04_ELT_example.py
[2023-11-03T20:02:01.750+0000] {processor.py:829} INFO - Processing file /opt/airflow/dags/04_ELT_example.py for tasks to queue
[2023-11-03T20:02:01.758+0000] {logging_mixin.py:151} INFO - [2023-11-03T20:02:01.757+0000] {dagbag.py:536} INFO - Filling up the DagBag from /opt/airflow/dags/04_ELT_example.py
[2023-11-03T20:02:01.807+0000] {logging_mixin.py:151} INFO - [2023-11-03T20:02:01.804+0000] {dagbag.py:346} ERROR - Failed to import: /opt/airflow/dags/04_ELT_example.py
Traceback (most recent call last):
  File "/home/airflow/.local/lib/python3.8/site-packages/airflow/models/dagbag.py", line 342, in parse
    loader.exec_module(new_module)
  File "<frozen importlib._bootstrap_external>", line 843, in exec_module
  File "<frozen importlib._bootstrap>", line 219, in _call_with_frames_removed
  File "/opt/airflow/dags/04_ELT_example.py", line 17, in <module>
    conn_id = Variable.get("conn_name")
  File "/home/airflow/.local/lib/python3.8/site-packages/airflow/models/variable.py", line 140, in get
    raise KeyError(f"Variable {key} does not exist")
KeyError: 'Variable conn_name does not exist'
[2023-11-03T20:02:01.810+0000] {processor.py:841} WARNING - No viable dags retrieved from /opt/airflow/dags/04_ELT_example.py
[2023-11-03T20:02:01.839+0000] {processor.py:179} INFO - Processing /opt/airflow/dags/04_ELT_example.py took 0.100 seconds
[2023-11-03T20:02:32.602+0000] {processor.py:157} INFO - Started process (PID=35891) to work on /opt/airflow/dags/04_ELT_example.py
[2023-11-03T20:02:32.606+0000] {processor.py:829} INFO - Processing file /opt/airflow/dags/04_ELT_example.py for tasks to queue
[2023-11-03T20:02:32.616+0000] {logging_mixin.py:151} INFO - [2023-11-03T20:02:32.615+0000] {dagbag.py:536} INFO - Filling up the DagBag from /opt/airflow/dags/04_ELT_example.py
[2023-11-03T20:02:32.677+0000] {logging_mixin.py:151} INFO - [2023-11-03T20:02:32.673+0000] {dagbag.py:346} ERROR - Failed to import: /opt/airflow/dags/04_ELT_example.py
Traceback (most recent call last):
  File "/home/airflow/.local/lib/python3.8/site-packages/airflow/models/dagbag.py", line 342, in parse
    loader.exec_module(new_module)
  File "<frozen importlib._bootstrap_external>", line 843, in exec_module
  File "<frozen importlib._bootstrap>", line 219, in _call_with_frames_removed
  File "/opt/airflow/dags/04_ELT_example.py", line 17, in <module>
    conn_id = Variable.get("conn_name")
  File "/home/airflow/.local/lib/python3.8/site-packages/airflow/models/variable.py", line 140, in get
    raise KeyError(f"Variable {key} does not exist")
KeyError: 'Variable conn_name does not exist'
[2023-11-03T20:02:32.678+0000] {processor.py:841} WARNING - No viable dags retrieved from /opt/airflow/dags/04_ELT_example.py
[2023-11-03T20:02:32.714+0000] {processor.py:179} INFO - Processing /opt/airflow/dags/04_ELT_example.py took 0.123 seconds
[2023-11-03T20:03:03.130+0000] {processor.py:157} INFO - Started process (PID=35953) to work on /opt/airflow/dags/04_ELT_example.py
[2023-11-03T20:03:03.133+0000] {processor.py:829} INFO - Processing file /opt/airflow/dags/04_ELT_example.py for tasks to queue
[2023-11-03T20:03:03.140+0000] {logging_mixin.py:151} INFO - [2023-11-03T20:03:03.138+0000] {dagbag.py:536} INFO - Filling up the DagBag from /opt/airflow/dags/04_ELT_example.py
[2023-11-03T20:03:03.205+0000] {logging_mixin.py:151} INFO - [2023-11-03T20:03:03.201+0000] {dagbag.py:346} ERROR - Failed to import: /opt/airflow/dags/04_ELT_example.py
Traceback (most recent call last):
  File "/home/airflow/.local/lib/python3.8/site-packages/airflow/models/dagbag.py", line 342, in parse
    loader.exec_module(new_module)
  File "<frozen importlib._bootstrap_external>", line 843, in exec_module
  File "<frozen importlib._bootstrap>", line 219, in _call_with_frames_removed
  File "/opt/airflow/dags/04_ELT_example.py", line 17, in <module>
    conn_id = Variable.get("conn_name")
  File "/home/airflow/.local/lib/python3.8/site-packages/airflow/models/variable.py", line 140, in get
    raise KeyError(f"Variable {key} does not exist")
KeyError: 'Variable conn_name does not exist'
[2023-11-03T20:03:03.210+0000] {processor.py:841} WARNING - No viable dags retrieved from /opt/airflow/dags/04_ELT_example.py
[2023-11-03T20:03:03.244+0000] {processor.py:179} INFO - Processing /opt/airflow/dags/04_ELT_example.py took 0.121 seconds
[2023-11-03T20:03:33.974+0000] {processor.py:157} INFO - Started process (PID=36016) to work on /opt/airflow/dags/04_ELT_example.py
[2023-11-03T20:03:33.977+0000] {processor.py:829} INFO - Processing file /opt/airflow/dags/04_ELT_example.py for tasks to queue
[2023-11-03T20:03:33.985+0000] {logging_mixin.py:151} INFO - [2023-11-03T20:03:33.983+0000] {dagbag.py:536} INFO - Filling up the DagBag from /opt/airflow/dags/04_ELT_example.py
[2023-11-03T20:03:34.052+0000] {logging_mixin.py:151} INFO - [2023-11-03T20:03:34.048+0000] {dagbag.py:346} ERROR - Failed to import: /opt/airflow/dags/04_ELT_example.py
Traceback (most recent call last):
  File "/home/airflow/.local/lib/python3.8/site-packages/airflow/models/dagbag.py", line 342, in parse
    loader.exec_module(new_module)
  File "<frozen importlib._bootstrap_external>", line 843, in exec_module
  File "<frozen importlib._bootstrap>", line 219, in _call_with_frames_removed
  File "/opt/airflow/dags/04_ELT_example.py", line 17, in <module>
    conn_id = Variable.get("conn_name")
  File "/home/airflow/.local/lib/python3.8/site-packages/airflow/models/variable.py", line 140, in get
    raise KeyError(f"Variable {key} does not exist")
KeyError: 'Variable conn_name does not exist'
[2023-11-03T20:03:34.054+0000] {processor.py:841} WARNING - No viable dags retrieved from /opt/airflow/dags/04_ELT_example.py
[2023-11-03T20:03:34.090+0000] {processor.py:179} INFO - Processing /opt/airflow/dags/04_ELT_example.py took 0.129 seconds
[2023-11-03T20:04:04.820+0000] {processor.py:157} INFO - Started process (PID=36079) to work on /opt/airflow/dags/04_ELT_example.py
[2023-11-03T20:04:04.823+0000] {processor.py:829} INFO - Processing file /opt/airflow/dags/04_ELT_example.py for tasks to queue
[2023-11-03T20:04:04.830+0000] {logging_mixin.py:151} INFO - [2023-11-03T20:04:04.829+0000] {dagbag.py:536} INFO - Filling up the DagBag from /opt/airflow/dags/04_ELT_example.py
[2023-11-03T20:04:04.892+0000] {logging_mixin.py:151} INFO - [2023-11-03T20:04:04.888+0000] {dagbag.py:346} ERROR - Failed to import: /opt/airflow/dags/04_ELT_example.py
Traceback (most recent call last):
  File "/home/airflow/.local/lib/python3.8/site-packages/airflow/models/dagbag.py", line 342, in parse
    loader.exec_module(new_module)
  File "<frozen importlib._bootstrap_external>", line 843, in exec_module
  File "<frozen importlib._bootstrap>", line 219, in _call_with_frames_removed
  File "/opt/airflow/dags/04_ELT_example.py", line 17, in <module>
    conn_id = Variable.get("conn_name")
  File "/home/airflow/.local/lib/python3.8/site-packages/airflow/models/variable.py", line 140, in get
    raise KeyError(f"Variable {key} does not exist")
KeyError: 'Variable conn_name does not exist'
[2023-11-03T20:04:04.895+0000] {processor.py:841} WARNING - No viable dags retrieved from /opt/airflow/dags/04_ELT_example.py
[2023-11-03T20:04:04.927+0000] {processor.py:179} INFO - Processing /opt/airflow/dags/04_ELT_example.py took 0.121 seconds
[2023-11-03T20:04:35.560+0000] {processor.py:157} INFO - Started process (PID=36140) to work on /opt/airflow/dags/04_ELT_example.py
[2023-11-03T20:04:35.563+0000] {processor.py:829} INFO - Processing file /opt/airflow/dags/04_ELT_example.py for tasks to queue
[2023-11-03T20:04:35.574+0000] {logging_mixin.py:151} INFO - [2023-11-03T20:04:35.573+0000] {dagbag.py:536} INFO - Filling up the DagBag from /opt/airflow/dags/04_ELT_example.py
[2023-11-03T20:04:35.634+0000] {logging_mixin.py:151} INFO - [2023-11-03T20:04:35.630+0000] {dagbag.py:346} ERROR - Failed to import: /opt/airflow/dags/04_ELT_example.py
Traceback (most recent call last):
  File "/home/airflow/.local/lib/python3.8/site-packages/airflow/models/dagbag.py", line 342, in parse
    loader.exec_module(new_module)
  File "<frozen importlib._bootstrap_external>", line 843, in exec_module
  File "<frozen importlib._bootstrap>", line 219, in _call_with_frames_removed
  File "/opt/airflow/dags/04_ELT_example.py", line 17, in <module>
    conn_id = Variable.get("conn_name")
  File "/home/airflow/.local/lib/python3.8/site-packages/airflow/models/variable.py", line 140, in get
    raise KeyError(f"Variable {key} does not exist")
KeyError: 'Variable conn_name does not exist'
[2023-11-03T20:04:35.636+0000] {processor.py:841} WARNING - No viable dags retrieved from /opt/airflow/dags/04_ELT_example.py
[2023-11-03T20:04:35.664+0000] {processor.py:179} INFO - Processing /opt/airflow/dags/04_ELT_example.py took 0.117 seconds
[2023-11-03T20:05:06.488+0000] {processor.py:157} INFO - Started process (PID=36202) to work on /opt/airflow/dags/04_ELT_example.py
[2023-11-03T20:05:06.492+0000] {processor.py:829} INFO - Processing file /opt/airflow/dags/04_ELT_example.py for tasks to queue
[2023-11-03T20:05:06.504+0000] {logging_mixin.py:151} INFO - [2023-11-03T20:05:06.502+0000] {dagbag.py:536} INFO - Filling up the DagBag from /opt/airflow/dags/04_ELT_example.py
[2023-11-03T20:05:06.556+0000] {logging_mixin.py:151} INFO - [2023-11-03T20:05:06.552+0000] {dagbag.py:346} ERROR - Failed to import: /opt/airflow/dags/04_ELT_example.py
Traceback (most recent call last):
  File "/home/airflow/.local/lib/python3.8/site-packages/airflow/models/dagbag.py", line 342, in parse
    loader.exec_module(new_module)
  File "<frozen importlib._bootstrap_external>", line 843, in exec_module
  File "<frozen importlib._bootstrap>", line 219, in _call_with_frames_removed
  File "/opt/airflow/dags/04_ELT_example.py", line 17, in <module>
    conn_id = Variable.get("conn_name")
  File "/home/airflow/.local/lib/python3.8/site-packages/airflow/models/variable.py", line 140, in get
    raise KeyError(f"Variable {key} does not exist")
KeyError: 'Variable conn_name does not exist'
[2023-11-03T20:05:06.557+0000] {processor.py:841} WARNING - No viable dags retrieved from /opt/airflow/dags/04_ELT_example.py
[2023-11-03T20:05:06.585+0000] {processor.py:179} INFO - Processing /opt/airflow/dags/04_ELT_example.py took 0.115 seconds
[2023-11-03T20:05:36.886+0000] {processor.py:157} INFO - Started process (PID=36264) to work on /opt/airflow/dags/04_ELT_example.py
[2023-11-03T20:05:36.890+0000] {processor.py:829} INFO - Processing file /opt/airflow/dags/04_ELT_example.py for tasks to queue
[2023-11-03T20:05:36.899+0000] {logging_mixin.py:151} INFO - [2023-11-03T20:05:36.897+0000] {dagbag.py:536} INFO - Filling up the DagBag from /opt/airflow/dags/04_ELT_example.py
[2023-11-03T20:05:36.947+0000] {logging_mixin.py:151} INFO - [2023-11-03T20:05:36.944+0000] {dagbag.py:346} ERROR - Failed to import: /opt/airflow/dags/04_ELT_example.py
Traceback (most recent call last):
  File "/home/airflow/.local/lib/python3.8/site-packages/airflow/models/dagbag.py", line 342, in parse
    loader.exec_module(new_module)
  File "<frozen importlib._bootstrap_external>", line 843, in exec_module
  File "<frozen importlib._bootstrap>", line 219, in _call_with_frames_removed
  File "/opt/airflow/dags/04_ELT_example.py", line 17, in <module>
    conn_id = Variable.get("conn_name")
  File "/home/airflow/.local/lib/python3.8/site-packages/airflow/models/variable.py", line 140, in get
    raise KeyError(f"Variable {key} does not exist")
KeyError: 'Variable conn_name does not exist'
[2023-11-03T20:05:36.949+0000] {processor.py:841} WARNING - No viable dags retrieved from /opt/airflow/dags/04_ELT_example.py
[2023-11-03T20:05:36.986+0000] {processor.py:179} INFO - Processing /opt/airflow/dags/04_ELT_example.py took 0.111 seconds
